Workbook

Sheet Penguin - Tank Calculations
B3: INPUTS | C3: Units: | D3: English | F3: OUTPUTS | AM3: Tables
F4: Wall Calcs | AY4: Table 8-1 | BI4: Table 8-2
B5: Outer Wall | F5: Pressure Vessel Calculations | J5: Forward Bulkhead Stress Calculations | N5: Buckling Calculations | R5: Normal Force on Outer Wall During Landing | V5: Bolt Shear | Z5: Tear-out | AD5: Bearing Stress | AH5: Net Section Stress | AM5: Material Properties of Aluminum | AS5: Material Properties of Aluminum | BC5: Metric | BN5: English
B6: Wall thickness, tO | C6: =1/8 -> 0.125 | D6: =IF($D$3="English","in", "mm") -> in | AM6: https://www.coremarkmetals.com/6061-t6-aluminum-round-tube | AS6: https://asm.matweb.com/search/specificmaterial.asp?bassnum=ma6061t6 | AY6: UNC | BD6: UNF | BI6: UNC | BO6: UNF
B7: Outer diameter, DO | C7: 4 | D7: =IF($D$3="English","in", "mm") -> in | F7: Pressure Vessel Calculations for Outer Wall | J7: Forward Bulkhead Stress for Top Bulkhead | N7: Buckling for Outer Wall | R7: Normal Force on Outer Wall (ignoring Inner Wall to be conservative) | V7: Top/Bottom Bolts Shearing | Z7: Tear-out for Outer Wall | AD7: Bearing Stress for Outer Wall | AH7: Net Section Stress for Outer Wall | AY7: Nominal Major Diameter d [mm] | AZ7: Pitch p [mm] | BA7: Tensile-Stress Area At​ [mm2] | BB7: Minor-Diameter Area Ar [mm2] | BD7: Nominal Major Diameter d [mm] | BE7: Pitch p [mm] | BF7: Tensile-Stress Area At​ [mm2] | BG7: Minor-Diameter Area Ar [mm2] | BI7: Size Designation | BJ7: Nominal Major Diameter d [in] | BK7: Threads per Inch N [in] | BL7: Tensile-Stress Area At​ [in2] | BM7: Minor-Diameter Area Ar [in2] | BO7: Size Designation | BP7: Nominal Major Diameter d [in] | BQ7: Threads per Inch N [in] | BR7: Tensile-Stress Area At​ [in2] | BS7: Minor-Diameter Area Ar [in2]
B8: Outer radius, RO | C8: =C7/2 -> 2 | D8: =IF($D$3="English","in", "mm") -> in | F8: Assume Thin Walled Pressure Vessel | G8: t < 0.1 * rmean | H8: =C6<0.1*C11 -> TRUE | J8: Forward bulkhead stress, σbulkhead | K8: =(3*$C$14*($C$8^2))/(4*(C29^2)) -> 10611.57 | L8: =IF($D$3="English","psi","Pa") -> psi | N8: End condition constant, C | O8: 1 | P8: - | R8: Moment of inertia of cross-section, I | S8: =IF($D$3="English",O9,O9*((10^-3)^4)) -> 2.8591484 | T8: =IF($D$3="English","in^4","m^4") -> in^4 | V8: Cross-sectional Area within Outer Wall dO, A | W8: =(PI()*(C9^2))/4 -> 11.044662 | X8: =IF($D$3="English","in^2","mm^2") -> in^2 | Z8: Force from internal Pressure per bolt | AA8: =W9/C61 -> 729.49309 | AB8: =IF($D$3="English","lbf","N") -> lbf | AD8: Bearing Stress, σbearing | AE8: =AA10/(C50*C6) -> 26845.346 | AF8: =IF($D$3="English","psi","Pa") -> psi | AH8: Net Section Stress, σsection | AI8: =W9/((PI()/4)*(C7^2-C9^2)-(C60*C51*C6)) -> 12526.023 | AJ8: =IF($D$3="English","psi","Pa") -> psi | AN8: Metric | AP8: Imperial | AT8: Metric | AV8: Imperial | AY8: 1.6 | AZ8: 0.35 | BA8: 1.27 | BB8: 1.07 | BD8: 1.6 | BE8: =NA() -> #N/A | BF8: =NA() -> #N/A | BG8: =NA() -> #N/A | BI8: =0 -> 0 | BJ8: 0.06 | BK8: =NA() -> #N/A | BL8: =NA() -> #N/A | BM8: =NA() -> #N/A | BO8: =0 -> 0 | BP8: 0.06 | BQ8: 80 | BR8: 0.0018 | BS8: 0.00151
B9: Inner diameter, dO | C9: =C7-(2*C6) -> 3.75 | D9: =IF($D$3="English","in", "mm") -> in | F9: Assume no outer pressure | N9: Moment of inertia of cross-section, I | O9: =(PI()/64)*((C7^4)-(C9^4)) -> 2.8591484 | P9: =IF($D$3="English","in^4","mm^4") -> in^4 | R9: Distance F applied from Top Bulkhead, x | S9: =C12 -> 75.56 | T9: =IF($D$3="English","in","m") -> in | V9: Total force from internal pressure | W9: =W8*C14 -> 11817.788 | X9: =IF($D$3="English","lbf","N") -> lbf | Z9: Fitting Factor | AA9: 1.15 | AB9: - | AM9: Property | AN9: Value | AO9: Units | AP9: Value | AQ9: Units | AS9: Property | AT9: Value | AU9: Units | AV9: Value | AW9: Units | AY9: 2 | AZ9: 0.4 | BA9: 2.07 | BB9: 1.79 | BD9: 2 | BE9: =NA() -> #N/A | BF9: =NA() -> #N/A | BG9: =NA() -> #N/A | BI9: =1 -> 1 | BJ9: 0.073 | BK9: 64 | BL9: 0.00263 | BM9: 0.00218 | BO9: =1 -> 1 | BP9: 0.073 | BQ9: 72 | BR9: 0.00278 | BS9: 0.00237
B10: inner radius, rO | C10: =C9/2 -> 1.875 | D10: =IF($D$3="English","in", "mm") -> in | F10: Max tangential (hoop) stress, (σt)max | G10: =C14*C11/C6 -> 16585 | H10: =IF($D$3="English","psi","Pa") -> psi | J10: Forward Bulkhead Stress for Bottom Bulkhead | N10: Area of cross-section, Ac | O10: =(PI()/4)*((C7^2)-(C9^2)) -> 1.5217089 | P10: =IF($D$3="English","in^2","mm^2") -> in^2 | R10: Force applied during landing, F | S10: 200 | T10: =IF($D$3="English","lbf","N") -> lbf | V10: Bolt Shear Stress, τbolt shear | W10: =(W9)/(C61*C59) -> 26084.799 | X10: =IF($D$3="English","psi","Pa") -> psi | Z10: Force per bolt w/ Fitting Factor | AA10: =AA8*AA9 -> 838.91705 | AB10: =IF($D$3="English","lbf","N") -> lbf | AH10: Net Section Stress fo Top Bulkhead | AM10: Density | AN10: 2700 | AO10: kg/(m^3) | AP10: 0.1 | AQ10: lb/in^3 | AS10: Modulus of Elasticity, E | AT10: =68.9*10^9 -> 68900000000 | AU10: Pa | AV10: =10000*10^3 -> 10000000 | AW10: psi | AY10: 2.5 | AZ10: 0.45 | BA10: 3.39 | BB10: 2.98 | BD10: 2.5 | BE10: =NA() -> #N/A | BF10: =NA() -> #N/A | BG10: =NA() -> #N/A | BI10: =2 -> 2 | BJ10: 0.086 | BK10: 56 | BL10: 0.0037 | BM10: 0.0031 | BO10: =2 -> 2 | BP10: 0.086 | BQ10: 64 | BR10: 0.00394 | BS10: 0.00339
B11: mean radius, rmeanO | C11: =(C8+C10)/2 -> 1.9375 | D11: =IF($D$3="English","in", "mm") -> in | F11: Max radial stress, (σr)max | G11: =-C14 -> -1070 | H11: =IF($D$3="English","psi","Pa") -> psi | J11: Forward bulkhead stress, σbulkhead | K11: =(3*$C$14*($C$8^2))/(4*(C37^2)) -> 514.83486 | L11: =IF($D$3="English","psi","Pa") -> psi | O11: =IF($D$3="English",O10,O10*((10^-3)^2)) -> 1.5217089 | P11: =IF($D$3="English","in^2","m^2") -> in^2 | R11: Moment caused by F, M | S11: =S10*S9 -> 15112 | T11: =IF($D$3="English","lbf-in","N-m") -> lbf-in | Z11: Edge distance to center of bolt hole | AA11: 0.5 | AB11: =IF($D$3="English","in","m") -> in | AH11: Net Section Stress, σsection | AI11: =W9/((PI()/4)*(C32^2-C33^2)-(C60*C50*C34)) -> 6027.9464 | AJ11: =IF($D$3="English","psi","Pa") -> psi | AM11: Ultimate Tensile Strength | AN11: =310*10^6 -> 310000000 | AO11: Pa | AP11: 45000 | AQ11: psi | AS11: Ultimate Bearing Strength | AT11: =607*10^6 -> 607000000 | AU11: Pa | AV11: 88000 | AW11: psi | AY11: 3 | AZ11: 0.5 | BA11: 5.03 | BB11: 4.47 | BD11: 3 | BE11: =NA() -> #N/A | BF11: =NA() -> #N/A | BG11: =NA() -> #N/A | BI11: =3 -> 3 | BJ11: 0.099 | BK11: 48 | BL11: 0.00487 | BM11: 0.00406 | BO11: =3 -> 3 | BP11: 0.099 | BQ11: 56 | BR11: 0.00523 | BS11: 0.00451
B12: Length, lO | C12: 75.56 | D12: =IF($D$3="English","in", "mm") -> in | F12: longitudinal (axial) stress, σl | G12: =C14*C9/(4*C6) -> 8025 | H12: =IF($D$3="English","psi","Pa") -> psi | N12: Radius of gyration, k | O12: =SQRT(O9/O11) -> 1.370732 | P12: =IF($D$3="English","in","mm") -> in | R12: Bending Stress, σbending | S12: =(S11*S9)/S8 -> 399371.61 | T12: =IF($D$3="English","psi","Pa") -> psi | Z12: Min Edge distance (tip of hole to edge), Emin | AA12: =AA11-(C50/2) -> 0.375 | AB12: =IF($D$3="English","in","m") -> in | AM12: Yield Tensile Strength | AN12: =276*10^6 -> 276000000 | AO12: Pa | AP12: 40000 | AQ12: psi | AS12: Bearing Yield Strength | AT12: =386*10^6 -> 386000000 | AU12: Pa | AV12: 56000 | AW12: psi | AY12: 3.5 | AZ12: 0.6 | BA12: 6.78 | BB12: 6 | BD12: 3.5 | BE12: =NA() -> #N/A | BF12: =NA() -> #N/A | BG12: =NA() -> #N/A | BI12: =4 -> 4 | BJ12: 0.112 | BK12: 40 | BL12: 0.00604 | BM12: 0.00496 | BO12: =4 -> 4 | BP12: 0.112 | BQ12: 48 | BR12: 0.00661 | BS12: 0.00566
C13: =IF($D$3="English",C12/12, C12*10^-3) -> 6.2966667 | D13: =IF($D$3="English","ft", "m") -> ft | N13: Slenderness ratio, l/k | O13: =C12/O12 -> 55.123831 | P13: - | Z13: Tear-out Shear Stress, τTear-out | AA13: =AA10/(2*AA12*C6) -> 8948.4485 | AB13: =IF($D$3="English","psi","Pa") -> psi | AH13: Same as Casing Tensile Stress from Half-Cat Rocketry | AM13: Fatigue Strength | AN13: =96.5*10^6 -> 96500000 | AO13: Pa | AP13: 14000 | AQ13: psi | AY13: 4 | AZ13: 0.7 | BA13: 8.78 | BB13: 7.75 | BD13: 4 | BE13: =NA() -> #N/A | BF13: =NA() -> #N/A | BG13: =NA() -> #N/A | BI13: =5 -> 5 | BJ13: 0.125 | BK13: 40 | BL13: 0.00796 | BM13: 0.00672 | BO13: =5 -> 5 | BP13: 0.125 | BQ13: 44 | BR13: 0.0088 | BS13: 0.00716
B14: Expected max internal pressure, (pi)max O | C14: 1070 | D14: =IF($D$3="English","psi","Pa") -> psi | N14: Johnson slenderness ratio, (l/k)1 | O14: =SQRT((2*(PI()^2)*O8*$C$45)/$C$42) -> 70.248147 | P14: - | Z14: Von Mises Effective Tear-out Stress | AA14: =SQRT(3*(AA13^2)) -> 15499.167 | AB14: =IF($D$3="English","psi","Pa") -> psi | AM14: Shear Strength | AN14: =207*10^6 -> 207000000 | AO14: Pa | AP14: 30000 | AQ14: psi | AY14: 5 | AZ14: 0.8 | BA14: 14.2 | BB14: 12.7 | BD14: 5 | BE14: =NA() -> #N/A | BF14: =NA() -> #N/A | BG14: =NA() -> #N/A | BI14: =6 -> 6 | BJ14: 0.138 | BK14: 32 | BL14: 0.00909 | BM14: 0.00745 | BO14: =6 -> 6 | BP14: 0.138 | BQ14: 40 | BR14: 0.01015 | BS14: 0.00874
N15: Compare slenderness ratios to choose formula needed: | P15: =IF(O13>O14, "Use Euler ", "Use Johnson ") -> Use Johnson | AM15: Melting Point | AN15: 582 - 652 | AO15: °C | AP15: 1,080 - 1,205 | AQ15: °F | AY15: 6 | AZ15: 1 | BA15: 20.1 | BB15: 17.9 | BD15: 6 | BE15: =NA() -> #N/A | BF15: =NA() -> #N/A | BG15: =NA() -> #N/A | BI15: =8 -> 8 | BJ15: 0.164 | BK15: 32 | BL15: 0.014 | BM15: 0.01196 | BO15: =8 -> 8 | BP15: 0.164 | BQ15: 36 | BR15: 0.01474 | BS15: 0.01285
B16: Inner Wall | N16: Critical load, Pcr | O16: =IF(O13>O14, (O8*(PI()^2)*$C$45*O11)/(O13^2), O11*($C$42-((($C$42/(2*PI()))*O13)^2)*(1/(O8*$C$45)))) -> 42128.313 | P16: =IF($D$3="English","lbf","N") -> lbf | Z16: Tear-out for Bulk Heads | AM16: Hardness Rockwell | AN16: B60 | AY16: 8 | AZ16: 1.25 | BA16: 36.6 | BB16: 32.8 | BD16: 8 | BE16: 1 | BF16: 39.2 | BG16: 36 | BI16: =10 -> 10 | BJ16: 0.19 | BK16: 24 | BL16: 0.0175 | BM16: 0.0145 | BO16: =10 -> 10 | BP16: 0.19 | BQ16: 32 | BR16: 0.02 | BS16: 0.0175
B17: Wall thickness, ti | C17: =1/8 -> 0.125 | D17: =IF($D$3="English","in", "mm") -> in | Z17: Force from internal Pressure per bolt | AA17: =W9/C61 -> 729.49309 | AB17: =IF($D$3="English","lbf","N") -> lbf | AM17: Hardness Brinell | AN17: 95 | AY17: 10 | AZ17: 1.5 | BA17: 58 | BB17: 52.3 | BD17: 10 | BE17: 1.25 | BF17: 61.2 | BG17: 56.3 | BI17: =12 -> 12 | BJ17: 0.216 | BK17: 24 | BL17: 0.0242 | BM17: 0.0206 | BO17: =12 -> 12 | BP17: 0.216 | BQ17: 28 | BR17: 0.0258 | BS17: 0.0226
B18: Outer diameter, Di | C18: 2 | D18: =IF($D$3="English","in", "mm") -> in | N18: Buckling for Inner Wall | Z18: Fitting Factor | AA18: 1.15 | AB18: - | AY18: 12 | AZ18: 1.75 | BA18: 84.3 | BB18: 76.3 | BD18: 12 | BE18: 1.25 | BF18: 92.1 | BG18: 86 | BI18: =1/4 -> 0.25 | BJ18: 0.25 | BK18: 20 | BL18: 0.0318 | BM18: 0.0269 | BO18: =1/4 -> 0.25 | BP18: 0.25 | BQ18: 28 | BR18: 0.0364 | BS18: 0.0326
B19: Outer radius, Ri | C19: =C18/2 -> 1 | D19: =IF($D$3="English","in", "mm") -> in | N19: End condition constant, C | O19: 1 | P19: - | Z19: Force per bolt w/ Fitting Factor | AA19: =AA17*AA18 -> 838.91705 | AB19: =IF($D$3="English","lbf","N") -> lbf | AY19: 14 | AZ19: 2 | BA19: 115 | BB19: 104 | BD19: 14 | BE19: 1.5 | BF19: 125 | BG19: 116 | BI19: =5/16 -> 0.3125 | BJ19: 0.3125 | BK19: 18 | BL19: 0.0524 | BM19: 0.0454 | BO19: =5/16 -> 0.3125 | BP19: 0.3125 | BQ19: 24 | BR19: 0.058 | BS19: 0.0524
B20: Inner diameter, di | C20: =C18-(2*C17) -> 1.75 | D20: =IF($D$3="English","in", "mm") -> in | N20: Moment of inertia of cross-section, I | O20: =(PI()/64)*((C18^4)-(C20^4)) -> 0.32501218 | P20: =IF($D$3="English","in^4","mm^4") -> in^4 | Z20: Edge distance to center of bolt hole | AA20: =AA11 -> 0.5 | AB20: =IF($D$3="English","in","m") -> in | AY20: 16 | AZ20: 2 | BA20: 157 | BB20: 144 | BD20: 16 | BE20: 1.5 | BF20: 167 | BG20: 157 | BI20: =3/8 -> 0.375 | BJ20: 0.375 | BK20: 16 | BL20: 0.0775 | BM20: 0.0678 | BO20: =3/8 -> 0.375 | BP20: 0.375 | BQ20: 24 | BR20: 0.0878 | BS20: 0.0809
B21: inner radius, ri | C21: =C20/2 -> 0.875 | D21: =IF($D$3="English","in", "mm") -> in | N21: Area of cross-section, Ac | O21: =(PI()/4)*((C18^2)-(C20^2)) -> 0.73631078 | P21: =IF($D$3="English","in^2","mm^2") -> in^2 | Z21: Min Edge distance (tip of hole to edge), Emin | AA21: =AA20-(C50/2) -> 0.375 | AB21: =IF($D$3="English","in","m") -> in | AY21: 20 | AZ21: 2.5 | BA21: 245 | BB21: 225 | BD21: 20 | BE21: 1.5 | BF21: 272 | BG21: 259 | BI21: =7/16 -> 0.4375 | BJ21: 0.4375 | BK21: 14 | BL21: 0.1063 | BM21: 0.0933 | BO21: =7/16 -> 0.4375 | BP21: 0.4375 | BQ21: 20 | BR21: 0.1187 | BS21: 0.109
B22: mean radius, rmeani | C22: =(C19+C21)/2 -> 0.9375 | D22: =IF($D$3="English","in", "mm") -> in | O22: =IF($D$3="English",O21,O21*((10^-3)^2)) -> 0.73631078 | P22: =IF($D$3="English","in^2","m^2") -> in^2 | Z22: Tear-out Shear Stress, τTear-out | AA22: =AA19/(2*AA21*C29) -> 2033.7383 | AB22: =IF($D$3="English","psi","Pa") -> psi | AY22: 24 | AZ22: 3 | BA22: 353 | BB22: 324 | BD22: 24 | BE22: 2 | BF22: 384 | BG22: 365 | BI22: =1/2 -> 0.5 | BJ22: 0.5 | BK22: 13 | BL22: 0.1419 | BM22: 0.1257 | BO22: =1/2 -> 0.5 | BP22: 0.5 | BQ22: 20 | BR22: 0.1599 | BS22: 0.1486
B23: Length, li | C23: =6*12 -> 72 | D23: =IF($D$3="English","in", "mm") -> in | N23: Radius of gyration, k | O23: =SQRT(O20/O22) -> 0.66438411 | P23: =IF($D$3="English","in","mm") -> in | Z23: Von Mises Effective Tear-out Stress | AA23: =SQRT(3*(AA22^2)) -> 3522.5381 | AB23: =IF($D$3="English","psi","Pa") -> psi | AY23: 30 | AZ23: 3.5 | BA23: 561 | BB23: 519 | BD23: 30 | BE23: 2 | BF23: 621 | BG23: 596 | BI23: =9/16 -> 0.5625 | BJ23: 0.5625 | BK23: 12 | BL23: 0.182 | BM23: 0.162 | BO23: =9/16 -> 0.5625 | BP23: 0.5625 | BQ23: 18 | BR23: 0.203 | BS23: 0.189
C24: =IF($D$3="English",C23/12, C23*10^-3) -> 6 | D24: =IF($D$3="English","ft", "m") -> ft | N24: Slenderness ratio, l/k | O24: =C23/O23 -> 108.37104 | P24: - | AY24: 36 | AZ24: 4 | BA24: 817 | BB24: 759 | BD24: 36 | BE24: 2 | BF24: 915 | BG24: 884 | BI24: =5/8 -> 0.625 | BJ24: 0.625 | BK24: 11 | BL24: 0.226 | BM24: 0.202 | BO24: =5/8 -> 0.625 | BP24: 0.625 | BQ24: 18 | BR24: 0.256 | BS24: 0.24
B25: Expected max internal pressure, (pi)max i | C25: 10 | D25: =IF($D$3="English","psi","Pa") -> psi | N25: Johnson slenderness ratio, (l/k)1 | O25: =SQRT((2*(PI()^2)*O19*$C$45)/$C$42) -> 70.248147 | P25: - | AY25: 42 | AZ25: 4.5 | BA25: 1120 | BB25: 1050 | BD25: 42 | BE25: 2 | BF25: 1260 | BG25: 1230 | BI25: =3/4 -> 0.75 | BJ25: 0.75 | BK25: 10 | BL25: 0.334 | BM25: 0.302 | BO25: =3/4 -> 0.75 | BP25: 0.75 | BQ25: 16 | BR25: 0.373 | BS25: 0.351
C26: ^^^ Read Note and change accordingly | N26: Compare slenderness ratios to choose formula needed: | P26: =IF(O24>O25, "Use Euler ", "Use Johnson ") -> Use Euler | AY26: 48 | AZ26: 5 | BA26: 1470 | BB26: 1380 | BD26: 48 | BE26: 2 | BF26: 1670 | BG26: 1630 | BI26: =7/8 -> 0.875 | BJ26: 0.875 | BK26: 9 | BL26: 0.462 | BM26: 0.419 | BO26: =7/8 -> 0.875 | BP26: 0.875 | BQ26: 14 | BR26: 0.509 | BS26: 0.48
N27: Critical load, Pcr | O27: =IF(O24>O25, (O19*(PI()^2)*$C$45*O22)/(O24^2), O22*($C$42-((($C$42/(2*PI()))*O24)^2)*(1/(O19*$C$45)))) -> 6187.7732 | P27: =IF($D$3="English","lbf","N") -> lbf | AY27: 56 | AZ27: 5.5 | BA27: 2030 | BB27: 1910 | BD27: 56 | BE27: 2 | BF27: 2300 | BG27: 2250 | BI27: =1 -> 1 | BJ27: 1 | BK27: 8 | BL27: 0.606 | BM27: 0.551 | BO27: =1 -> 1 | BP27: 1 | BQ27: 12 | BR27: 0.663 | BS27: 0.625
B28: Top Bulkhead | AY28: 64 | AZ28: 6 | BA28: 2680 | BB28: 2520 | BD28: 64 | BE28: 2 | BF28: 3030 | BG28: 2980 | BI28: =1.25 -> 1.25 | BJ28: 1.25 | BK28: 7 | BL28: 0.969 | BM28: 0.89 | BO28: =1.25 -> 1.25 | BP28: 1.25 | BQ28: 12 | BR28: 1.073 | BS28: 1.024
B29: Bottom thickness, tt | C29: 0.55 | D29: =IF($D$3="English","in", "mm") -> in | F29: Pressure Vessel Calculations for Inner Wall | N29: Actual Load on Vehicle | AY29: 72 | AZ29: 6 | BA29: 3460 | BB29: 3280 | BD29: 72 | BE29: 2 | BF29: 3860 | BG29: 3800 | BI29: =1.5 -> 1.5 | BJ29: 1.5 | BK29: 6 | BL29: 1.405 | BM29: 1.294 | BO29: =1.5 -> 1.5 | BP29: 1.5 | BQ29: 12 | BR29: 1.581 | BS29: 1.521
B30: Volume, V | C30: 12.67 | D30: =IF($D$3="English","in^3", "mm^3") -> in^3 | F30: Cannot assume Thin Walled Pressure Vessel | G30: t < 0.1 * rmean | H30: =C17<0.1*C22 -> FALSE | N30: Mass of Top Bulkhead | O30: =$C$30*$C$40 -> 1.267 | P30: =IF($D$3="English","lbm","kg") -> lbm | AY30: 80 | AZ30: 6 | BA30: 4340 | BB30: 4140 | BD30: 80 | BE30: 1.5 | BF30: 4850 | BG30: 4800
B31: Total outer diameter (Fiber Glass Connection) | C31: 3.898 | D31: =IF($D$3="English","in", "mm") -> in | F31: Assume no outer pressure | N31: Gravity, g | O31: =IF($D$3="English",32.174,9.81) -> 32.174 | P31: =IF($D$3="English","ft/s^2","m/s^2") -> ft/s^2 | AY31: 90 | AZ31: 6 | BA31: 5590 | BB31: 5360 | BD31: 90 | BE31: 2 | BF31: 6100 | BG31: 6020
B32: Outer diameter (Outer Wall Connection) | C32: =C9 -> 3.75 | D32: =IF($D$3="English","in", "mm") -> in | F32: Max tangential (hoop) stress, (σt)max | G32: =C25*C22/C17 -> 75 | H32: =IF($D$3="English","psi","Pa") -> psi | N32: Weight of Top Bulkhead | O32: =IF($D$3="English", O30,O30*O31) -> 1.267 | P32: =IF($D$3="English","lbf","N") -> lbf | AY32: 100 | AZ32: 6 | BA32: 6990 | BB32: 6740 | BD32: 100 | BE32: 2 | BF32: 7560 | BG32: 7470
B33: Inner diameter (diameter of inner cut) | C33: =C31-2*C34 -> 2.998 | D33: =IF($D$3="English","in", "mm") -> in | F33: Max radial stress, (σr)max | G33: =-C25 -> -10 | H33: =IF($D$3="English","psi","Pa") -> psi | N33: Weight of Other Subsystems | O33: 15 | P33: =IF($D$3="English","lbf","N") -> lbf | AY33: 110 | AZ33: 6 | BA33: =NA() -> #N/A | BB33: =NA() -> #N/A | BD33: 110 | BE33: 2 | BF33: 9180 | BG33: 9080
B34: Side wall thickness | C34: 0.45 | D34: =IF($D$3="English","in", "mm") -> in | F34: longitudinal (axial) stress, σl | G34: =C25*C20/(4*C17) -> 35 | H34: =IF($D$3="English","psi","Pa") -> psi | N34: Max drag force on vehicle | O34: 130 | P34: =IF($D$3="English","lbf","N") -> lbf
N35: Actual load on vehicle, P | O35: =SUM(O32:O34) -> 146.267 | P35: =IF($D$3="English","lbf","N") -> lbf
B36: Bottom Bulkhead
B37: Thickness, tb | C37: 2.497 | D37: =IF($D$3="English","in", "mm") -> in | N37: Johnson
B39: Material Properties of 6061-T6 Aluminum (for Outer Tank Material)
B40: Density, ρ | C40: =IF($D$3="English",AP10, AN10) -> 0.1 | D40: =IF($D$3="English",AQ10, AO10) -> lb/in^3
B41: Ultimate Tensile Strength, Sut | C41: =IF($D$3="English",AP11, AN11) -> 45000 | D41: =IF($D$3="English",AQ11, AO11) -> psi
B42: Yield Tensile Strength, Sy | C42: =IF($D$3="English",AP12, AN12) -> 40000 | D42: =IF($D$3="English",AQ12, AO12) -> psi | N42: Euler
B43: Fatigue Strength, Se | C43: =IF($D$3="English",AP13, AN13) -> 14000 | D43: =IF($D$3="English",AQ13, AO13) -> psi
...

Sheet CDR Calcs
B2: Component Group ID | C2: Components1 | D2: Stress Calculation | E2: Analysis | F2: Load Case | G2: FoS_y | H2: FoS_u | I2: σ_y (psi) | J2: σ_u (psi) | K2: σ (psi) | L2: MoS_y | M2: MoS_u | N2: Component Type | O2: Criticality | P2: Components2
B3: 1 | C3: Top Bulkhead | D3: Forward Stress | E3: Hand Calcs | F3: Internal Pressure | G3: 1.8 | H3: 2 | I3: ='Penguin - Tank Calculations'!$C$42 -> 40000 | J3: ='Penguin - Tank Calculations'!$C$41 -> 45000 | K3: ='Penguin - Tank Calculations'!K8 -> 10611.57 | L3: =(I3/($K3 * G3)) - 1 -> 1.0941502 | M3: =(J3/($K3 * H3)) - 1 -> 1.1203271 | N3: Structural | O3: 1 | P3: =C3 -> Top Bulkhead
B4: =IF(C4=C3, B3, B3+1) -> 1 | C4: Top Bulkhead | D4: Bolt Tear-out | E4: Hand Calcs | F4: Internal Pressure | G4: 1.8 | H4: 2 | I4: ='Penguin - Tank Calculations'!$C$42 -> 40000 | J4: ='Penguin - Tank Calculations'!$C$41 -> 45000 | K4: ='Penguin - Tank Calculations'!AA23 -> 3522.5381 | L4: =(I4/($K4 * G4)) - 1 -> 5.3085826 | M4: =(J4/($K4 * H4)) - 1 -> 5.3874398 | N4: Structural | O4: 1 | P4: =C4 -> Top Bulkhead
B5: =IF(C5=C4, B4, B4+1) -> 1 | C5: Top Bulkhead | D5: Tanks Bolt Net Section Tensile | E5: Hand Calcs | F5: Internal Pressure | G5: 1.8 | H5: 2 | I5: ='Penguin - Tank Calculations'!$C$42 -> 40000 | J5: ='Penguin - Tank Calculations'!$C$41 -> 45000 | K5: ='Penguin - Tank Calculations'!AI11 -> 6027.9464 | L5: =(I5/($K5 * G5)) - 1 -> 2.6865328 | M5: =(J5/($K5 * H5)) - 1 -> 2.7326145 | N5: Structural | O5: 1 | P5: =C5 -> Top Bulkhead
B6: =IF(C6=C5, B5, B5+1) -> 2 | C6: Outer Wall | D6: Longitudinal | E6: Hand Calcs | F6: Internal Pressure | G6: 1.7 | H6: 1.8 | I6: ='Penguin - Tank Calculations'!$C$42 -> 40000 | J6: ='Penguin - Tank Calculations'!$C$41 -> 45000 | K6: ='Penguin - Tank Calculations'!G12 -> 8025 | L6: =(I6/($K6 * G6)) - 1 -> 1.9320139 | M6: =(J6/($K6 * H6)) - 1 -> 2.1152648 | N6: Structural | O6: 2 | P6: =C6 -> Outer Wall
B7: =IF(C7=C6, B6, B6+1) -> 2 | C7: Outer Wall | D7: Hoop | E7: Hand Calcs | F7: Internal Pressure | G7: 1.7 | H7: 1.8 | I7: ='Penguin - Tank Calculations'!$C$42 -> 40000 | J7: ='Penguin - Tank Calculations'!$C$41 -> 45000 | K7: ='Penguin - Tank Calculations'!G10 -> 16585 | L7: =(I7/($K7 * G7)) - 1 -> 0.41871642 | M7: =(J7/($K7 * H7)) - 1 -> 0.50738619 | N7: Structural | O7: 2 | P7: =C7 -> Outer Wall
B8: =IF(C8=C7, B7, B7+1) -> 2 | C8: Outer Wall | D8: Buckling | E8: Hand Calcs | F8: Vehicle and Flight | G8: 1.7 | H8: 1.8 | I8: =_xlfn.CONCAT(_xlfn.VALUETOTEXT(ROUND('Penguin - Tank Calculations'!O16,0),0), " [lbf]") -> 42128 [lbf] | J8: - | K8: =_xlfn.CONCAT(_xlfn.VALUETOTEXT(ROUND('Penguin - Tank Calculations'!O35,0),0), " [lbf]") -> 146 [lbf] | L8: =('[1]Wall Calcs'!$R$49/('[1]Wall Calcs'!$R$55 * G8)) - 1 -> 132.2188 | M8: - | N8: Structural | O8: 2 | P8: =C8 -> Outer Wall
B9: =IF(C9=C8, B8, B8+1) -> 2 | C9: Outer Wall | D9: Bolt Tear-out | E9: Hand Calcs | F9: Internal Pressure | G9: 1.7 | H9: 1.8 | I9: ='Penguin - Tank Calculations'!$C$42 -> 40000 | J9: ='Penguin - Tank Calculations'!$C$41 -> 45000 | K9: ='Penguin - Tank Calculations'!AA14 -> 15499.167 | L9: =(I9/($K9 * G9)) - 1 -> 0.5181081 | M9: =(J9/($K9 * H9)) - 1 -> 0.61298986 | N9: Structural | O9: 2 | P9: =C9 -> Outer Wall
B10: =IF(C10=C9, B9, B9+1) -> 2 | C10: Outer Wall | D10: Bolt Bearing | E10: Hand Calcs | F10: Internal Pressure | G10: 1.7 | H10: 1.8 | I10: ='Penguin - Tank Calculations'!C47 -> 56000 | J10: ='Penguin - Tank Calculations'!C46 -> 88000 | K10: ='Penguin - Tank Calculations'!AE8 -> 26845.346 | L10: =(I10/($K10 * G10)) - 1 -> 0.22707217 | M10: =(J10/($K10 * H10)) - 1 -> 0.82113092 | N10: Structural | O10: 2 | P10: =C10 -> Outer Wall
B11: =IF(C11=C10, B10, B10+1) -> 2 | C11: Outer Wall | D11: Bolt Net Section Tensile | E11: Hand Calcs | F11: Internal Pressure | G11: 1.7 | H11: 1.8 | I11: ='Penguin - Tank Calculations'!$C$42 -> 40000 | J11: ='Penguin - Tank Calculations'!$C$41 -> 45000 | K11: ='Penguin - Tank Calculations'!AI8 -> 12526.023 | L11: =(I11/($K11 * G11)) - 1 -> 0.87844239 | M11: =(J11/($K11 * H11)) - 1 -> 0.99584504 | N11: Structural | O11: 2 | P11: =C11 -> Outer Wall
B12: =IF(C12=C11, B11, B11+1) -> 2 | C12: Outer Wall | D12: Normal Force at Impact | E12: Hand Calcs | F12: Vehicle Landing | G12: 1.7 | H12: 1.8 | I12: ='Penguin - Tank Calculations'!$C$42 -> 40000 | J12: ='Penguin - Tank Calculations'!$C$41 -> 45000 | K12: ='Penguin - Tank Calculations'!S12 -> 399371.61 | L12: =(I12/($K12 * G12)) - 1 -> -0.94108392 | M12: =(J12/($K12 * H12)) - 1 -> -0.93740166 | N12: Structural | O12: 2 | P12: =C12 -> Outer Wall
B13: =IF(C13=C12, B12, B12+1) -> 3 | C13: Inner Wall | D13: Longitudinal | E13: Hand Calcs | F13: Internal Pressure | G13: 1.8 | H13: 2 | I13: ='Penguin - Tank Calculations'!$C$42 -> 40000 | J13: ='Penguin - Tank Calculations'!$C$41 -> 45000 | K13: ='Penguin - Tank Calculations'!G34 -> 35 | L13: - | M13: - | N13: Structural | O13: 1 | P13: =C13 -> Inner Wall
B14: =IF(C14=C13, B13, B13+1) -> 3 | C14: Inner Wall | D14: Hoop | E14: Hand Calcs | F14: Internal Pressure | G14: 1.8 | H14: 2 | I14: ='Penguin - Tank Calculations'!$C$42 -> 40000 | J14: ='Penguin - Tank Calculations'!$C$41 -> 45000 | K14: ='Penguin - Tank Calculations'!G32 -> 75 | L14: - | M14: - | N14: Structural | O14: 1 | P14: =C14 -> Inner Wall
B15: =IF(C15=C14, B14, B14+1) -> 3 | C15: Inner Wall | D15: Buckling | E15: Hand Calcs | F15: Internal Pressure | G15: 1.8 | H15: 2 | I15: ='Penguin - Tank Calculations'!$C$42 -> 40000 | J15: ='Penguin - Tank Calculations'!$C$41 -> 45000 | K15: ='Penguin - Tank Calculations'!O27 -> 6187.7732 | L15: - | M15: - | N15: Structural | O15: 1 | P15: =C15 -> Inner Wall
B16: =IF(C16=C15, B15, B15+1) -> 4 | C16: Bottom Bulkhead | D16: Forward Stress | E16: Hand Calcs | F16: Internal Pressure | G16: 1.8 | H16: 2 | I16: ='Penguin - Tank Calculations'!$C$42 -> 40000 | J16: ='Penguin - Tank Calculations'!$C$41 -> 45000 | K16: ='Penguin - Tank Calculations'!K11 -> 514.83486 | L16: =(I16/($K16 * G16)) - 1 -> 42.163787 | M16: =(J16/($K16 * H16)) - 1 -> 42.703334 | N16: Structural | O16: 1 | P16: =C16 -> Bottom Bulkhead
B17: =IF(C17=C16, B16, B16+1) -> 4 | C17: Bottom Bulkhead | D17: Bolt Tear-out | E17: Hand Calcs | F17: Internal Pressure | G17: 1.8 | H17: 2 | I17: ='Penguin - Tank Calculations'!$C$42 -> 40000 | J17: ='Penguin - Tank Calculations'!$C$41 -> 45000 | K17: ='Penguin - Tank Calculations'!AA23 -> 3522.5381 | L17: =(I17/($K17 * G17)) - 1 -> 5.3085826 | M17: =(J17/($K17 * H17)) - 1 -> 5.3874398 | N17: Structural | O17: 1 | P17: =C17 -> Bottom Bulkhead
B18: =IF(C18=C17, B17, B17+1) -> 5 | C18: Tanks Bolts | D18: Bolt Shear | E18: Hand Calcs | F18: Internal Pressure | G18: 1.8 | H18: 2 | I18: - | J18: ='Penguin - Tank Calculations'!C65 -> 69282.032 | K18: ='Penguin - Tank Calculations'!W10 -> 26084.799 | L18: - | M18: =(J18/($K18 * H18)) - 1 -> 0.32801544 | N18: Structural | O18: 1 | P18: =C18 -> Tanks Bolts
C20: Whats left? | D20: Oring calcs
S23: Requirement | T23: Priority | U23: Data Source | V23: Tolerance, FoS
S24: The total cost of the tank subsystem shall not exceed $XXX. | T24: High | U24: Subsystem budget, allocated internally | V24: +/- $50
S25: The tank subsystem shall have the capability to withstand 1070 psi to a safety factor of 1.8 | T25: High | U25: Pressure testing tanks to validate operation | V25: FoSu 1.8
S26: The tank subsystem shall be compatible with the recovery's bolts, and integration's fiberglass outer wall. | T26: High | U26: Hand Calcs + Assembly of complete design
S27: The tank subsystem shall be able to withstand the weight of the subsystems above it and the forces applied during launch in the axial direction. | T27: High | U27: Hand Calcs + Assembly of complete design
S28: The tank subsystem shall be able to provide pressurized propellants to valve subsystem. | T28: High | U28: Hand Calcs and/or Pressure testing tanks
S29: The tank subsystem shall be able to withstand 200 lb in the normal direction during expected landing. | T29: Low | U29: Hand Calcs
