Workbook

Sheet L18 Combined Loads Bearings
B2: INPUTS | C2: Units: | D2: Metric | H2: OUTPUTS | S2: Tables
B4: Bearing Design | H4: Initial Rated Load, C10, Fa = 0 | K4: =($C$19*$C$9*C16)*($C$32/($C$29+($C$30-$C$29)*(LN($C$6^-1))^(1/$C$31)))^(1/$C$11) -> 23.568082 | L4: kN | T4: Table 11-6 | Z4: Table 11-2 | AK4: Table 11-1
B5: Bearing Brand | C5: SKF | H5: C10 From Table 11.2, Fa = 0 | K5: =IF($C$7="Deep Groove", SMALL($AF$8:$AF$27,COUNTIF($AF$8:$AF$27,"<"&K4)+1), IF($C$7="Angular", SMALL($AH$8:$AH$27,COUNTIF($AH$8:$AH$27,"<"&K4)+1), IF($C$7="02-Series", SMALL($AC$62:$AC$82,COUNTIF($AC$62:$AC$82,"<"&K4)+1), IF($C$7="03-Series", SMALL($AG$62:$AG$82,COUNTIF($AG$62:$AG$82,"<"&K4)+1), NA())))) -> 25.5 | L5: kN | T5: Manufacturer | U5: Rating Life (revs) | V5: x0 | W5: θ | X5: b | Z5: Bore | AA5: OD | AB5: Width | AC5: Fillet Radius | AD5: Shoulder | AF5: Load Ratings | AK5: Fa/C0 | AL5: e | AM5: Fa/(VFr) <= e | AO5: Fa/(VFr) > e
B6: Design Reliability, RD | C6: 0.99 | E6: must be greater than 90% | H6: C0 From Table 11.2, Fa = 0 | K6: =IF($C$7="Deep Groove",VLOOKUP(K5,$AF$8:$AG$27,2,FALSE), IF($C$7="Angular", VLOOKUP(K5,$AH$8:$AI$27,2,FALSE), IF($C$7="02-Series", VLOOKUP(K5,$AC$62:$AD$82,2,FALSE), IF($C$7="03-Series", VLOOKUP(K5,$AG$62:$AH$82,2,FALSE), NA())))) -> 13.7 | L6: kN | T6: TIMKEN | U6: =90*10^6 -> 90000000 | V6: 0 | W6: 4.48 | X6: 1.5 | AD6: Diameter | AF6: Deep Groove | AH6: Angular | AM6: X1 | AN6: Y1 | AO6: X2 | AP6: Y2
B7: Contact Type | C7: Deep Groove | H7: Fa/C0 | K7: =$C$18/K6 -> 0.072992701 | T7: SKF | U7: =1*10^6 -> 1000000 | V7: 0.02 | W7: 4.459 | X7: 1.483 | AD7: ds | AE7: dh | AF7: C10 | AG7: C0 | AH7: C10 | AI7: C0 | AK7: 0.014 | AL7: 0.19 | AM7: 1 | AN7: 0 | AO7: 0.56 | AP7: 2.3
B8: Which Ring Rotates | C8: Outer Ring | Z8: 10 | AA8: 30 | AB8: 9 | AC8: 0.6 | AD8: 12.5 | AE8: 27 | AF8: 5.07 | AG8: 2.24 | AH8: 4.94 | AI8: 2.12 | AK8: 0.021 | AL8: 0.21 | AM8: 1 | AN8: 0 | AO8: 0.56 | AP8: 2.15
B9: Rotating Ring Correction Factor, Vr | C9: =IF(C8="Inner Ring", 1, 1.2) -> 1.2 | H9: Iteration Table for C0 value | Z9: 12 | AA9: 32 | AB9: 10 | AC9: 0.6 | AD9: 14.5 | AE9: 28 | AF9: 6.89 | AG9: 3.1 | AH9: 7.02 | AI9: 3.05 | AK9: 0.028 | AL9: 0.22 | AM9: 1 | AN9: 0 | AO9: 0.56 | AP9: 1.99
B10: Bearing Type | C10: Ball | H10: Itteration # | I10: Fa/C0 | J10: Fa/(VFr) | K10: e | L10: X | M10: Y | N10: FE [kN] | O10: Updated Search C10 [kN] | P10: Updated C10 [kN] | Q10: Updated C0 [kN] | Z10: 15 | AA10: 35 | AB10: 11 | AC10: 0.6 | AD10: 17.5 | AE10: 31 | AF10: 7.8 | AG10: 3.55 | AH10: 8.06 | AI10: 3.65 | AK10: 0.042 | AL10: 0.24 | AM10: 1 | AN10: 0 | AO10: 0.56 | AP10: 1.85
B11: Power Law Exponent, a | C11: =IF(F12,C12,IF(C10="Ball", 3, 10/3)) -> 3 | H11: 0 | I11: =IF($C$18/K6 < 0.014, 0.014, $C$18/K6) -> 0.072992701 | J11: =$C$18/($C$9*$C$16) -> 0.46451133 | K11: =0.506467531924409*(I11)^0.23203728471849 -> 0.27592437 | L11: =IF(J11<=K11,1,0.56) -> 0.56 | M11: =IF(J11<=K11,0,0.863191147423464*(I11)^(-0.234866270653838)) -> 1.5961889 | N11: =L11*$C$9*$C$16 + M11*$C$18 -> 2.8017569 | O11: =($C$19*N11)*($C$32/($C$29+($C$30-$C$29)*(LN($C$6^-1))^(1/$C$31)))^(1/$C$11) -> 30.67263 | P11: =IF($C$7="Deep Groove", SMALL($AF$8:$AF$27,COUNTIF($AF$8:$AF$27,"<"&O11)+1), IF($C$7="Angular", SMALL($AH$8:$AH$27,COUNTIF($AH$8:$AH$27,"<"&O11)+1), IF($C$7="02-Series", SMALL($AC$62:$AC$82,COUNTIF($AC$62:$AC$82,"<"&O11)+1), IF($C$7="03-Series", SMALL($AG$62:$AG$82,COUNTIF($AG$62:$AG$82,"<"&O11)+1), NA())))) -> 30.7 | Q11: =IF($C$7="Deep Groove",VLOOKUP(P11,$AF$8:$AG$27,2,FALSE), IF($C$7="Angular", VLOOKUP(P11,$AH$8:$AI$27,2,FALSE), IF($C$7="02-Series", VLOOKUP(P11,$AC$62:$AD$82,2,FALSE), IF($C$7="03-Series", VLOOKUP(P11,$AG$62:$AH$82,2,FALSE), NA())))) -> 16.6 | Z11: 17 | AA11: 40 | AB11: 12 | AC11: 0.6 | AD11: 19.5 | AE11: 34 | AF11: 9.56 | AG11: 4.5 | AH11: 9.95 | AI11: 4.75 | AK11: 0.056 | AL11: 0.26 | AM11: 1 | AN11: 0 | AO11: 0.56 | AP11: 1.71
E12: Override a | F12: FALSE | H12: 1 | I12: =IF($C$18/Q11 < 0.014, 0.014, $C$18/Q11) -> 0.060240964 | J12: =$C$18/($C$9*$C$16) -> 0.46451133 | K12: =0.506467531924409*(I12)^0.23203728471849 -> 0.263901 | L12: =IF(J12<=K12,1,0.56) -> 0.56 | M12: =IF(J12<=K12,0,0.863191147423464*(I12)^(-0.234866270653838)) -> 1.6698183 | N12: =L12*$C$9*$C$16 + M12*$C$18 -> 2.8753863 | O12: =($C$19*N12)*($C$32/($C$29+($C$30-$C$29)*(LN($C$6^-1))^(1/$C$31)))^(1/$C$11) -> 31.478698 | P12: =IF($C$7="Deep Groove", SMALL($AF$8:$AF$27,COUNTIF($AF$8:$AF$27,"<"&O12)+1), IF($C$7="Angular", SMALL($AH$8:$AH$27,COUNTIF($AH$8:$AH$27,"<"&O12)+1), IF($C$7="02-Series", SMALL($AC$62:$AC$82,COUNTIF($AC$62:$AC$82,"<"&O12)+1), IF($C$7="03-Series", SMALL($AG$62:$AG$82,COUNTIF($AG$62:$AG$82,"<"&O12)+1), NA())))) -> 33.2 | Q12: =IF($C$7="Deep Groove",VLOOKUP(P12,$AF$8:$AG$27,2,FALSE), IF($C$7="Angular", VLOOKUP(P12,$AH$8:$AI$27,2,FALSE), IF($C$7="02-Series", VLOOKUP(P12,$AC$62:$AD$82,2,FALSE), IF($C$7="03-Series", VLOOKUP(P12,$AG$62:$AH$82,2,FALSE), NA())))) -> 18.6 | Z12: 20 | AA12: 47 | AB12: 14 | AC12: 1 | AD12: 25 | AE12: 41 | AF12: 12.7 | AG12: 6.2 | AH12: 13.3 | AI12: 6.55 | AK12: 0.07 | AL12: 0.27 | AM12: 1 | AN12: 0 | AO12: 0.56 | AP12: 1.63
H13: 2 | I13: =IF($C$18/Q12 < 0.014, 0.014, $C$18/Q12) -> 0.053763441 | J13: =$C$18/($C$9*$C$16) -> 0.46451133 | K13: =0.506467531924409*(I13)^0.23203728471849 -> 0.25702613 | L13: =IF(J13<=K13,1,0.56) -> 0.56 | M13: =IF(J13<=K13,0,0.863191147423464*(I13)^(-0.234866270653838)) -> 1.7150341 | N13: =L13*$C$9*$C$16 + M13*$C$18 -> 2.9206021 | O13: =($C$19*N13)*($C$32/($C$29+($C$30-$C$29)*(LN($C$6^-1))^(1/$C$31)))^(1/$C$11) -> 31.973704 | P13: =IF($C$7="Deep Groove", SMALL($AF$8:$AF$27,COUNTIF($AF$8:$AF$27,"<"&O13)+1), IF($C$7="Angular", SMALL($AH$8:$AH$27,COUNTIF($AH$8:$AH$27,"<"&O13)+1), IF($C$7="02-Series", SMALL($AC$62:$AC$82,COUNTIF($AC$62:$AC$82,"<"&O13)+1), IF($C$7="03-Series", SMALL($AG$62:$AG$82,COUNTIF($AG$62:$AG$82,"<"&O13)+1), NA())))) -> 33.2 | Q13: =IF($C$7="Deep Groove",VLOOKUP(P13,$AF$8:$AG$27,2,FALSE), IF($C$7="Angular", VLOOKUP(P13,$AH$8:$AI$27,2,FALSE), IF($C$7="02-Series", VLOOKUP(P13,$AC$62:$AD$82,2,FALSE), IF($C$7="03-Series", VLOOKUP(P13,$AG$62:$AH$82,2,FALSE), NA())))) -> 18.6 | Z13: 25 | AA13: 52 | AB13: 15 | AC13: 1 | AD13: 30 | AE13: 47 | AF13: 14 | AG13: 6.95 | AH13: 14.8 | AI13: 7.65 | AK13: 0.084 | AL13: 0.28 | AM13: 1 | AN13: 0 | AO13: 0.56 | AP13: 1.55
B14: Bearing Loads | H14: 3 | I14: =IF($C$18/Q13 < 0.014, 0.014, $C$18/Q13) -> 0.053763441 | J14: =$C$18/($C$9*$C$16) -> 0.46451133 | K14: =0.506467531924409*(I14)^0.23203728471849 -> 0.25702613 | L14: =IF(J14<=K14,1,0.56) -> 0.56 | M14: =IF(J14<=K14,0,0.863191147423464*(I14)^(-0.234866270653838)) -> 1.7150341 | N14: =L14*$C$9*$C$16 + M14*$C$18 -> 2.9206021 | O14: =($C$19*N14)*($C$32/($C$29+($C$30-$C$29)*(LN($C$6^-1))^(1/$C$31)))^(1/$C$11) -> 31.973704 | P14: =IF($C$7="Deep Groove", SMALL($AF$8:$AF$27,COUNTIF($AF$8:$AF$27,"<"&O14)+1), IF($C$7="Angular", SMALL($AH$8:$AH$27,COUNTIF($AH$8:$AH$27,"<"&O14)+1), IF($C$7="02-Series", SMALL($AC$62:$AC$82,COUNTIF($AC$62:$AC$82,"<"&O14)+1), IF($C$7="03-Series", SMALL($AG$62:$AG$82,COUNTIF($AG$62:$AG$82,"<"&O14)+1), NA())))) -> 33.2 | Q14: =IF($C$7="Deep Groove",VLOOKUP(P14,$AF$8:$AG$27,2,FALSE), IF($C$7="Angular", VLOOKUP(P14,$AH$8:$AI$27,2,FALSE), IF($C$7="02-Series", VLOOKUP(P14,$AC$62:$AD$82,2,FALSE), IF($C$7="03-Series", VLOOKUP(P14,$AG$62:$AH$82,2,FALSE), NA())))) -> 18.6 | Z14: 30 | AA14: 62 | AB14: 16 | AC14: 1 | AD14: 35 | AE14: 55 | AF14: 19.5 | AG14: 10 | AH14: 20.3 | AI14: 11 | AK14: 0.11 | AL14: 0.3 | AM14: 1 | AN14: 0 | AO14: 0.56 | AP14: 1.45
B15: Input Radial Load, Fr | C15: 1.794 | D15: =IF($D$2="English","klbf", "kN") -> kN | H15: 4 | I15: =IF($C$18/Q14 < 0.014, 0.014, $C$18/Q14) -> 0.053763441 | J15: =$C$18/($C$9*$C$16) -> 0.46451133 | K15: =0.506467531924409*(I15)^0.23203728471849 -> 0.25702613 | L15: =IF(J15<=K15,1,0.56) -> 0.56 | M15: =IF(J15<=K15,0,0.863191147423464*(I15)^(-0.234866270653838)) -> 1.7150341 | N15: =L15*$C$9*$C$16 + M15*$C$18 -> 2.9206021 | O15: =($C$19*N15)*($C$32/($C$29+($C$30-$C$29)*(LN($C$6^-1))^(1/$C$31)))^(1/$C$11) -> 31.973704 | P15: =IF($C$7="Deep Groove", SMALL($AF$8:$AF$27,COUNTIF($AF$8:$AF$27,"<"&O15)+1), IF($C$7="Angular", SMALL($AH$8:$AH$27,COUNTIF($AH$8:$AH$27,"<"&O15)+1), IF($C$7="02-Series", SMALL($AC$62:$AC$82,COUNTIF($AC$62:$AC$82,"<"&O15)+1), IF($C$7="03-Series", SMALL($AG$62:$AG$82,COUNTIF($AG$62:$AG$82,"<"&O15)+1), NA())))) -> 33.2 | Q15: =IF($C$7="Deep Groove",VLOOKUP(P15,$AF$8:$AG$27,2,FALSE), IF($C$7="Angular", VLOOKUP(P15,$AH$8:$AI$27,2,FALSE), IF($C$7="02-Series", VLOOKUP(P15,$AC$62:$AD$82,2,FALSE), IF($C$7="03-Series", VLOOKUP(P15,$AG$62:$AH$82,2,FALSE), NA())))) -> 18.6 | Z15: 35 | AA15: 72 | AB15: 17 | AC15: 1 | AD15: 41 | AE15: 65 | AF15: 25.5 | AG15: 13.7 | AH15: 27 | AI15: 15 | AK15: 0.17 | AL15: 0.34 | AM15: 1 | AN15: 0 | AO15: 0.56 | AP15: 1.31
C16: =IF($D$2="English",C15*4.448, C15) -> 1.794 | D16: kN | H16: 5 | I16: =IF($C$18/Q15 < 0.014, 0.014, $C$18/Q15) -> 0.053763441 | J16: =$C$18/($C$9*$C$16) -> 0.46451133 | K16: =0.506467531924409*(I16)^0.23203728471849 -> 0.25702613 | L16: =IF(J16<=K16,1,0.56) -> 0.56 | M16: =IF(J16<=K16,0,0.863191147423464*(I16)^(-0.234866270653838)) -> 1.7150341 | N16: =L16*$C$9*$C$16 + M16*$C$18 -> 2.9206021 | O16: =($C$19*N16)*($C$32/($C$29+($C$30-$C$29)*(LN($C$6^-1))^(1/$C$31)))^(1/$C$11) -> 31.973704 | P16: =IF($C$7="Deep Groove", SMALL($AF$8:$AF$27,COUNTIF($AF$8:$AF$27,"<"&O16)+1), IF($C$7="Angular", SMALL($AH$8:$AH$27,COUNTIF($AH$8:$AH$27,"<"&O16)+1), IF($C$7="02-Series", SMALL($AC$62:$AC$82,COUNTIF($AC$62:$AC$82,"<"&O16)+1), IF($C$7="03-Series", SMALL($AG$62:$AG$82,COUNTIF($AG$62:$AG$82,"<"&O16)+1), NA())))) -> 33.2 | Q16: =IF($C$7="Deep Groove",VLOOKUP(P16,$AF$8:$AG$27,2,FALSE), IF($C$7="Angular", VLOOKUP(P16,$AH$8:$AI$27,2,FALSE), IF($C$7="02-Series", VLOOKUP(P16,$AC$62:$AD$82,2,FALSE), IF($C$7="03-Series", VLOOKUP(P16,$AG$62:$AH$82,2,FALSE), NA())))) -> 18.6 | Z16: 40 | AA16: 80 | AB16: 18 | AC16: 1 | AD16: 46 | AE16: 72 | AF16: 30.7 | AG16: 16.6 | AH16: 31.9 | AI16: 18.6 | AK16: 0.28 | AL16: 0.38 | AM16: 1 | AN16: 0 | AO16: 0.56 | AP16: 1.15
B17: Input Axial Load, FA | C17: 1 | D17: =IF($D$2="English","klbf", "kN") -> kN | H17: 6 | I17: =IF($C$18/Q16 < 0.014, 0.014, $C$18/Q16) -> 0.053763441 | J17: =$C$18/($C$9*$C$16) -> 0.46451133 | K17: =0.506467531924409*(I17)^0.23203728471849 -> 0.25702613 | L17: =IF(J17<=K17,1,0.56) -> 0.56 | M17: =IF(J17<=K17,0,0.863191147423464*(I17)^(-0.234866270653838)) -> 1.7150341 | N17: =L17*$C$9*$C$16 + M17*$C$18 -> 2.9206021 | O17: =($C$19*N17)*($C$32/($C$29+($C$30-$C$29)*(LN($C$6^-1))^(1/$C$31)))^(1/$C$11) -> 31.973704 | P17: =IF($C$7="Deep Groove", SMALL($AF$8:$AF$27,COUNTIF($AF$8:$AF$27,"<"&O17)+1), IF($C$7="Angular", SMALL($AH$8:$AH$27,COUNTIF($AH$8:$AH$27,"<"&O17)+1), IF($C$7="02-Series", SMALL($AC$62:$AC$82,COUNTIF($AC$62:$AC$82,"<"&O17)+1), IF($C$7="03-Series", SMALL($AG$62:$AG$82,COUNTIF($AG$62:$AG$82,"<"&O17)+1), NA())))) -> 33.2 | Q17: =IF($C$7="Deep Groove",VLOOKUP(P17,$AF$8:$AG$27,2,FALSE), IF($C$7="Angular", VLOOKUP(P17,$AH$8:$AI$27,2,FALSE), IF($C$7="02-Series", VLOOKUP(P17,$AC$62:$AD$82,2,FALSE), IF($C$7="03-Series", VLOOKUP(P17,$AG$62:$AH$82,2,FALSE), NA())))) -> 18.6 | Z17: 45 | AA17: 85 | AB17: 19 | AC17: 1 | AD17: 52 | AE17: 77 | AF17: 33.2 | AG17: 18.6 | AH17: 35.8 | AI17: 21.2 | AK17: 0.42 | AL17: 0.42 | AM17: 1 | AN17: 0 | AO17: 0.56 | AP17: 1.04
C18: =IF($D$2="English",C17*4.448, C17) -> 1 | D18: kN | H18: 7 | I18: =IF($C$18/Q17 < 0.014, 0.014, $C$18/Q17) -> 0.053763441 | J18: =$C$18/($C$9*$C$16) -> 0.46451133 | K18: =0.506467531924409*(I18)^0.23203728471849 -> 0.25702613 | L18: =IF(J18<=K18,1,0.56) -> 0.56 | M18: =IF(J18<=K18,0,0.863191147423464*(I18)^(-0.234866270653838)) -> 1.7150341 | N18: =L18*$C$9*$C$16 + M18*$C$18 -> 2.9206021 | O18: =($C$19*N18)*($C$32/($C$29+($C$30-$C$29)*(LN($C$6^-1))^(1/$C$31)))^(1/$C$11) -> 31.973704 | P18: =IF($C$7="Deep Groove", SMALL($AF$8:$AF$27,COUNTIF($AF$8:$AF$27,"<"&O18)+1), IF($C$7="Angular", SMALL($AH$8:$AH$27,COUNTIF($AH$8:$AH$27,"<"&O18)+1), IF($C$7="02-Series", SMALL($AC$62:$AC$82,COUNTIF($AC$62:$AC$82,"<"&O18)+1), IF($C$7="03-Series", SMALL($AG$62:$AG$82,COUNTIF($AG$62:$AG$82,"<"&O18)+1), NA())))) -> 33.2 | Q18: =IF($C$7="Deep Groove",VLOOKUP(P18,$AF$8:$AG$27,2,FALSE), IF($C$7="Angular", VLOOKUP(P18,$AH$8:$AI$27,2,FALSE), IF($C$7="02-Series", VLOOKUP(P18,$AC$62:$AD$82,2,FALSE), IF($C$7="03-Series", VLOOKUP(P18,$AG$62:$AH$82,2,FALSE), NA())))) -> 18.6 | Z18: 50 | AA18: 90 | AB18: 20 | AC18: 1 | AD18: 56 | AE18: 82 | AF18: 35.1 | AG18: 19.6 | AH18: 37.7 | AI18: 22.8 | AK18: 0.56 | AL18: 0.44 | AM18: 1 | AN18: 0 | AO18: 0.56 | AP18: 1
B19: Load Application Factor, af | C19: 1.4 | H19: 8 | I19: =IF($C$18/Q18 < 0.014, 0.014, $C$18/Q18) -> 0.053763441 | J19: =$C$18/($C$9*$C$16) -> 0.46451133 | K19: =0.506467531924409*(I19)^0.23203728471849 -> 0.25702613 | L19: =IF(J19<=K19,1,0.56) -> 0.56 | M19: =IF(J19<=K19,0,0.863191147423464*(I19)^(-0.234866270653838)) -> 1.7150341 | N19: =L19*$C$9*$C$16 + M19*$C$18 -> 2.9206021 | O19: =($C$19*N19)*($C$32/($C$29+($C$30-$C$29)*(LN($C$6^-1))^(1/$C$31)))^(1/$C$11) -> 31.973704 | P19: =IF($C$7="Deep Groove", SMALL($AF$8:$AF$27,COUNTIF($AF$8:$AF$27,"<"&O19)+1), IF($C$7="Angular", SMALL($AH$8:$AH$27,COUNTIF($AH$8:$AH$27,"<"&O19)+1), IF($C$7="02-Series", SMALL($AC$62:$AC$82,COUNTIF($AC$62:$AC$82,"<"&O19)+1), IF($C$7="03-Series", SMALL($AG$62:$AG$82,COUNTIF($AG$62:$AG$82,"<"&O19)+1), NA())))) -> 33.2 | Q19: =IF($C$7="Deep Groove",VLOOKUP(P19,$AF$8:$AG$27,2,FALSE), IF($C$7="Angular", VLOOKUP(P19,$AH$8:$AI$27,2,FALSE), IF($C$7="02-Series", VLOOKUP(P19,$AC$62:$AD$82,2,FALSE), IF($C$7="03-Series", VLOOKUP(P19,$AG$62:$AH$82,2,FALSE), NA())))) -> 18.6 | Z19: 55 | AA19: 100 | AB19: 21 | AC19: 1.5 | AD19: 63 | AE19: 90 | AF19: 43.6 | AG19: 25 | AH19: 46.2 | AI19: 28.5
H20: 9 | I20: =IF($C$18/Q19 < 0.014, 0.014, $C$18/Q19) -> 0.053763441 | J20: =$C$18/($C$9*$C$16) -> 0.46451133 | K20: =0.506467531924409*(I20)^0.23203728471849 -> 0.25702613 | L20: =IF(J20<=K20,1,0.56) -> 0.56 | M20: =IF(J20<=K20,0,0.863191147423464*(I20)^(-0.234866270653838)) -> 1.7150341 | N20: =L20*$C$9*$C$16 + M20*$C$18 -> 2.9206021 | O20: =($C$19*N20)*($C$32/($C$29+($C$30-$C$29)*(LN($C$6^-1))^(1/$C$31)))^(1/$C$11) -> 31.973704 | P20: =IF($C$7="Deep Groove", SMALL($AF$8:$AF$27,COUNTIF($AF$8:$AF$27,"<"&O20)+1), IF($C$7="Angular", SMALL($AH$8:$AH$27,COUNTIF($AH$8:$AH$27,"<"&O20)+1), IF($C$7="02-Series", SMALL($AC$62:$AC$82,COUNTIF($AC$62:$AC$82,"<"&O20)+1), IF($C$7="03-Series", SMALL($AG$62:$AG$82,COUNTIF($AG$62:$AG$82,"<"&O20)+1), NA())))) -> 33.2 | Q20: =IF($C$7="Deep Groove",VLOOKUP(P20,$AF$8:$AG$27,2,FALSE), IF($C$7="Angular", VLOOKUP(P20,$AH$8:$AI$27,2,FALSE), IF($C$7="02-Series", VLOOKUP(P20,$AC$62:$AD$82,2,FALSE), IF($C$7="03-Series", VLOOKUP(P20,$AG$62:$AH$82,2,FALSE), NA())))) -> 18.6 | Z20: 60 | AA20: 110 | AB20: 22 | AC20: 1.5 | AD20: 70 | AE20: 99 | AF20: 47.5 | AG20: 28 | AH20: 55.9 | AI20: 35.5
B21: Design Cycle Lifetime | H21: 10 | I21: =IF($C$18/Q20 < 0.014, 0.014, $C$18/Q20) -> 0.053763441 | J21: =$C$18/($C$9*$C$16) -> 0.46451133 | K21: =0.506467531924409*(I21)^0.23203728471849 -> 0.25702613 | L21: =IF(J21<=K21,1,0.56) -> 0.56 | M21: =IF(J21<=K21,0,0.863191147423464*(I21)^(-0.234866270653838)) -> 1.7150341 | N21: =L21*$C$9*$C$16 + M21*$C$18 -> 2.9206021 | O21: =($C$19*N21)*($C$32/($C$29+($C$30-$C$29)*(LN($C$6^-1))^(1/$C$31)))^(1/$C$11) -> 31.973704 | P21: =IF($C$7="Deep Groove", SMALL($AF$8:$AF$27,COUNTIF($AF$8:$AF$27,"<"&O21)+1), IF($C$7="Angular", SMALL($AH$8:$AH$27,COUNTIF($AH$8:$AH$27,"<"&O21)+1), IF($C$7="02-Series", SMALL($AC$62:$AC$82,COUNTIF($AC$62:$AC$82,"<"&O21)+1), IF($C$7="03-Series", SMALL($AG$62:$AG$82,COUNTIF($AG$62:$AG$82,"<"&O21)+1), NA())))) -> 33.2 | Q21: =IF($C$7="Deep Groove",VLOOKUP(P21,$AF$8:$AG$27,2,FALSE), IF($C$7="Angular", VLOOKUP(P21,$AH$8:$AI$27,2,FALSE), IF($C$7="02-Series", VLOOKUP(P21,$AC$62:$AD$82,2,FALSE), IF($C$7="03-Series", VLOOKUP(P21,$AG$62:$AH$82,2,FALSE), NA())))) -> 18.6 | Z21: 65 | AA21: 120 | AB21: 23 | AC21: 1.5 | AD21: 74 | AE21: 109 | AF21: 55.9 | AG21: 34 | AH21: 63.7 | AI21: 41.5
B22: Lifetime, ℒD | C22: 5000 | D22: hrs | Z22: 70 | AA22: 125 | AB22: 24 | AC22: 1.5 | AD22: 79 | AE22: 114 | AF22: 61.8 | AG22: 37.5 | AH22: 68.9 | AI22: 45.5
B23: Rotation Speed, n | C23: 350 | D23: rpm | H23: Final Iterated Values | Z23: 75 | AA23: 130 | AB23: 25 | AC23: 1.5 | AD23: 86 | AE23: 119 | AF23: 66.3 | AG23: 40.5 | AH23: 71.5 | AI23: 49
B24: Design Lifetime, LD | C24: =IF(F25,C25,C22*C23*60) -> 105000000 | D24: revs | H24: Iterated C10 | I24: =P21 -> 33.2 | J24: kN | Z24: 80 | AA24: 140 | AB24: 26 | AC24: 2 | AD24: 93 | AE24: 127 | AF24: 70.2 | AG24: 45 | AH24: 80.6 | AI24: 55
C25: 100000000 | D25: revs | E25: Override LD | F25: FALSE | I25: =I24/4.448 -> 7.4640288 | J25: klbf | Z25: 85 | AA25: 150 | AB25: 28 | AC25: 2 | AD25: 99 | AE25: 136 | AF25: 83.2 | AG25: 53 | AH25: 90.4 | AI25: 63
H26: Iterated C0 | I26: =Q21 -> 18.6 | J26: kN | Z26: 90 | AA26: 160 | AB26: 30 | AC26: 2 | AD26: 104 | AE26: 146 | AF26: 95.6 | AG26: 62 | AH26: 106 | AI26: 73.5
B27: Weibull Paramters Automattically Based on Bearing Brand | E27: RD for 90% = | F27: =EXP(-1*((1 - C29) / (C30 - C29))^C31) -> 0.8990379 | I27: =I26/4.448 -> 4.1816547 | J27: klbf | Z27: 95 | AA27: 170 | AB27: 32 | AC27: 2 | AD27: 110 | AE27: 156 | AF27: 108 | AG27: 69.5 | AH27: 121 | AI27: 85
B28: Rating Life, L10 | C28: =IF(F36,C37,VLOOKUP($C$5,$T$6:$X$7,2,FALSE)) -> 1000000 | D28: revs
B29: x0 | C29: =IF(F36,C38,VLOOKUP($C$5,$T$6:$X$7,3,FALSE)) -> 0.02
B30: θ | C30: =IF(F36,C40,VLOOKUP($C$5,$T$6:$X$7,4,FALSE)) -> 4.459
B31: b | C31: =IF(F36,C42,VLOOKUP($C$5,$T$6:$X$7,5,FALSE)) -> 1.483
B32: Nomormalized Lifetime by Design, xD | C32: =IF(F33,C33,C24/C28) -> 105 | D32: revs
D33: revs | E33: Override xD | F33: FALSE
B34: Normalized Lifetime, xB | C34: =C29+(C30-C29)*(LN(C6^-1))^(1/C31) -> 0.21958958 | E34: For RD | F34: =C6 -> 0.99
B36: Weibull Parameters | E36: Override Weibull Parameters | F36: FALSE
B37: Rating Life, L10 | C37: =10^6 -> 1000000 | D37: revs
B38: x0 | C38: 0.02
B39: θ - x0 | C39: 4.439
B40: θ | C40: =IF(F41,C41,C39+C38) -> 4.459
D41: revs | E41: Override θ | F41: FALSE
B42: b | C42: 1.483
Z58: Table 11-3
...

Sheet Sprdsht Quiz 6 1
B2: INPUTS | C2: Units: | D2: Metric | H2: OUTPUTS | S2: Tables
B4: Bearing Design | H4: Initial Rated Load, C10, Fa = 0 | K4: =($C$19*$C$9*C16)*($C$32/($C$29+($C$30-$C$29)*(LN($C$6^-1))^(1/$C$31)))^(1/$C$11) -> 69.33026 | L4: kN | T4: Table 11-6 | Z4: Table 11-2 | AK4: Table 11-1
B5: Bearing Brand | C5: SKF | H5: C10 From Table 11.2, Fa = 0 | K5: =IF($C$7="Deep Groove", SMALL($AF$8:$AF$27,COUNTIF($AF$8:$AF$27,"<"&K4)+1), IF($C$7="Angular", SMALL($AH$8:$AH$27,COUNTIF($AH$8:$AH$27,"<"&K4)+1), IF($C$7="02-Series", SMALL($AC$62:$AC$82,COUNTIF($AC$62:$AC$82,"<"&K4)+1), IF($C$7="03-Series", SMALL($AG$62:$AG$82,COUNTIF($AG$62:$AG$82,"<"&K4)+1), NA())))) -> 70.2 | L5: kN | T5: Manufacturer | U5: Rating Life (revs) | V5: x0 | W5: θ | X5: b | Z5: Bore | AA5: OD | AB5: Width | AC5: Fillet Radius | AD5: Shoulder | AF5: Load Ratings | AK5: Fa/C0 | AL5: e | AM5: Fa/(VFr) <= e | AO5: Fa/(VFr) > e
B6: Design Reliability, RD | C6: 0.96 | E6: must be greater than 90% | H6: C0 From Table 11.2, Fa = 0 | K6: =IF($C$7="Deep Groove",VLOOKUP(K5,$AF$8:$AG$27,2,FALSE), IF($C$7="Angular", VLOOKUP(K5,$AH$8:$AI$27,2,FALSE), IF($C$7="02-Series", VLOOKUP(K5,$AC$62:$AD$82,2,FALSE), IF($C$7="03-Series", VLOOKUP(K5,$AG$62:$AH$82,2,FALSE), NA())))) -> 45 | L6: kN | T6: TIMKEN | U6: =90*10^6 -> 90000000 | V6: 0 | W6: 4.48 | X6: 1.5 | AD6: Diameter | AF6: Deep Groove | AH6: Angular | AM6: X1 | AN6: Y1 | AO6: X2 | AP6: Y2
B7: Contact Type | C7: Deep Groove | H7: Fa/C0 | K7: =$C$18/K6 -> 0 | T7: SKF | U7: =1*10^6 -> 1000000 | V7: 0.02 | W7: 4.459 | X7: 1.483 | AD7: ds | AE7: dh | AF7: C10 | AG7: C0 | AH7: C10 | AI7: C0 | AK7: 0.014 | AL7: 0.19 | AM7: 1 | AN7: 0 | AO7: 0.56 | AP7: 2.3
B8: Which Ring Rotates | C8: Outer Ring | Z8: 10 | AA8: 30 | AB8: 9 | AC8: 0.6 | AD8: 12.5 | AE8: 27 | AF8: 5.07 | AG8: 2.24 | AH8: 4.94 | AI8: 2.12 | AK8: 0.021 | AL8: 0.21 | AM8: 1 | AN8: 0 | AO8: 0.56 | AP8: 2.15
B9: Rotating Ring Correction Factor, Vr | C9: =IF(C8="Inner Ring", 1, 1.2) -> 1.2 | H9: Iteration Table for C0 value | Z9: 12 | AA9: 32 | AB9: 10 | AC9: 0.6 | AD9: 14.5 | AE9: 28 | AF9: 6.89 | AG9: 3.1 | AH9: 7.02 | AI9: 3.05 | AK9: 0.028 | AL9: 0.22 | AM9: 1 | AN9: 0 | AO9: 0.56 | AP9: 1.99
B10: Bearing Type | C10: Ball | H10: Itteration # | I10: Fa/C0 | J10: Fa/(VFr) | K10: e | L10: X | M10: Y | N10: FE [kN] | O10: Updated Search C10 [kN] | P10: Updated C10 [kN] | Q10: Updated C0 [kN] | Z10: 15 | AA10: 35 | AB10: 11 | AC10: 0.6 | AD10: 17.5 | AE10: 31 | AF10: 7.8 | AG10: 3.55 | AH10: 8.06 | AI10: 3.65 | AK10: 0.042 | AL10: 0.24 | AM10: 1 | AN10: 0 | AO10: 0.56 | AP10: 1.85
B11: Power Law Exponent, a | C11: =IF(F12,C12,IF(C10="Ball", 3, 10/3)) -> 3 | H11: 0 | I11: =IF($C$18/K6 < 0.014, 0.014, $C$18/K6) -> 0.014 | J11: =$C$18/($C$9*$C$16) -> 0 | K11: =0.506467531924409*(I11)^0.23203728471849 -> 0.18809801 | L11: =IF(J11<=K11,1,0.56) -> 1 | M11: =IF(J11<=K11,0,0.863191147423464*(I11)^(-0.234866270653838)) -> 0 | N11: =L11*$C$9*$C$16 + M11*$C$18 -> 8.4 | O11: =($C$19*N11)*($C$32/($C$29+($C$30-$C$29)*(LN($C$6^-1))^(1/$C$31)))^(1/$C$11) -> 69.33026 | P11: =IF($C$7="Deep Groove", SMALL($AF$8:$AF$27,COUNTIF($AF$8:$AF$27,"<"&O11)+1), IF($C$7="Angular", SMALL($AH$8:$AH$27,COUNTIF($AH$8:$AH$27,"<"&O11)+1), IF($C$7="02-Series", SMALL($AC$62:$AC$82,COUNTIF($AC$62:$AC$82,"<"&O11)+1), IF($C$7="03-Series", SMALL($AG$62:$AG$82,COUNTIF($AG$62:$AG$82,"<"&O11)+1), NA())))) -> 70.2 | Q11: =IF($C$7="Deep Groove",VLOOKUP(P11,$AF$8:$AG$27,2,FALSE), IF($C$7="Angular", VLOOKUP(P11,$AH$8:$AI$27,2,FALSE), IF($C$7="02-Series", VLOOKUP(P11,$AC$62:$AD$82,2,FALSE), IF($C$7="03-Series", VLOOKUP(P11,$AG$62:$AH$82,2,FALSE), NA())))) -> 45 | Z11: 17 | AA11: 40 | AB11: 12 | AC11: 0.6 | AD11: 19.5 | AE11: 34 | AF11: 9.56 | AG11: 4.5 | AH11: 9.95 | AI11: 4.75 | AK11: 0.056 | AL11: 0.26 | AM11: 1 | AN11: 0 | AO11: 0.56 | AP11: 1.71
E12: Override a | F12: FALSE | H12: 1 | I12: =IF($C$18/Q11 < 0.014, 0.014, $C$18/Q11) -> 0.014 | J12: =$C$18/($C$9*$C$16) -> 0 | K12: =0.506467531924409*(I12)^0.23203728471849 -> 0.18809801 | L12: =IF(J12<=K12,1,0.56) -> 1 | M12: =IF(J12<=K12,0,0.863191147423464*(I12)^(-0.234866270653838)) -> 0 | N12: =L12*$C$9*$C$16 + M12*$C$18 -> 8.4 | O12: =($C$19*N12)*($C$32/($C$29+($C$30-$C$29)*(LN($C$6^-1))^(1/$C$31)))^(1/$C$11) -> 69.33026 | P12: =IF($C$7="Deep Groove", SMALL($AF$8:$AF$27,COUNTIF($AF$8:$AF$27,"<"&O12)+1), IF($C$7="Angular", SMALL($AH$8:$AH$27,COUNTIF($AH$8:$AH$27,"<"&O12)+1), IF($C$7="02-Series", SMALL($AC$62:$AC$82,COUNTIF($AC$62:$AC$82,"<"&O12)+1), IF($C$7="03-Series", SMALL($AG$62:$AG$82,COUNTIF($AG$62:$AG$82,"<"&O12)+1), NA())))) -> 70.2 | Q12: =IF($C$7="Deep Groove",VLOOKUP(P12,$AF$8:$AG$27,2,FALSE), IF($C$7="Angular", VLOOKUP(P12,$AH$8:$AI$27,2,FALSE), IF($C$7="02-Series", VLOOKUP(P12,$AC$62:$AD$82,2,FALSE), IF($C$7="03-Series", VLOOKUP(P12,$AG$62:$AH$82,2,FALSE), NA())))) -> 45 | Z12: 20 | AA12: 47 | AB12: 14 | AC12: 1 | AD12: 25 | AE12: 41 | AF12: 12.7 | AG12: 6.2 | AH12: 13.3 | AI12: 6.55 | AK12: 0.07 | AL12: 0.27 | AM12: 1 | AN12: 0 | AO12: 0.56 | AP12: 1.63
H13: 2 | I13: =IF($C$18/Q12 < 0.014, 0.014, $C$18/Q12) -> 0.014 | J13: =$C$18/($C$9*$C$16) -> 0 | K13: =0.506467531924409*(I13)^0.23203728471849 -> 0.18809801 | L13: =IF(J13<=K13,1,0.56) -> 1 | M13: =IF(J13<=K13,0,0.863191147423464*(I13)^(-0.234866270653838)) -> 0 | N13: =L13*$C$9*$C$16 + M13*$C$18 -> 8.4 | O13: =($C$19*N13)*($C$32/($C$29+($C$30-$C$29)*(LN($C$6^-1))^(1/$C$31)))^(1/$C$11) -> 69.33026 | P13: =IF($C$7="Deep Groove", SMALL($AF$8:$AF$27,COUNTIF($AF$8:$AF$27,"<"&O13)+1), IF($C$7="Angular", SMALL($AH$8:$AH$27,COUNTIF($AH$8:$AH$27,"<"&O13)+1), IF($C$7="02-Series", SMALL($AC$62:$AC$82,COUNTIF($AC$62:$AC$82,"<"&O13)+1), IF($C$7="03-Series", SMALL($AG$62:$AG$82,COUNTIF($AG$62:$AG$82,"<"&O13)+1), NA())))) -> 70.2 | Q13: =IF($C$7="Deep Groove",VLOOKUP(P13,$AF$8:$AG$27,2,FALSE), IF($C$7="Angular", VLOOKUP(P13,$AH$8:$AI$27,2,FALSE), IF($C$7="02-Series", VLOOKUP(P13,$AC$62:$AD$82,2,FALSE), IF($C$7="03-Series", VLOOKUP(P13,$AG$62:$AH$82,2,FALSE), NA())))) -> 45 | Z13: 25 | AA13: 52 | AB13: 15 | AC13: 1 | AD13: 30 | AE13: 47 | AF13: 14 | AG13: 6.95 | AH13: 14.8 | AI13: 7.65 | AK13: 0.084 | AL13: 0.28 | AM13: 1 | AN13: 0 | AO13: 0.56 | AP13: 1.55
B14: Bearing Loads | H14: 3 | I14: =IF($C$18/Q13 < 0.014, 0.014, $C$18/Q13) -> 0.014 | J14: =$C$18/($C$9*$C$16) -> 0 | K14: =0.506467531924409*(I14)^0.23203728471849 -> 0.18809801 | L14: =IF(J14<=K14,1,0.56) -> 1 | M14: =IF(J14<=K14,0,0.863191147423464*(I14)^(-0.234866270653838)) -> 0 | N14: =L14*$C$9*$C$16 + M14*$C$18 -> 8.4 | O14: =($C$19*N14)*($C$32/($C$29+($C$30-$C$29)*(LN($C$6^-1))^(1/$C$31)))^(1/$C$11) -> 69.33026 | P14: =IF($C$7="Deep Groove", SMALL($AF$8:$AF$27,COUNTIF($AF$8:$AF$27,"<"&O14)+1), IF($C$7="Angular", SMALL($AH$8:$AH$27,COUNTIF($AH$8:$AH$27,"<"&O14)+1), IF($C$7="02-Series", SMALL($AC$62:$AC$82,COUNTIF($AC$62:$AC$82,"<"&O14)+1), IF($C$7="03-Series", SMALL($AG$62:$AG$82,COUNTIF($AG$62:$AG$82,"<"&O14)+1), NA())))) -> 70.2 | Q14: =IF($C$7="Deep Groove",VLOOKUP(P14,$AF$8:$AG$27,2,FALSE), IF($C$7="Angular", VLOOKUP(P14,$AH$8:$AI$27,2,FALSE), IF($C$7="02-Series", VLOOKUP(P14,$AC$62:$AD$82,2,FALSE), IF($C$7="03-Series", VLOOKUP(P14,$AG$62:$AH$82,2,FALSE), NA())))) -> 45 | Z14: 30 | AA14: 62 | AB14: 16 | AC14: 1 | AD14: 35 | AE14: 55 | AF14: 19.5 | AG14: 10 | AH14: 20.3 | AI14: 11 | AK14: 0.11 | AL14: 0.3 | AM14: 1 | AN14: 0 | AO14: 0.56 | AP14: 1.45
B15: Input Radial Load, Fr | C15: 7 | D15: =IF($D$2="English","klbf", "kN") -> kN | H15: 4 | I15: =IF($C$18/Q14 < 0.014, 0.014, $C$18/Q14) -> 0.014 | J15: =$C$18/($C$9*$C$16) -> 0 | K15: =0.506467531924409*(I15)^0.23203728471849 -> 0.18809801 | L15: =IF(J15<=K15,1,0.56) -> 1 | M15: =IF(J15<=K15,0,0.863191147423464*(I15)^(-0.234866270653838)) -> 0 | N15: =L15*$C$9*$C$16 + M15*$C$18 -> 8.4 | O15: =($C$19*N15)*($C$32/($C$29+($C$30-$C$29)*(LN($C$6^-1))^(1/$C$31)))^(1/$C$11) -> 69.33026 | P15: =IF($C$7="Deep Groove", SMALL($AF$8:$AF$27,COUNTIF($AF$8:$AF$27,"<"&O15)+1), IF($C$7="Angular", SMALL($AH$8:$AH$27,COUNTIF($AH$8:$AH$27,"<"&O15)+1), IF($C$7="02-Series", SMALL($AC$62:$AC$82,COUNTIF($AC$62:$AC$82,"<"&O15)+1), IF($C$7="03-Series", SMALL($AG$62:$AG$82,COUNTIF($AG$62:$AG$82,"<"&O15)+1), NA())))) -> 70.2 | Q15: =IF($C$7="Deep Groove",VLOOKUP(P15,$AF$8:$AG$27,2,FALSE), IF($C$7="Angular", VLOOKUP(P15,$AH$8:$AI$27,2,FALSE), IF($C$7="02-Series", VLOOKUP(P15,$AC$62:$AD$82,2,FALSE), IF($C$7="03-Series", VLOOKUP(P15,$AG$62:$AH$82,2,FALSE), NA())))) -> 45 | Z15: 35 | AA15: 72 | AB15: 17 | AC15: 1 | AD15: 41 | AE15: 65 | AF15: 25.5 | AG15: 13.7 | AH15: 27 | AI15: 15 | AK15: 0.17 | AL15: 0.34 | AM15: 1 | AN15: 0 | AO15: 0.56 | AP15: 1.31
C16: =IF($D$2="English",C15*4.448, C15) -> 7 | D16: kN | H16: 5 | I16: =IF($C$18/Q15 < 0.014, 0.014, $C$18/Q15) -> 0.014 | J16: =$C$18/($C$9*$C$16) -> 0 | K16: =0.506467531924409*(I16)^0.23203728471849 -> 0.18809801 | L16: =IF(J16<=K16,1,0.56) -> 1 | M16: =IF(J16<=K16,0,0.863191147423464*(I16)^(-0.234866270653838)) -> 0 | N16: =L16*$C$9*$C$16 + M16*$C$18 -> 8.4 | O16: =($C$19*N16)*($C$32/($C$29+($C$30-$C$29)*(LN($C$6^-1))^(1/$C$31)))^(1/$C$11) -> 69.33026 | P16: =IF($C$7="Deep Groove", SMALL($AF$8:$AF$27,COUNTIF($AF$8:$AF$27,"<"&O16)+1), IF($C$7="Angular", SMALL($AH$8:$AH$27,COUNTIF($AH$8:$AH$27,"<"&O16)+1), IF($C$7="02-Series", SMALL($AC$62:$AC$82,COUNTIF($AC$62:$AC$82,"<"&O16)+1), IF($C$7="03-Series", SMALL($AG$62:$AG$82,COUNTIF($AG$62:$AG$82,"<"&O16)+1), NA())))) -> 70.2 | Q16: =IF($C$7="Deep Groove",VLOOKUP(P16,$AF$8:$AG$27,2,FALSE), IF($C$7="Angular", VLOOKUP(P16,$AH$8:$AI$27,2,FALSE), IF($C$7="02-Series", VLOOKUP(P16,$AC$62:$AD$82,2,FALSE), IF($C$7="03-Series", VLOOKUP(P16,$AG$62:$AH$82,2,FALSE), NA())))) -> 45 | Z16: 40 | AA16: 80 | AB16: 18 | AC16: 1 | AD16: 46 | AE16: 72 | AF16: 30.7 | AG16: 16.6 | AH16: 31.9 | AI16: 18.6 | AK16: 0.28 | AL16: 0.38 | AM16: 1 | AN16: 0 | AO16: 0.56 | AP16: 1.15
B17: Input Axial Load, FA | D17: =IF($D$2="English","klbf", "kN") -> kN | H17: 6 | I17: =IF($C$18/Q16 < 0.014, 0.014, $C$18/Q16) -> 0.014 | J17: =$C$18/($C$9*$C$16) -> 0 | K17: =0.506467531924409*(I17)^0.23203728471849 -> 0.18809801 | L17: =IF(J17<=K17,1,0.56) -> 1 | M17: =IF(J17<=K17,0,0.863191147423464*(I17)^(-0.234866270653838)) -> 0 | N17: =L17*$C$9*$C$16 + M17*$C$18 -> 8.4 | O17: =($C$19*N17)*($C$32/($C$29+($C$30-$C$29)*(LN($C$6^-1))^(1/$C$31)))^(1/$C$11) -> 69.33026 | P17: =IF($C$7="Deep Groove", SMALL($AF$8:$AF$27,COUNTIF($AF$8:$AF$27,"<"&O17)+1), IF($C$7="Angular", SMALL($AH$8:$AH$27,COUNTIF($AH$8:$AH$27,"<"&O17)+1), IF($C$7="02-Series", SMALL($AC$62:$AC$82,COUNTIF($AC$62:$AC$82,"<"&O17)+1), IF($C$7="03-Series", SMALL($AG$62:$AG$82,COUNTIF($AG$62:$AG$82,"<"&O17)+1), NA())))) -> 70.2 | Q17: =IF($C$7="Deep Groove",VLOOKUP(P17,$AF$8:$AG$27,2,FALSE), IF($C$7="Angular", VLOOKUP(P17,$AH$8:$AI$27,2,FALSE), IF($C$7="02-Series", VLOOKUP(P17,$AC$62:$AD$82,2,FALSE), IF($C$7="03-Series", VLOOKUP(P17,$AG$62:$AH$82,2,FALSE), NA())))) -> 45 | Z17: 45 | AA17: 85 | AB17: 19 | AC17: 1 | AD17: 52 | AE17: 77 | AF17: 33.2 | AG17: 18.6 | AH17: 35.8 | AI17: 21.2 | AK17: 0.42 | AL17: 0.42 | AM17: 1 | AN17: 0 | AO17: 0.56 | AP17: 1.04
C18: =IF($D$2="English",C17*4.448, C17) -> 0 | D18: kN | H18: 7 | I18: =IF($C$18/Q17 < 0.014, 0.014, $C$18/Q17) -> 0.014 | J18: =$C$18/($C$9*$C$16) -> 0 | K18: =0.506467531924409*(I18)^0.23203728471849 -> 0.18809801 | L18: =IF(J18<=K18,1,0.56) -> 1 | M18: =IF(J18<=K18,0,0.863191147423464*(I18)^(-0.234866270653838)) -> 0 | N18: =L18*$C$9*$C$16 + M18*$C$18 -> 8.4 | O18: =($C$19*N18)*($C$32/($C$29+($C$30-$C$29)*(LN($C$6^-1))^(1/$C$31)))^(1/$C$11) -> 69.33026 | P18: =IF($C$7="Deep Groove", SMALL($AF$8:$AF$27,COUNTIF($AF$8:$AF$27,"<"&O18)+1), IF($C$7="Angular", SMALL($AH$8:$AH$27,COUNTIF($AH$8:$AH$27,"<"&O18)+1), IF($C$7="02-Series", SMALL($AC$62:$AC$82,COUNTIF($AC$62:$AC$82,"<"&O18)+1), IF($C$7="03-Series", SMALL($AG$62:$AG$82,COUNTIF($AG$62:$AG$82,"<"&O18)+1), NA())))) -> 70.2 | Q18: =IF($C$7="Deep Groove",VLOOKUP(P18,$AF$8:$AG$27,2,FALSE), IF($C$7="Angular", VLOOKUP(P18,$AH$8:$AI$27,2,FALSE), IF($C$7="02-Series", VLOOKUP(P18,$AC$62:$AD$82,2,FALSE), IF($C$7="03-Series", VLOOKUP(P18,$AG$62:$AH$82,2,FALSE), NA())))) -> 45 | Z18: 50 | AA18: 90 | AB18: 20 | AC18: 1 | AD18: 56 | AE18: 82 | AF18: 35.1 | AG18: 19.6 | AH18: 37.7 | AI18: 22.8 | AK18: 0.56 | AL18: 0.44 | AM18: 1 | AN18: 0 | AO18: 0.56 | AP18: 1
B19: Load Application Factor, af | C19: 1 | H19: 8 | I19: =IF($C$18/Q18 < 0.014, 0.014, $C$18/Q18) -> 0.014 | J19: =$C$18/($C$9*$C$16) -> 0 | K19: =0.506467531924409*(I19)^0.23203728471849 -> 0.18809801 | L19: =IF(J19<=K19,1,0.56) -> 1 | M19: =IF(J19<=K19,0,0.863191147423464*(I19)^(-0.234866270653838)) -> 0 | N19: =L19*$C$9*$C$16 + M19*$C$18 -> 8.4 | O19: =($C$19*N19)*($C$32/($C$29+($C$30-$C$29)*(LN($C$6^-1))^(1/$C$31)))^(1/$C$11) -> 69.33026 | P19: =IF($C$7="Deep Groove", SMALL($AF$8:$AF$27,COUNTIF($AF$8:$AF$27,"<"&O19)+1), IF($C$7="Angular", SMALL($AH$8:$AH$27,COUNTIF($AH$8:$AH$27,"<"&O19)+1), IF($C$7="02-Series", SMALL($AC$62:$AC$82,COUNTIF($AC$62:$AC$82,"<"&O19)+1), IF($C$7="03-Series", SMALL($AG$62:$AG$82,COUNTIF($AG$62:$AG$82,"<"&O19)+1), NA())))) -> 70.2 | Q19: =IF($C$7="Deep Groove",VLOOKUP(P19,$AF$8:$AG$27,2,FALSE), IF($C$7="Angular", VLOOKUP(P19,$AH$8:$AI$27,2,FALSE), IF($C$7="02-Series", VLOOKUP(P19,$AC$62:$AD$82,2,FALSE), IF($C$7="03-Series", VLOOKUP(P19,$AG$62:$AH$82,2,FALSE), NA())))) -> 45 | Z19: 55 | AA19: 100 | AB19: 21 | AC19: 1.5 | AD19: 63 | AE19: 90 | AF19: 43.6 | AG19: 25 | AH19: 46.2 | AI19: 28.5
H20: 9 | I20: =IF($C$18/Q19 < 0.014, 0.014, $C$18/Q19) -> 0.014 | J20: =$C$18/($C$9*$C$16) -> 0 | K20: =0.506467531924409*(I20)^0.23203728471849 -> 0.18809801 | L20: =IF(J20<=K20,1,0.56) -> 1 | M20: =IF(J20<=K20,0,0.863191147423464*(I20)^(-0.234866270653838)) -> 0 | N20: =L20*$C$9*$C$16 + M20*$C$18 -> 8.4 | O20: =($C$19*N20)*($C$32/($C$29+($C$30-$C$29)*(LN($C$6^-1))^(1/$C$31)))^(1/$C$11) -> 69.33026 | P20: =IF($C$7="Deep Groove", SMALL($AF$8:$AF$27,COUNTIF($AF$8:$AF$27,"<"&O20)+1), IF($C$7="Angular", SMALL($AH$8:$AH$27,COUNTIF($AH$8:$AH$27,"<"&O20)+1), IF($C$7="02-Series", SMALL($AC$62:$AC$82,COUNTIF($AC$62:$AC$82,"<"&O20)+1), IF($C$7="03-Series", SMALL($AG$62:$AG$82,COUNTIF($AG$62:$AG$82,"<"&O20)+1), NA())))) -> 70.2 | Q20: =IF($C$7="Deep Groove",VLOOKUP(P20,$AF$8:$AG$27,2,FALSE), IF($C$7="Angular", VLOOKUP(P20,$AH$8:$AI$27,2,FALSE), IF($C$7="02-Series", VLOOKUP(P20,$AC$62:$AD$82,2,FALSE), IF($C$7="03-Series", VLOOKUP(P20,$AG$62:$AH$82,2,FALSE), NA())))) -> 45 | Z20: 60 | AA20: 110 | AB20: 22 | AC20: 1.5 | AD20: 70 | AE20: 99 | AF20: 47.5 | AG20: 28 | AH20: 55.9 | AI20: 35.5
B21: Design Cycle Lifetime | H21: 10 | I21: =IF($C$18/Q20 < 0.014, 0.014, $C$18/Q20) -> 0.014 | J21: =$C$18/($C$9*$C$16) -> 0 | K21: =0.506467531924409*(I21)^0.23203728471849 -> 0.18809801 | L21: =IF(J21<=K21,1,0.56) -> 1 | M21: =IF(J21<=K21,0,0.863191147423464*(I21)^(-0.234866270653838)) -> 0 | N21: =L21*$C$9*$C$16 + M21*$C$18 -> 8.4 | O21: =($C$19*N21)*($C$32/($C$29+($C$30-$C$29)*(LN($C$6^-1))^(1/$C$31)))^(1/$C$11) -> 69.33026 | P21: =IF($C$7="Deep Groove", SMALL($AF$8:$AF$27,COUNTIF($AF$8:$AF$27,"<"&O21)+1), IF($C$7="Angular", SMALL($AH$8:$AH$27,COUNTIF($AH$8:$AH$27,"<"&O21)+1), IF($C$7="02-Series", SMALL($AC$62:$AC$82,COUNTIF($AC$62:$AC$82,"<"&O21)+1), IF($C$7="03-Series", SMALL($AG$62:$AG$82,COUNTIF($AG$62:$AG$82,"<"&O21)+1), NA())))) -> 70.2 | Q21: =IF($C$7="Deep Groove",VLOOKUP(P21,$AF$8:$AG$27,2,FALSE), IF($C$7="Angular", VLOOKUP(P21,$AH$8:$AI$27,2,FALSE), IF($C$7="02-Series", VLOOKUP(P21,$AC$62:$AD$82,2,FALSE), IF($C$7="03-Series", VLOOKUP(P21,$AG$62:$AH$82,2,FALSE), NA())))) -> 45 | Z21: 65 | AA21: 120 | AB21: 23 | AC21: 1.5 | AD21: 74 | AE21: 109 | AF21: 55.9 | AG21: 34 | AH21: 63.7 | AI21: 41.5
B22: Lifetime, ℒD | C22: 10000 | D22: hrs | Z22: 70 | AA22: 125 | AB22: 24 | AC22: 1.5 | AD22: 79 | AE22: 114 | AF22: 61.8 | AG22: 37.5 | AH22: 68.9 | AI22: 45.5
B23: Rotation Speed, n | C23: 500 | D23: rpm | H23: Final Iterated Values | Z23: 75 | AA23: 130 | AB23: 25 | AC23: 1.5 | AD23: 86 | AE23: 119 | AF23: 66.3 | AG23: 40.5 | AH23: 71.5 | AI23: 49
B24: Design Lifetime, LD | C24: =IF(F25,C25,C22*C23*60) -> 300000000 | D24: revs | H24: Iterated C10 | I24: =P21 -> 70.2 | J24: kN | Z24: 80 | AA24: 140 | AB24: 26 | AC24: 2 | AD24: 93 | AE24: 127 | AF24: 70.2 | AG24: 45 | AH24: 80.6 | AI24: 55
C25: 100000000 | D25: revs | E25: Override LD | F25: FALSE | I25: =I24/4.448 -> 15.782374 | J25: klbf | Z25: 85 | AA25: 150 | AB25: 28 | AC25: 2 | AD25: 99 | AE25: 136 | AF25: 83.2 | AG25: 53 | AH25: 90.4 | AI25: 63
H26: Iterated C0 | I26: =Q21 -> 45 | J26: kN | Z26: 90 | AA26: 160 | AB26: 30 | AC26: 2 | AD26: 104 | AE26: 146 | AF26: 95.6 | AG26: 62 | AH26: 106 | AI26: 73.5
B27: Weibull Paramters Automattically Based on Bearing Brand | E27: RD for 90% = | F27: =EXP(-1*((1 - C29) / (C30 - C29))^C31) -> 0.8990379 | I27: =I26/4.448 -> 10.116906 | J27: klbf | Z27: 95 | AA27: 170 | AB27: 32 | AC27: 2 | AD27: 110 | AE27: 156 | AF27: 108 | AG27: 69.5 | AH27: 121 | AI27: 85
B28: Rating Life, L10 | C28: =IF(F36,C37,VLOOKUP($C$5,$T$6:$X$7,2,FALSE)) -> 1000000 | D28: revs
B29: x0 | C29: =IF(F36,C38,VLOOKUP($C$5,$T$6:$X$7,3,FALSE)) -> 0.02
B30: θ | C30: =IF(F36,C40,VLOOKUP($C$5,$T$6:$X$7,4,FALSE)) -> 4.459
B31: b | C31: =IF(F36,C42,VLOOKUP($C$5,$T$6:$X$7,5,FALSE)) -> 1.483
B32: Nomormalized Lifetime by Design, xD | C32: =IF(F33,C33,C24/C28) -> 300 | D32: revs
D33: revs | E33: Override xD | F33: FALSE
B34: Normalized Lifetime, xB | C34: =C29+(C30-C29)*(LN(C6^-1))^(1/C31) -> 0.53356905 | E34: For RD | F34: =C6 -> 0.96
B36: Weibull Parameters | E36: Override Weibull Parameters | F36: FALSE
B37: Rating Life, L10 | C37: =10^6 -> 1000000 | D37: revs
B38: x0 | C38: 0.02
B39: θ - x0 | C39: 4.439
B40: θ | C40: =IF(F41,C41,C39+C38) -> 4.459
D41: revs | E41: Override θ | F41: FALSE
B42: b | C42: 1.483
Z58: Table 11-3
...

Sheet Sprdsht Quiz 6 2
B2: INPUTS | C2: Units: | D2: Metric | H2: OUTPUTS | S2: Tables
B4: Bearing Design | H4: Initial Rated Load, C10, Fa = 0 | K4: =($C$19*$C$9*C16)*($C$32/($C$29+($C$30-$C$29)*(LN($C$6^-1))^(1/$C$31)))^(1/$C$11) -> 53.057174 | L4: kN | T4: Table 11-6 | Z4: Table 11-2 | AK4: Table 11-1
B5: Bearing Brand | C5: SKF | H5: C10 From Table 11.2, Fa = 0 | K5: =IF($C$7="Deep Groove", SMALL($AF$8:$AF$27,COUNTIF($AF$8:$AF$27,"<"&K4)+1), IF($C$7="Angular", SMALL($AH$8:$AH$27,COUNTIF($AH$8:$AH$27,"<"&K4)+1), IF($C$7="02-Series", SMALL($AC$62:$AC$82,COUNTIF($AC$62:$AC$82,"<"&K4)+1), IF($C$7="03-Series", SMALL($AG$62:$AG$82,COUNTIF($AG$62:$AG$82,"<"&K4)+1), NA())))) -> 55.9 | L5: kN | T5: Manufacturer | U5: Rating Life (revs) | V5: x0 | W5: θ | X5: b | Z5: Bore | AA5: OD | AB5: Width | AC5: Fillet Radius | AD5: Shoulder | AF5: Load Ratings | AK5: Fa/C0 | AL5: e | AM5: Fa/(VFr) <= e | AO5: Fa/(VFr) > e
B6: Design Reliability, RD | C6: 0.95 | E6: must be greater than 90% | H6: C0 From Table 11.2, Fa = 0 | K6: =IF($C$7="Deep Groove",VLOOKUP(K5,$AF$8:$AG$27,2,FALSE), IF($C$7="Angular", VLOOKUP(K5,$AH$8:$AI$27,2,FALSE), IF($C$7="02-Series", VLOOKUP(K5,$AC$62:$AD$82,2,FALSE), IF($C$7="03-Series", VLOOKUP(K5,$AG$62:$AH$82,2,FALSE), NA())))) -> 35.5 | L6: kN | T6: TIMKEN | U6: =90*10^6 -> 90000000 | V6: 0 | W6: 4.48 | X6: 1.5 | AD6: Diameter | AF6: Deep Groove | AH6: Angular | AM6: X1 | AN6: Y1 | AO6: X2 | AP6: Y2
B7: Contact Type | C7: Angular | H7: Fa/C0 | K7: =$C$18/K6 -> 0.028169014 | T7: SKF | U7: =1*10^6 -> 1000000 | V7: 0.02 | W7: 4.459 | X7: 1.483 | AD7: ds | AE7: dh | AF7: C10 | AG7: C0 | AH7: C10 | AI7: C0 | AK7: 0.014 | AL7: 0.19 | AM7: 1 | AN7: 0 | AO7: 0.56 | AP7: 2.3
B8: Which Ring Rotates | C8: Inner Ring | Z8: 10 | AA8: 30 | AB8: 9 | AC8: 0.6 | AD8: 12.5 | AE8: 27 | AF8: 5.07 | AG8: 2.24 | AH8: 4.94 | AI8: 2.12 | AK8: 0.021 | AL8: 0.21 | AM8: 1 | AN8: 0 | AO8: 0.56 | AP8: 2.15
B9: Rotating Ring Correction Factor, Vr | C9: =IF(C8="Inner Ring", 1, 1.2) -> 1 | H9: Iteration Table for C0 value | Z9: 12 | AA9: 32 | AB9: 10 | AC9: 0.6 | AD9: 14.5 | AE9: 28 | AF9: 6.89 | AG9: 3.1 | AH9: 7.02 | AI9: 3.05 | AK9: 0.028 | AL9: 0.22 | AM9: 1 | AN9: 0 | AO9: 0.56 | AP9: 1.99
B10: Bearing Type | C10: Ball | H10: Itteration # | I10: Fa/C0 | J10: Fa/(VFr) | K10: e | L10: X | M10: Y | N10: FE [kN] | O10: Updated Search C10 [kN] | P10: Updated C10 [kN] | Q10: Updated C0 [kN] | Z10: 15 | AA10: 35 | AB10: 11 | AC10: 0.6 | AD10: 17.5 | AE10: 31 | AF10: 7.8 | AG10: 3.55 | AH10: 8.06 | AI10: 3.65 | AK10: 0.042 | AL10: 0.24 | AM10: 1 | AN10: 0 | AO10: 0.56 | AP10: 1.85
B11: Power Law Exponent, a | C11: =IF(F12,C12,IF(C10="Ball", 3, 10/3)) -> 3 | H11: 0 | I11: =IF($C$18/K6 < 0.014, 0.014, $C$18/K6) -> 0.028169014 | J11: =$C$18/($C$9*$C$16) -> 0.33333333 | K11: =0.506467531924409*(I11)^0.23203728471849 -> 0.22122838 | L11: =IF(J11<=K11,1,0.56) -> 0.56 | M11: =IF(J11<=K11,0,0.863191147423464*(I11)^(-0.234866270653838)) -> 1.9961967 | N11: =L11*$C$9*$C$16 + M11*$C$18 -> 3.6761967 | O11: =($C$19*N11)*($C$32/($C$29+($C$30-$C$29)*(LN($C$6^-1))^(1/$C$31)))^(1/$C$11) -> 65.016202 | P11: =IF($C$7="Deep Groove", SMALL($AF$8:$AF$27,COUNTIF($AF$8:$AF$27,"<"&O11)+1), IF($C$7="Angular", SMALL($AH$8:$AH$27,COUNTIF($AH$8:$AH$27,"<"&O11)+1), IF($C$7="02-Series", SMALL($AC$62:$AC$82,COUNTIF($AC$62:$AC$82,"<"&O11)+1), IF($C$7="03-Series", SMALL($AG$62:$AG$82,COUNTIF($AG$62:$AG$82,"<"&O11)+1), NA())))) -> 68.9 | Q11: =IF($C$7="Deep Groove",VLOOKUP(P11,$AF$8:$AG$27,2,FALSE), IF($C$7="Angular", VLOOKUP(P11,$AH$8:$AI$27,2,FALSE), IF($C$7="02-Series", VLOOKUP(P11,$AC$62:$AD$82,2,FALSE), IF($C$7="03-Series", VLOOKUP(P11,$AG$62:$AH$82,2,FALSE), NA())))) -> 45.5 | Z11: 17 | AA11: 40 | AB11: 12 | AC11: 0.6 | AD11: 19.5 | AE11: 34 | AF11: 9.56 | AG11: 4.5 | AH11: 9.95 | AI11: 4.75 | AK11: 0.056 | AL11: 0.26 | AM11: 1 | AN11: 0 | AO11: 0.56 | AP11: 1.71
E12: Override a | F12: FALSE | H12: 1 | I12: =IF($C$18/Q11 < 0.014, 0.014, $C$18/Q11) -> 0.021978022 | J12: =$C$18/($C$9*$C$16) -> 0.33333333 | K12: =0.506467531924409*(I12)^0.23203728471849 -> 0.2088484 | L12: =IF(J12<=K12,1,0.56) -> 0.56 | M12: =IF(J12<=K12,0,0.863191147423464*(I12)^(-0.234866270653838)) -> 2.116011 | N12: =L12*$C$9*$C$16 + M12*$C$18 -> 3.796011 | O12: =($C$19*N12)*($C$32/($C$29+($C$30-$C$29)*(LN($C$6^-1))^(1/$C$31)))^(1/$C$11) -> 67.135206 | P12: =IF($C$7="Deep Groove", SMALL($AF$8:$AF$27,COUNTIF($AF$8:$AF$27,"<"&O12)+1), IF($C$7="Angular", SMALL($AH$8:$AH$27,COUNTIF($AH$8:$AH$27,"<"&O12)+1), IF($C$7="02-Series", SMALL($AC$62:$AC$82,COUNTIF($AC$62:$AC$82,"<"&O12)+1), IF($C$7="03-Series", SMALL($AG$62:$AG$82,COUNTIF($AG$62:$AG$82,"<"&O12)+1), NA())))) -> 68.9 | Q12: =IF($C$7="Deep Groove",VLOOKUP(P12,$AF$8:$AG$27,2,FALSE), IF($C$7="Angular", VLOOKUP(P12,$AH$8:$AI$27,2,FALSE), IF($C$7="02-Series", VLOOKUP(P12,$AC$62:$AD$82,2,FALSE), IF($C$7="03-Series", VLOOKUP(P12,$AG$62:$AH$82,2,FALSE), NA())))) -> 45.5 | Z12: 20 | AA12: 47 | AB12: 14 | AC12: 1 | AD12: 25 | AE12: 41 | AF12: 12.7 | AG12: 6.2 | AH12: 13.3 | AI12: 6.55 | AK12: 0.07 | AL12: 0.27 | AM12: 1 | AN12: 0 | AO12: 0.56 | AP12: 1.63
H13: 2 | I13: =IF($C$18/Q12 < 0.014, 0.014, $C$18/Q12) -> 0.021978022 | J13: =$C$18/($C$9*$C$16) -> 0.33333333 | K13: =0.506467531924409*(I13)^0.23203728471849 -> 0.2088484 | L13: =IF(J13<=K13,1,0.56) -> 0.56 | M13: =IF(J13<=K13,0,0.863191147423464*(I13)^(-0.234866270653838)) -> 2.116011 | N13: =L13*$C$9*$C$16 + M13*$C$18 -> 3.796011 | O13: =($C$19*N13)*($C$32/($C$29+($C$30-$C$29)*(LN($C$6^-1))^(1/$C$31)))^(1/$C$11) -> 67.135206 | P13: =IF($C$7="Deep Groove", SMALL($AF$8:$AF$27,COUNTIF($AF$8:$AF$27,"<"&O13)+1), IF($C$7="Angular", SMALL($AH$8:$AH$27,COUNTIF($AH$8:$AH$27,"<"&O13)+1), IF($C$7="02-Series", SMALL($AC$62:$AC$82,COUNTIF($AC$62:$AC$82,"<"&O13)+1), IF($C$7="03-Series", SMALL($AG$62:$AG$82,COUNTIF($AG$62:$AG$82,"<"&O13)+1), NA())))) -> 68.9 | Q13: =IF($C$7="Deep Groove",VLOOKUP(P13,$AF$8:$AG$27,2,FALSE), IF($C$7="Angular", VLOOKUP(P13,$AH$8:$AI$27,2,FALSE), IF($C$7="02-Series", VLOOKUP(P13,$AC$62:$AD$82,2,FALSE), IF($C$7="03-Series", VLOOKUP(P13,$AG$62:$AH$82,2,FALSE), NA())))) -> 45.5 | Z13: 25 | AA13: 52 | AB13: 15 | AC13: 1 | AD13: 30 | AE13: 47 | AF13: 14 | AG13: 6.95 | AH13: 14.8 | AI13: 7.65 | AK13: 0.084 | AL13: 0.28 | AM13: 1 | AN13: 0 | AO13: 0.56 | AP13: 1.55
B14: Bearing Loads | H14: 3 | I14: =IF($C$18/Q13 < 0.014, 0.014, $C$18/Q13) -> 0.021978022 | J14: =$C$18/($C$9*$C$16) -> 0.33333333 | K14: =0.506467531924409*(I14)^0.23203728471849 -> 0.2088484 | L14: =IF(J14<=K14,1,0.56) -> 0.56 | M14: =IF(J14<=K14,0,0.863191147423464*(I14)^(-0.234866270653838)) -> 2.116011 | N14: =L14*$C$9*$C$16 + M14*$C$18 -> 3.796011 | O14: =($C$19*N14)*($C$32/($C$29+($C$30-$C$29)*(LN($C$6^-1))^(1/$C$31)))^(1/$C$11) -> 67.135206 | P14: =IF($C$7="Deep Groove", SMALL($AF$8:$AF$27,COUNTIF($AF$8:$AF$27,"<"&O14)+1), IF($C$7="Angular", SMALL($AH$8:$AH$27,COUNTIF($AH$8:$AH$27,"<"&O14)+1), IF($C$7="02-Series", SMALL($AC$62:$AC$82,COUNTIF($AC$62:$AC$82,"<"&O14)+1), IF($C$7="03-Series", SMALL($AG$62:$AG$82,COUNTIF($AG$62:$AG$82,"<"&O14)+1), NA())))) -> 68.9 | Q14: =IF($C$7="Deep Groove",VLOOKUP(P14,$AF$8:$AG$27,2,FALSE), IF($C$7="Angular", VLOOKUP(P14,$AH$8:$AI$27,2,FALSE), IF($C$7="02-Series", VLOOKUP(P14,$AC$62:$AD$82,2,FALSE), IF($C$7="03-Series", VLOOKUP(P14,$AG$62:$AH$82,2,FALSE), NA())))) -> 45.5 | Z14: 30 | AA14: 62 | AB14: 16 | AC14: 1 | AD14: 35 | AE14: 55 | AF14: 19.5 | AG14: 10 | AH14: 20.3 | AI14: 11 | AK14: 0.11 | AL14: 0.3 | AM14: 1 | AN14: 0 | AO14: 0.56 | AP14: 1.45
B15: Input Radial Load, Fr | C15: 3 | D15: =IF($D$2="English","klbf", "kN") -> kN | H15: 4 | I15: =IF($C$18/Q14 < 0.014, 0.014, $C$18/Q14) -> 0.021978022 | J15: =$C$18/($C$9*$C$16) -> 0.33333333 | K15: =0.506467531924409*(I15)^0.23203728471849 -> 0.2088484 | L15: =IF(J15<=K15,1,0.56) -> 0.56 | M15: =IF(J15<=K15,0,0.863191147423464*(I15)^(-0.234866270653838)) -> 2.116011 | N15: =L15*$C$9*$C$16 + M15*$C$18 -> 3.796011 | O15: =($C$19*N15)*($C$32/($C$29+($C$30-$C$29)*(LN($C$6^-1))^(1/$C$31)))^(1/$C$11) -> 67.135206 | P15: =IF($C$7="Deep Groove", SMALL($AF$8:$AF$27,COUNTIF($AF$8:$AF$27,"<"&O15)+1), IF($C$7="Angular", SMALL($AH$8:$AH$27,COUNTIF($AH$8:$AH$27,"<"&O15)+1), IF($C$7="02-Series", SMALL($AC$62:$AC$82,COUNTIF($AC$62:$AC$82,"<"&O15)+1), IF($C$7="03-Series", SMALL($AG$62:$AG$82,COUNTIF($AG$62:$AG$82,"<"&O15)+1), NA())))) -> 68.9 | Q15: =IF($C$7="Deep Groove",VLOOKUP(P15,$AF$8:$AG$27,2,FALSE), IF($C$7="Angular", VLOOKUP(P15,$AH$8:$AI$27,2,FALSE), IF($C$7="02-Series", VLOOKUP(P15,$AC$62:$AD$82,2,FALSE), IF($C$7="03-Series", VLOOKUP(P15,$AG$62:$AH$82,2,FALSE), NA())))) -> 45.5 | Z15: 35 | AA15: 72 | AB15: 17 | AC15: 1 | AD15: 41 | AE15: 65 | AF15: 25.5 | AG15: 13.7 | AH15: 27 | AI15: 15 | AK15: 0.17 | AL15: 0.34 | AM15: 1 | AN15: 0 | AO15: 0.56 | AP15: 1.31
C16: =IF($D$2="English",C15*4.448, C15) -> 3 | D16: kN | H16: 5 | I16: =IF($C$18/Q15 < 0.014, 0.014, $C$18/Q15) -> 0.021978022 | J16: =$C$18/($C$9*$C$16) -> 0.33333333 | K16: =0.506467531924409*(I16)^0.23203728471849 -> 0.2088484 | L16: =IF(J16<=K16,1,0.56) -> 0.56 | M16: =IF(J16<=K16,0,0.863191147423464*(I16)^(-0.234866270653838)) -> 2.116011 | N16: =L16*$C$9*$C$16 + M16*$C$18 -> 3.796011 | O16: =($C$19*N16)*($C$32/($C$29+($C$30-$C$29)*(LN($C$6^-1))^(1/$C$31)))^(1/$C$11) -> 67.135206 | P16: =IF($C$7="Deep Groove", SMALL($AF$8:$AF$27,COUNTIF($AF$8:$AF$27,"<"&O16)+1), IF($C$7="Angular", SMALL($AH$8:$AH$27,COUNTIF($AH$8:$AH$27,"<"&O16)+1), IF($C$7="02-Series", SMALL($AC$62:$AC$82,COUNTIF($AC$62:$AC$82,"<"&O16)+1), IF($C$7="03-Series", SMALL($AG$62:$AG$82,COUNTIF($AG$62:$AG$82,"<"&O16)+1), NA())))) -> 68.9 | Q16: =IF($C$7="Deep Groove",VLOOKUP(P16,$AF$8:$AG$27,2,FALSE), IF($C$7="Angular", VLOOKUP(P16,$AH$8:$AI$27,2,FALSE), IF($C$7="02-Series", VLOOKUP(P16,$AC$62:$AD$82,2,FALSE), IF($C$7="03-Series", VLOOKUP(P16,$AG$62:$AH$82,2,FALSE), NA())))) -> 45.5 | Z16: 40 | AA16: 80 | AB16: 18 | AC16: 1 | AD16: 46 | AE16: 72 | AF16: 30.7 | AG16: 16.6 | AH16: 31.9 | AI16: 18.6 | AK16: 0.28 | AL16: 0.38 | AM16: 1 | AN16: 0 | AO16: 0.56 | AP16: 1.15
B17: Input Axial Load, FA | C17: 1 | D17: =IF($D$2="English","klbf", "kN") -> kN | H17: 6 | I17: =IF($C$18/Q16 < 0.014, 0.014, $C$18/Q16) -> 0.021978022 | J17: =$C$18/($C$9*$C$16) -> 0.33333333 | K17: =0.506467531924409*(I17)^0.23203728471849 -> 0.2088484 | L17: =IF(J17<=K17,1,0.56) -> 0.56 | M17: =IF(J17<=K17,0,0.863191147423464*(I17)^(-0.234866270653838)) -> 2.116011 | N17: =L17*$C$9*$C$16 + M17*$C$18 -> 3.796011 | O17: =($C$19*N17)*($C$32/($C$29+($C$30-$C$29)*(LN($C$6^-1))^(1/$C$31)))^(1/$C$11) -> 67.135206 | P17: =IF($C$7="Deep Groove", SMALL($AF$8:$AF$27,COUNTIF($AF$8:$AF$27,"<"&O17)+1), IF($C$7="Angular", SMALL($AH$8:$AH$27,COUNTIF($AH$8:$AH$27,"<"&O17)+1), IF($C$7="02-Series", SMALL($AC$62:$AC$82,COUNTIF($AC$62:$AC$82,"<"&O17)+1), IF($C$7="03-Series", SMALL($AG$62:$AG$82,COUNTIF($AG$62:$AG$82,"<"&O17)+1), NA())))) -> 68.9 | Q17: =IF($C$7="Deep Groove",VLOOKUP(P17,$AF$8:$AG$27,2,FALSE), IF($C$7="Angular", VLOOKUP(P17,$AH$8:$AI$27,2,FALSE), IF($C$7="02-Series", VLOOKUP(P17,$AC$62:$AD$82,2,FALSE), IF($C$7="03-Series", VLOOKUP(P17,$AG$62:$AH$82,2,FALSE), NA())))) -> 45.5 | Z17: 45 | AA17: 85 | AB17: 19 | AC17: 1 | AD17: 52 | AE17: 77 | AF17: 33.2 | AG17: 18.6 | AH17: 35.8 | AI17: 21.2 | AK17: 0.42 | AL17: 0.42 | AM17: 1 | AN17: 0 | AO17: 0.56 | AP17: 1.04
C18: =IF($D$2="English",C17*4.448, C17) -> 1 | D18: kN | H18: 7 | I18: =IF($C$18/Q17 < 0.014, 0.014, $C$18/Q17) -> 0.021978022 | J18: =$C$18/($C$9*$C$16) -> 0.33333333 | K18: =0.506467531924409*(I18)^0.23203728471849 -> 0.2088484 | L18: =IF(J18<=K18,1,0.56) -> 0.56 | M18: =IF(J18<=K18,0,0.863191147423464*(I18)^(-0.234866270653838)) -> 2.116011 | N18: =L18*$C$9*$C$16 + M18*$C$18 -> 3.796011 | O18: =($C$19*N18)*($C$32/($C$29+($C$30-$C$29)*(LN($C$6^-1))^(1/$C$31)))^(1/$C$11) -> 67.135206 | P18: =IF($C$7="Deep Groove", SMALL($AF$8:$AF$27,COUNTIF($AF$8:$AF$27,"<"&O18)+1), IF($C$7="Angular", SMALL($AH$8:$AH$27,COUNTIF($AH$8:$AH$27,"<"&O18)+1), IF($C$7="02-Series", SMALL($AC$62:$AC$82,COUNTIF($AC$62:$AC$82,"<"&O18)+1), IF($C$7="03-Series", SMALL($AG$62:$AG$82,COUNTIF($AG$62:$AG$82,"<"&O18)+1), NA())))) -> 68.9 | Q18: =IF($C$7="Deep Groove",VLOOKUP(P18,$AF$8:$AG$27,2,FALSE), IF($C$7="Angular", VLOOKUP(P18,$AH$8:$AI$27,2,FALSE), IF($C$7="02-Series", VLOOKUP(P18,$AC$62:$AD$82,2,FALSE), IF($C$7="03-Series", VLOOKUP(P18,$AG$62:$AH$82,2,FALSE), NA())))) -> 45.5 | Z18: 50 | AA18: 90 | AB18: 20 | AC18: 1 | AD18: 56 | AE18: 82 | AF18: 35.1 | AG18: 19.6 | AH18: 37.7 | AI18: 22.8 | AK18: 0.56 | AL18: 0.44 | AM18: 1 | AN18: 0 | AO18: 0.56 | AP18: 1
B19: Load Application Factor, af | C19: 1.4 | H19: 8 | I19: =IF($C$18/Q18 < 0.014, 0.014, $C$18/Q18) -> 0.021978022 | J19: =$C$18/($C$9*$C$16) -> 0.33333333 | K19: =0.506467531924409*(I19)^0.23203728471849 -> 0.2088484 | L19: =IF(J19<=K19,1,0.56) -> 0.56 | M19: =IF(J19<=K19,0,0.863191147423464*(I19)^(-0.234866270653838)) -> 2.116011 | N19: =L19*$C$9*$C$16 + M19*$C$18 -> 3.796011 | O19: =($C$19*N19)*($C$32/($C$29+($C$30-$C$29)*(LN($C$6^-1))^(1/$C$31)))^(1/$C$11) -> 67.135206 | P19: =IF($C$7="Deep Groove", SMALL($AF$8:$AF$27,COUNTIF($AF$8:$AF$27,"<"&O19)+1), IF($C$7="Angular", SMALL($AH$8:$AH$27,COUNTIF($AH$8:$AH$27,"<"&O19)+1), IF($C$7="02-Series", SMALL($AC$62:$AC$82,COUNTIF($AC$62:$AC$82,"<"&O19)+1), IF($C$7="03-Series", SMALL($AG$62:$AG$82,COUNTIF($AG$62:$AG$82,"<"&O19)+1), NA())))) -> 68.9 | Q19: =IF($C$7="Deep Groove",VLOOKUP(P19,$AF$8:$AG$27,2,FALSE), IF($C$7="Angular", VLOOKUP(P19,$AH$8:$AI$27,2,FALSE), IF($C$7="02-Series", VLOOKUP(P19,$AC$62:$AD$82,2,FALSE), IF($C$7="03-Series", VLOOKUP(P19,$AG$62:$AH$82,2,FALSE), NA())))) -> 45.5 | Z19: 55 | AA19: 100 | AB19: 21 | AC19: 1.5 | AD19: 63 | AE19: 90 | AF19: 43.6 | AG19: 25 | AH19: 46.2 | AI19: 28.5
H20: 9 | I20: =IF($C$18/Q19 < 0.014, 0.014, $C$18/Q19) -> 0.021978022 | J20: =$C$18/($C$9*$C$16) -> 0.33333333 | K20: =0.506467531924409*(I20)^0.23203728471849 -> 0.2088484 | L20: =IF(J20<=K20,1,0.56) -> 0.56 | M20: =IF(J20<=K20,0,0.863191147423464*(I20)^(-0.234866270653838)) -> 2.116011 | N20: =L20*$C$9*$C$16 + M20*$C$18 -> 3.796011 | O20: =($C$19*N20)*($C$32/($C$29+($C$30-$C$29)*(LN($C$6^-1))^(1/$C$31)))^(1/$C$11) -> 67.135206 | P20: =IF($C$7="Deep Groove", SMALL($AF$8:$AF$27,COUNTIF($AF$8:$AF$27,"<"&O20)+1), IF($C$7="Angular", SMALL($AH$8:$AH$27,COUNTIF($AH$8:$AH$27,"<"&O20)+1), IF($C$7="02-Series", SMALL($AC$62:$AC$82,COUNTIF($AC$62:$AC$82,"<"&O20)+1), IF($C$7="03-Series", SMALL($AG$62:$AG$82,COUNTIF($AG$62:$AG$82,"<"&O20)+1), NA())))) -> 68.9 | Q20: =IF($C$7="Deep Groove",VLOOKUP(P20,$AF$8:$AG$27,2,FALSE), IF($C$7="Angular", VLOOKUP(P20,$AH$8:$AI$27,2,FALSE), IF($C$7="02-Series", VLOOKUP(P20,$AC$62:$AD$82,2,FALSE), IF($C$7="03-Series", VLOOKUP(P20,$AG$62:$AH$82,2,FALSE), NA())))) -> 45.5 | Z20: 60 | AA20: 110 | AB20: 22 | AC20: 1.5 | AD20: 70 | AE20: 99 | AF20: 47.5 | AG20: 28 | AH20: 55.9 | AI20: 35.5
B21: Design Cycle Lifetime | H21: 10 | I21: =IF($C$18/Q20 < 0.014, 0.014, $C$18/Q20) -> 0.021978022 | J21: =$C$18/($C$9*$C$16) -> 0.33333333 | K21: =0.506467531924409*(I21)^0.23203728471849 -> 0.2088484 | L21: =IF(J21<=K21,1,0.56) -> 0.56 | M21: =IF(J21<=K21,0,0.863191147423464*(I21)^(-0.234866270653838)) -> 2.116011 | N21: =L21*$C$9*$C$16 + M21*$C$18 -> 3.796011 | O21: =($C$19*N21)*($C$32/($C$29+($C$30-$C$29)*(LN($C$6^-1))^(1/$C$31)))^(1/$C$11) -> 67.135206 | P21: =IF($C$7="Deep Groove", SMALL($AF$8:$AF$27,COUNTIF($AF$8:$AF$27,"<"&O21)+1), IF($C$7="Angular", SMALL($AH$8:$AH$27,COUNTIF($AH$8:$AH$27,"<"&O21)+1), IF($C$7="02-Series", SMALL($AC$62:$AC$82,COUNTIF($AC$62:$AC$82,"<"&O21)+1), IF($C$7="03-Series", SMALL($AG$62:$AG$82,COUNTIF($AG$62:$AG$82,"<"&O21)+1), NA())))) -> 68.9 | Q21: =IF($C$7="Deep Groove",VLOOKUP(P21,$AF$8:$AG$27,2,FALSE), IF($C$7="Angular", VLOOKUP(P21,$AH$8:$AI$27,2,FALSE), IF($C$7="02-Series", VLOOKUP(P21,$AC$62:$AD$82,2,FALSE), IF($C$7="03-Series", VLOOKUP(P21,$AG$62:$AH$82,2,FALSE), NA())))) -> 45.5 | Z21: 65 | AA21: 120 | AB21: 23 | AC21: 1.5 | AD21: 74 | AE21: 109 | AF21: 55.9 | AG21: 34 | AH21: 63.7 | AI21: 41.5
B22: Lifetime, ℒD | C22: 40000 | D22: hrs | Z22: 70 | AA22: 125 | AB22: 24 | AC22: 1.5 | AD22: 79 | AE22: 114 | AF22: 61.8 | AG22: 37.5 | AH22: 68.9 | AI22: 45.5
B23: Rotation Speed, n | C23: 520 | D23: rpm | H23: Final Iterated Values | Z23: 75 | AA23: 130 | AB23: 25 | AC23: 1.5 | AD23: 86 | AE23: 119 | AF23: 66.3 | AG23: 40.5 | AH23: 71.5 | AI23: 49
B24: Design Lifetime, LD | C24: =IF(F25,C25,C22*C23*60) -> 1248000000 | D24: revs | H24: Iterated C10 | I24: =P21 -> 68.9 | J24: kN | Z24: 80 | AA24: 140 | AB24: 26 | AC24: 2 | AD24: 93 | AE24: 127 | AF24: 70.2 | AG24: 45 | AH24: 80.6 | AI24: 55
C25: 100000000 | D25: revs | E25: Override LD | F25: FALSE | I25: =I24/4.448 -> 15.490108 | J25: klbf | Z25: 85 | AA25: 150 | AB25: 28 | AC25: 2 | AD25: 99 | AE25: 136 | AF25: 83.2 | AG25: 53 | AH25: 90.4 | AI25: 63
H26: Iterated C0 | I26: =Q21 -> 45.5 | J26: kN | Z26: 90 | AA26: 160 | AB26: 30 | AC26: 2 | AD26: 104 | AE26: 146 | AF26: 95.6 | AG26: 62 | AH26: 106 | AI26: 73.5
B27: Weibull Paramters Automattically Based on Bearing Brand | E27: RD for 90% = | F27: =EXP(-1*((1 - C29) / (C30 - C29))^C31) -> 0.8990379 | I27: =I26/4.448 -> 10.229317 | J27: klbf | Z27: 95 | AA27: 170 | AB27: 32 | AC27: 2 | AD27: 110 | AE27: 156 | AF27: 108 | AG27: 69.5 | AH27: 121 | AI27: 85
B28: Rating Life, L10 | C28: =IF(F36,C37,VLOOKUP($C$5,$T$6:$X$7,2,FALSE)) -> 1000000 | D28: revs
B29: x0 | C29: =IF(F36,C38,VLOOKUP($C$5,$T$6:$X$7,3,FALSE)) -> 0.02
B30: θ | C30: =IF(F36,C40,VLOOKUP($C$5,$T$6:$X$7,4,FALSE)) -> 4.459
B31: b | C31: =IF(F36,C42,VLOOKUP($C$5,$T$6:$X$7,5,FALSE)) -> 1.483
B32: Nomormalized Lifetime by Design, xD | C32: =IF(F33,C33,C24/C28) -> 1248 | D32: revs
D33: revs | E33: Override xD | F33: FALSE
B34: Normalized Lifetime, xB | C34: =C29+(C30-C29)*(LN(C6^-1))^(1/C31) -> 0.61905626 | E34: For RD | F34: =C6 -> 0.95
B36: Weibull Parameters | E36: Override Weibull Parameters | F36: FALSE
B37: Rating Life, L10 | C37: =10^6 -> 1000000 | D37: revs
B38: x0 | C38: 0.02
B39: θ - x0 | C39: 4.439
B40: θ | C40: =IF(F41,C41,C39+C38) -> 4.459
D41: revs | E41: Override θ | F41: FALSE
B42: b | C42: 1.483
Z58: Table 11-3
...

Sheet Shaft Moments Sprdsht Quiz 6 P3
I1: =_xlfn.CONCAT("x"," [",G2,"]") -> x [in] | J1: =_xlfn.CONCAT("moment about the z-axis"," [*10^3 ", E25,"]") -> moment about the z-axis [*10^3 in-lbf] | K1: =_xlfn.CONCAT("moment about the y-axis"," [*10^3 ", E25,"]") -> moment about the y-axis [*10^3 in-lbf] | L1: =_xlfn.CONCAT("Net Moment"," [*10^3 ", E25,"]") -> Net Moment [*10^3 in-lbf]
C2: Inputs | E2: step size | F2: =D5/1000 -> 0.04 | G2: =IF($D$4="English","in", "mm") -> in | I2: 0 | J2: =D$29*($I2/1000)+D$18*(($I2/1000)-($D$8/1000))*(($I2/1000)>($D$8/1000))+D$19*(($I2/1000)-($D$9/1000))*(($I2/1000)>($D$9/1000))+D$20*(($I2/1000)-($D$10/1000))*(($I2/1000)>($D$10/1000))+D$21*(($I2/1000)-($D$11/1000))*(($I2/1000)>($D$11/1000)) -> 0 | K2: =E$29*($I2/1000)+E$18*(($I2/1000)-($D$8/1000))*(($I2/1000)>($D$8/1000))+E$19*(($I2/1000)-($D$9/1000))*(($I2/1000)>($D$9/1000))+E$20*(($I2/1000)-($D$10/1000))*(($I2/1000)>($D$10/1000))+E$21*(($I2/1000)-($D$11/1000))*(($I2/1000)>($D$11/1000)) -> 0 | L2: =SQRT((J2^2)+(K2^2)) -> 0
I3: =IF((ROW(A1)*$F$2)<=$D$5, ROW(A1)*$F$2,NA()) -> 0.04 | J3: =D$29*($I3/1000)+D$18*(($I3/1000)-($D$8/1000))*(($I3/1000)>($D$8/1000))+D$19*(($I3/1000)-($D$9/1000))*(($I3/1000)>($D$9/1000))+D$20*(($I3/1000)-($D$10/1000))*(($I3/1000)>($D$10/1000))+D$21*(($I3/1000)-($D$11/1000))*(($I3/1000)>($D$11/1000)) -> 0 | K3: =E$29*($I3/1000)+E$18*(($I3/1000)-($D$8/1000))*(($I3/1000)>($D$8/1000))+E$19*(($I3/1000)-($D$9/1000))*(($I3/1000)>($D$9/1000))+E$20*(($I3/1000)-($D$10/1000))*(($I3/1000)>($D$10/1000))+E$21*(($I3/1000)-($D$11/1000))*(($I3/1000)>($D$11/1000)) -> -0.01173 | L3: =SQRT((J3^2)+(K3^2)) -> 0.01173
C4: Units | D4: English | I4: =IF((ROW(A2)*$F$2)<=$D$5, ROW(A2)*$F$2,NA()) -> 0.08 | J4: =D$29*($I4/1000)+D$18*(($I4/1000)-($D$8/1000))*(($I4/1000)>($D$8/1000))+D$19*(($I4/1000)-($D$9/1000))*(($I4/1000)>($D$9/1000))+D$20*(($I4/1000)-($D$10/1000))*(($I4/1000)>($D$10/1000))+D$21*(($I4/1000)-($D$11/1000))*(($I4/1000)>($D$11/1000)) -> 0 | K4: =E$29*($I4/1000)+E$18*(($I4/1000)-($D$8/1000))*(($I4/1000)>($D$8/1000))+E$19*(($I4/1000)-($D$9/1000))*(($I4/1000)>($D$9/1000))+E$20*(($I4/1000)-($D$10/1000))*(($I4/1000)>($D$10/1000))+E$21*(($I4/1000)-($D$11/1000))*(($I4/1000)>($D$11/1000)) -> -0.02346 | L4: =SQRT((J4^2)+(K4^2)) -> 0.02346
C5: Shaft Length | D5: =10+18+12 -> 40 | E5: =IF($D$4="English","in", "mm") -> in | I5: =IF((ROW(A3)*$F$2)<=$D$5, ROW(A3)*$F$2,NA()) -> 0.12 | J5: =D$29*($I5/1000)+D$18*(($I5/1000)-($D$8/1000))*(($I5/1000)>($D$8/1000))+D$19*(($I5/1000)-($D$9/1000))*(($I5/1000)>($D$9/1000))+D$20*(($I5/1000)-($D$10/1000))*(($I5/1000)>($D$10/1000))+D$21*(($I5/1000)-($D$11/1000))*(($I5/1000)>($D$11/1000)) -> 0 | K5: =E$29*($I5/1000)+E$18*(($I5/1000)-($D$8/1000))*(($I5/1000)>($D$8/1000))+E$19*(($I5/1000)-($D$9/1000))*(($I5/1000)>($D$9/1000))+E$20*(($I5/1000)-($D$10/1000))*(($I5/1000)>($D$10/1000))+E$21*(($I5/1000)-($D$11/1000))*(($I5/1000)>($D$11/1000)) -> -0.03519 | L5: =SQRT((J5^2)+(K5^2)) -> 0.03519
I6: =IF((ROW(A4)*$F$2)<=$D$5, ROW(A4)*$F$2,NA()) -> 0.16 | J6: =D$29*($I6/1000)+D$18*(($I6/1000)-($D$8/1000))*(($I6/1000)>($D$8/1000))+D$19*(($I6/1000)-($D$9/1000))*(($I6/1000)>($D$9/1000))+D$20*(($I6/1000)-($D$10/1000))*(($I6/1000)>($D$10/1000))+D$21*(($I6/1000)-($D$11/1000))*(($I6/1000)>($D$11/1000)) -> 0 | K6: =E$29*($I6/1000)+E$18*(($I6/1000)-($D$8/1000))*(($I6/1000)>($D$8/1000))+E$19*(($I6/1000)-($D$9/1000))*(($I6/1000)>($D$9/1000))+E$20*(($I6/1000)-($D$10/1000))*(($I6/1000)>($D$10/1000))+E$21*(($I6/1000)-($D$11/1000))*(($I6/1000)>($D$11/1000)) -> -0.04692 | L6: =SQRT((J6^2)+(K6^2)) -> 0.04692
C7: Location of forces along axis | I7: =IF((ROW(A5)*$F$2)<=$D$5, ROW(A5)*$F$2,NA()) -> 0.2 | J7: =D$29*($I7/1000)+D$18*(($I7/1000)-($D$8/1000))*(($I7/1000)>($D$8/1000))+D$19*(($I7/1000)-($D$9/1000))*(($I7/1000)>($D$9/1000))+D$20*(($I7/1000)-($D$10/1000))*(($I7/1000)>($D$10/1000))+D$21*(($I7/1000)-($D$11/1000))*(($I7/1000)>($D$11/1000)) -> 0 | K7: =E$29*($I7/1000)+E$18*(($I7/1000)-($D$8/1000))*(($I7/1000)>($D$8/1000))+E$19*(($I7/1000)-($D$9/1000))*(($I7/1000)>($D$9/1000))+E$20*(($I7/1000)-($D$10/1000))*(($I7/1000)>($D$10/1000))+E$21*(($I7/1000)-($D$11/1000))*(($I7/1000)>($D$11/1000)) -> -0.05865 | L7: =SQRT((J7^2)+(K7^2)) -> 0.05865
B8: 500lb | C8: Force 1 | D8: 10 | E8: =IF($D$4="English","in", "mm") -> in | I8: =IF((ROW(A6)*$F$2)<=$D$5, ROW(A6)*$F$2,NA()) -> 0.24 | J8: =D$29*($I8/1000)+D$18*(($I8/1000)-($D$8/1000))*(($I8/1000)>($D$8/1000))+D$19*(($I8/1000)-($D$9/1000))*(($I8/1000)>($D$9/1000))+D$20*(($I8/1000)-($D$10/1000))*(($I8/1000)>($D$10/1000))+D$21*(($I8/1000)-($D$11/1000))*(($I8/1000)>($D$11/1000)) -> 0 | K8: =E$29*($I8/1000)+E$18*(($I8/1000)-($D$8/1000))*(($I8/1000)>($D$8/1000))+E$19*(($I8/1000)-($D$9/1000))*(($I8/1000)>($D$9/1000))+E$20*(($I8/1000)-($D$10/1000))*(($I8/1000)>($D$10/1000))+E$21*(($I8/1000)-($D$11/1000))*(($I8/1000)>($D$11/1000)) -> -0.07038 | L8: =SQRT((J8^2)+(K8^2)) -> 0.07038
B9: 75lb | C9: Force 2 | D9: 10 | E9: =IF($D$4="English","in", "mm") -> in | I9: =IF((ROW(A7)*$F$2)<=$D$5, ROW(A7)*$F$2,NA()) -> 0.28 | J9: =D$29*($I9/1000)+D$18*(($I9/1000)-($D$8/1000))*(($I9/1000)>($D$8/1000))+D$19*(($I9/1000)-($D$9/1000))*(($I9/1000)>($D$9/1000))+D$20*(($I9/1000)-($D$10/1000))*(($I9/1000)>($D$10/1000))+D$21*(($I9/1000)-($D$11/1000))*(($I9/1000)>($D$11/1000)) -> 0 | K9: =E$29*($I9/1000)+E$18*(($I9/1000)-($D$8/1000))*(($I9/1000)>($D$8/1000))+E$19*(($I9/1000)-($D$9/1000))*(($I9/1000)>($D$9/1000))+E$20*(($I9/1000)-($D$10/1000))*(($I9/1000)>($D$10/1000))+E$21*(($I9/1000)-($D$11/1000))*(($I9/1000)>($D$11/1000)) -> -0.08211 | L9: =SQRT((J9^2)+(K9^2)) -> 0.08211
