Workbook

Sheet L25 Gears Cont.
S2: Table 13-1
B3: INPUTS | C3: Units: | D3: English | H3: OUTPUTS | S3: Tooth System | T3: Pressure Angle (ϕ) [deg] | U3: =IF($D$3="English","Addendum (a)/P", "Addendum (a)*m") -> Addendum (a)/P | V3: =IF($D$3="English","Dedendum (b)/P", "Dedendum (b)*m") -> Dedendum (b)/P | W3: 2nd row
S4: Full depth | T4: 20 | U4: 1 | V4: 1.25 | W4: 1.35/P or 1.35m
B5: All Gears Inputs | H5: All Gears Outputs | S5: Full depth | T5: 22.5 | U5: 1 | V5: 1.25 | W5: 1.35/P or 1.35m
B6: Tooth System | C6: Full depth | H6: Speed Ratio: Pinion/Gear | I6: =C24/C35 -> 2.5 | J6: - | S6: Full depth | T6: 25 | U6: 1 | V6: 1.25 | W6: 1.35/P or 1.35m
B7: Pressure Angle, ϕ | C7: 20 | D7: deg | H7: C-C dist. Pinion & Gear | I7: =I26/2 + I37/2 -> 6.3 | J7: =IF($D$3="English","in", "mm") -> in | S7: Stub | T7: 20 | U7: 0.8 | V7: 1
H8: Addendum, a | I8: =IF($D$3="English",VLOOKUP($C$7,$T$11:$V$13,2,FALSE)/I11, VLOOKUP($C$7,$T$11:$V$13,2,FALSE)*I11) -> 0.2 | J8: =IF($D$3="English","in", "mm") -> in
H9: Dedendum, b | I9: =IF($D$3="English",VLOOKUP($C$7,$T$11:$V$13,3,FALSE)/I11, VLOOKUP($C$7,$T$11:$V$13,3,FALSE)*I11) -> 0.25 | J9: =IF($D$3="English","in", "mm") -> in
H10: Tooth Clearance | I10: =I9-I8 -> 0.05 | J10: =IF($D$3="English","in", "mm") -> in
H11: =IF($D$3="English","Diametrial Pitch, P (N/d)", "Module, m (d/N)") -> Diametrial Pitch, P (N/d) | I11: =C31 -> 5 | J11: =IF($D$3="English","teeth/in", "mm/tooth") -> teeth/in | S11: {=_xlfn._xlws.FILTER(S4:V7,S4:S7=C6,S8:V10=NA())} -> Full depth | T11: 20 | U11: 1 | V11: 1.25
H12: Circular pitch, p | I12: =PI()*I26/I25 -> 0.62831853 | J12: =IF($D$3="English","in", "mm") -> in | S12: Full depth | T12: 22.5 | U12: 1 | V12: 1.25
H13: Pitch Line Velocity, V | I13: =I24*I26/2 -> 339.29201 | J13: =IF($D$3="English","in/s", "mm/s") -> in/s | S13: Full depth | T13: 25 | U13: 1 | V13: 1.25
I14: =IF($D$3="English",I13*(1/12)*60, I13*60) -> 1696.46 | J14: =IF($D$3="English","ft/min", "mm/min") -> ft/min
H15: Tangential Load, Wt | I15: =IF($D$3="English",33000, 60000)*C20/I14 -> 622.47267 | J15: =IF($D$3="English","lbf", "kN") -> lbf
H16: Radial Load, Wr | I16: =I15*TAN(RADIANS(C7)) -> 226.56152 | J16: =IF($D$3="English","lbf", "kN") -> lbf
H17: Input Torque, Tin | I17: =I15*I26/2 -> 1120.4508 | J17: =IF($D$3="English","in-lbf", "N-m") -> in-lbf
I18: =IF($D$3="English",I17*(1/12), I17) -> 93.3709 | J18: =IF($D$3="English","ft-lbf", "N-m") -> ft-lbf
B19: Power Input to Gear 2 (Pinion) | H19: Output Torque, Tout | I19: =I15*I37/2 -> 2801.127 | J19: =IF($D$3="English","in-lbf", "N-m") -> in-lbf
B20: Input Power, H | C20: 32 | D20: =IF($D$3="English","hp", "kN") -> hp | I20: =IF($D$3="English",I19*(1/12), I19) -> 233.42725 | J20: =IF($D$3="English","ft-lbf", "N-m") -> ft-lbf
L21: Forces
B22: Gear 2 (Pinion) Inputs | H22: Gear 2 (Pinion) Outputs | L22: Distance from 2 to B | M22: 3 | N22: in
B23: Rotational Speed, n2 | C23: 1800 | D23: rev/min | E23: ωG known | F23: =NOT(C23=0) -> TRUE | H23: Rotational Speed, n2 | I23: =C24 -> 1800 | J23: rev/min | L23: Distance from A to B | M23: 6 | N23: in
C24: =IF(F23,C23,C35*(C40/C29)) -> 1800 | D24: rev/min | H24: Rotational Speed, ω2 | I24: =C25 -> 188.49556 | J24: rad/s | L24: Radial Load at 2 | M24: {=-SQRT(SUM(I15:I16^2))} -> -662.42158 | N24: lbf
B25: Rotational Speed, ω2 | C25: =C24*PI()/30 -> 188.49556 | D25: rad/s | H25: # teeth, N2 | I25: =C27 -> 18 | J25: teeth | L25: Radial Load at A | M25: =-M24*M22/M23 -> 331.21079 | N25: lbf | O25: (from moment about B)
B26: # teeth, N2 | C26: 18 | D26: teeth | E26: NG known | F26: =NOT(C26=0) -> TRUE | H26: Pitch diameter, d2 | I26: =C29 -> 3.6 | J26: =IF($D$3="English","in", "mm") -> in | L26: Radial Load at B | M26: =SUM(M24:M25) -> -331.21079 | N26: lbf
C27: =IF(F26,C26,IF($D$3="English",C31*C29,(C31^-1)*C29)) -> 18 | D27: teeth | H27: Pitch radius, r2 | I27: =I26/2 -> 1.8 | J27: =IF($D$3="English","in", "mm") -> in | L27: Distance from 3 to D | M27: 3 | N27: in
B28: Pitch diameter, d2 | D28: =IF($D$3="English","in", "mm") -> in | E28: d known | F28: FALSE | H28: Base diameter, dbase2 | I28: =I26*COS(RADIANS($C$7)) -> 3.3828934 | J28: =IF($D$3="English","in", "mm") -> in | L28: Distance from D to C | M28: 6 | N28: in
C29: =IF(F28,C28,IF(F26,IF($D$3="English",(C31^-1)*C26, C31*C26),C40*(C35/C24))) -> 3.6 | D29: =IF($D$3="English","in", "mm") -> in | H29: Base radius, rbase2 | I29: =I28/2 -> 1.6914467 | J29: =IF($D$3="English","in", "mm") -> in | L29: Radial Load at 3 | M29: {=SQRT(SUM(I15:I16^2))} -> 662.42158 | N29: lbf
B30: =IF($D$3="English","Diametrial Pitch, P (N/d)", "Module, m (d/N)") -> Diametrial Pitch, P (N/d) | C30: 5 | D30: =IF($D$3="English","teeth/in", "mm/tooth") -> teeth/in | E30: =IF($D$3="English","P known", "m known") -> P known | F30: =NOT(F28) -> TRUE | L30: Radial Load at D | M30: =-M29*M27/M28 -> -331.21079 | N30: lbf | O30: (from moment about C)
C31: =IF(F30,IF(F31,IF(F42,"Pitch Wrong",C42),C30),IF($D$3="English",C26/C29, C29/C26)) -> 5 | D31: =IF($D$3="English","teeth/in", "mm/tooth") -> teeth/in | E31: P3=P2 | F31: FALSE | L31: Radial Load at C | M31: =SUM(M29:M30) -> 331.21079 | N31: lbf
B33: Gear 3 (Gear) Inputs | H33: Gear 3 (Gear) Outputs | L33: Bearing Info
B34: Rotational Speed, n3 | D34: rev/min | E34: ωG known | F34: =NOT(C34=0) -> FALSE | H34: Rotational Speed, n3 | I34: =C35 -> 720 | J34: rev/min | L34: If there is an overall 95% reliability for the bearings each
C35: =IF(F34,C34,C24*(C29/C40)) -> 720 | D35: rev/min | H35: Rotational Speed, ω3 | I35: =C36 -> 75.398224 | J35: rad/s | L35: bearing requires
B36: Rotational Speed, ω3 | C36: =C35*PI()/30 -> 75.398224 | D36: rad/s | H36: # teeth, N3 | I36: =C38 -> 45 | J36: teeth | L36: # Bearings | M36: 4 | N36: -
B37: # teeth, N3 | C37: 45 | D37: teeth | E37: NG known | F37: =NOT(C37=0) -> TRUE | H37: Pitch diameter, d3 | I37: =C40 -> 9 | J37: =IF($D$3="English","in", "mm") -> in | L37: Overall reliability | M37: 0.95 | N37: -
C38: =IF(F37,C37,IF($D$3="English",C42*C40,(C42^-1)*C40)) -> 45 | D38: teeth | H38: Pitch radius, r3 | I38: =I37/2 -> 4.5 | J38: =IF($D$3="English","in", "mm") -> in | L38: Equal RD for all bearings | M38: =(M37)^(1/M36) -> 0.98725854 | N38: -
B39: Pitch diameter, d3 | D39: =IF($D$3="English","in", "mm") -> in | E39: d known | F39: FALSE | H39: Base diameter, dbase3 | I39: =I37*COS(RADIANS($C$7)) -> 8.4572336 | J39: =IF($D$3="English","in", "mm") -> in
C40: =IF(F39,C39,IF(F37,IF($D$3="English",(C42^-1)*C37, C42*C37),C29*(C24/C35))) -> 9 | D40: =IF($D$3="English","in", "mm") -> in | H40: Base radius, rbase3 | I40: =I39/2 -> 4.2286168 | J40: =IF($D$3="English","in", "mm") -> in
B41: =IF($D$3="English","Diametrial Pitch, P (N/d)", "Module, m (d/N)") -> Diametrial Pitch, P (N/d) | D41: =IF($D$3="English","teeth/in", "mm/tooth") -> teeth/in | E41: =IF($D$3="English","P known", "m known") -> P known | F41: =NOT(F39) -> TRUE
C42: =IF(F41,IF(F42,IF(F31,"Pitch Wrong",C31),C41),IF($D$3="English",C37/C40, C40/C37)) -> 5 | D42: =IF($D$3="English","teeth/in", "mm/tooth") -> teeth/in | E42: P3=P2 | F42: TRUE

Sheet L25 Gears Cont. Q25
S2: Table 13-1
B3: INPUTS | C3: Units: | D3: English | H3: OUTPUTS | S3: Tooth System | T3: Pressure Angle (ϕ) [deg] | U3: =IF($D$3="English","Addendum (a)/P", "Addendum (a)*m") -> Addendum (a)/P | V3: =IF($D$3="English","Dedendum (b)/P", "Dedendum (b)*m") -> Dedendum (b)/P | W3: 2nd row
S4: Full depth | T4: 20 | U4: 1 | V4: 1.25 | W4: 1.35/P or 1.35m
B5: All Gears Inputs | H5: All Gears Outputs | S5: Full depth | T5: 22.5 | U5: 1 | V5: 1.25 | W5: 1.35/P or 1.35m
B6: Tooth System | C6: Full depth | H6: Speed Ratio: Pinion/Gear | I6: =C24/C35 -> 2.5 | J6: - | S6: Full depth | T6: 25 | U6: 1 | V6: 1.25 | W6: 1.35/P or 1.35m
B7: Pressure Angle, ϕ | C7: 20 | D7: deg | H7: C-C dist. Pinion & Gear | I7: =I26/2 + I37/2 -> 6.3 | J7: =IF($D$3="English","in", "mm") -> in | S7: Stub | T7: 20 | U7: 0.8 | V7: 1
H8: Addendum, a | I8: =IF($D$3="English",VLOOKUP($C$7,$T$11:$V$13,2,FALSE)/I11, VLOOKUP($C$7,$T$11:$V$13,2,FALSE)*I11) -> 0.2 | J8: =IF($D$3="English","in/tooth", "mm/tooth") -> in/tooth
H9: Dedendum, b | I9: =IF($D$3="English",VLOOKUP($C$7,$T$11:$V$13,3,FALSE)/I11, VLOOKUP($C$7,$T$11:$V$13,3,FALSE)*I11) -> 0.25 | J9: =IF($D$3="English","in/tooth", "mm/tooth") -> in/tooth
H10: Tooth Clearance | I10: =I9-I8 -> 0.05 | J10: =IF($D$3="English","in", "mm") -> in
H11: =IF($D$3="English","Diametrial Pitch, P (N/d)", "Module, m (d/N)") -> Diametrial Pitch, P (N/d) | I11: =C31 -> 5 | J11: =IF($D$3="English","teeth/in", "mm/tooth") -> teeth/in | S11: {=_xlfn._xlws.FILTER(S4:V7,S4:S7=C6,S8:V10=NA())} -> Full depth | T11: 20 | U11: 1 | V11: 1.25
H12: Circular pitch, p | I12: =PI()*I26/I25 -> 0.62831853 | J12: =IF($D$3="English","in", "mm") -> in | S12: Full depth | T12: 22.5 | U12: 1 | V12: 1.25
H13: Pitch Line Velocity, V | I13: =I24*I26/2 -> 339.29201 | J13: =IF($D$3="English","in/s", "mm/s") -> in/s | S13: Full depth | T13: 25 | U13: 1 | V13: 1.25
I14: =IF($D$3="English",I13*(1/12)*60, I13*60) -> 1696.46 | J14: =IF($D$3="English","ft/min", "mm/min") -> ft/min
H15: Tangential Load, Wt | I15: =IF($D$3="English",33000, 60000)*C20/I14 -> 622.47267 | J15: =IF($D$3="English","lbf", "kN") -> lbf
H16: Radial Load, Wr | I16: =I15*TAN(RADIANS(C7)) -> 226.56152 | J16: =IF($D$3="English","lbf", "kN") -> lbf
H17: Input Torque, Tin | I17: =I15*I26/2 -> 1120.4508 | J17: =IF($D$3="English","in-lbf", "N-m") -> in-lbf
I18: =IF($D$3="English",I17*(1/12), I17) -> 93.3709 | J18: =IF($D$3="English","ft-lbf", "N-m") -> ft-lbf
B19: Power Input to Gear 2 (Pinion) | H19: Output Torque, Tout | I19: =I15*I37/2 -> 2801.127 | J19: =IF($D$3="English","in-lbf", "N-m") -> in-lbf
B20: Input Power, H | C20: 32 | D20: =IF($D$3="English","hp", "kN") -> hp | I20: =IF($D$3="English",I19*(1/12), I19) -> 233.42725 | J20: =IF($D$3="English","ft-lbf", "N-m") -> ft-lbf
L21: Forces
B22: Gear 2 (Pinion) Inputs | H22: Gear 2 (Pinion) Outputs | L22: Distance from 2 to B | M22: 3 | N22: in
B23: Rotational Speed, n2 | C23: 1800 | D23: rev/min | E23: ωG known | F23: =NOT(C23=0) -> TRUE | H23: Rotational Speed, n2 | I23: =C24 -> 1800 | J23: rev/min | L23: Distance from A to B | M23: 6 | N23: in
C24: =IF(F23,C23,C35*(C40/C29)) -> 1800 | D24: rev/min | H24: Rotational Speed, ω2 | I24: =C25 -> 188.49556 | J24: rad/s | L24: Radial Load at 2 | M24: {=-SQRT(SUM(I15:I16^2))} -> -662.42158 | N24: lbf
B25: Rotational Speed, ω2 | C25: =C24*PI()/30 -> 188.49556 | D25: rad/s | H25: # teeth, N2 | I25: =C27 -> 18 | J25: teeth | L25: Radial Load at A | M25: =-M24*M22/M23 -> 331.21079 | N25: lbf | O25: (from moment about B)
B26: # teeth, N2 | C26: 18 | D26: teeth | E26: NG known | F26: =NOT(C26=0) -> TRUE | H26: Pitch diameter, d2 | I26: =C29 -> 3.6 | J26: =IF($D$3="English","in", "mm") -> in | L26: Radial Load at B | M26: =SUM(M24:M25) -> -331.21079 | N26: lbf
C27: =IF(F26,C26,IF($D$3="English",C31*C29,(C31^-1)*C29)) -> 18 | D27: teeth | H27: Pitch radius, r2 | I27: =I26/2 -> 1.8 | J27: =IF($D$3="English","in", "mm") -> in | L27: Distance from 3 to D | M27: 3 | N27: in
B28: Pitch diameter, d2 | D28: =IF($D$3="English","in", "mm") -> in | E28: d known | F28: FALSE | H28: Base diameter, dbase2 | I28: =I26*COS(RADIANS($C$7)) -> 3.3828934 | J28: =IF($D$3="English","in", "mm") -> in | L28: Distance from D to C | M28: 6 | N28: in
C29: =IF(F28,C28,IF(F26,IF($D$3="English",(C31^-1)*C26, C31*C26),C40*(C35/C24))) -> 3.6 | D29: =IF($D$3="English","in", "mm") -> in | H29: Base radius, rbase2 | I29: =I28/2 -> 1.6914467 | J29: =IF($D$3="English","in", "mm") -> in | L29: Radial Load at 3 | M29: {=SQRT(SUM(I15:I16^2))} -> 662.42158 | N29: lbf
B30: =IF($D$3="English","Diametrial Pitch, P (N/d)", "Module, m (d/N)") -> Diametrial Pitch, P (N/d) | C30: 5 | D30: =IF($D$3="English","teeth/in", "mm/tooth") -> teeth/in | E30: =IF($D$3="English","P known", "m known") -> P known | F30: =NOT(F28) -> TRUE | L30: Radial Load at D | M30: =-M29*M27/M28 -> -331.21079 | N30: lbf | O30: (from moment about C)
C31: =IF(F30,IF(F31,IF(F42,"Pitch Wrong",C42),C30),IF($D$3="English",C26/C29, C29/C26)) -> 5 | D31: =IF($D$3="English","teeth/in", "mm/tooth") -> teeth/in | E31: P3=P2 | F31: FALSE | L31: Radial Load at C | M31: =SUM(M29:M30) -> 331.21079 | N31: lbf
B33: Gear 3 (Gear) Inputs | H33: Gear 3 (Gear) Outputs | L33: Bearing Info
B34: Rotational Speed, n3 | D34: rev/min | E34: ωG known | F34: =NOT(C34=0) -> FALSE | H34: Rotational Speed, n3 | I34: =C35 -> 720 | J34: rev/min | L34: If there is an overall 95% reliability for the bearings each
C35: =IF(F34,C34,C24*(C29/C40)) -> 720 | D35: rev/min | H35: Rotational Speed, ω3 | I35: =C36 -> 75.398224 | J35: rad/s | L35: bearing requires
B36: Rotational Speed, ω3 | C36: =C35*PI()/30 -> 75.398224 | D36: rad/s | H36: # teeth, N3 | I36: =C38 -> 45 | J36: teeth | L36: # Bearings | M36: 4 | N36: -
B37: # teeth, N3 | C37: 45 | D37: teeth | E37: NG known | F37: =NOT(C37=0) -> TRUE | H37: Pitch diameter, d3 | I37: =C40 -> 9 | J37: =IF($D$3="English","in", "mm") -> in | L37: Overall reliability | M37: 0.95 | N37: -
C38: =IF(F37,C37,IF($D$3="English",C42*C40,(C42^-1)*C40)) -> 45 | D38: teeth | H38: Pitch radius, r3 | I38: =I37/2 -> 4.5 | J38: =IF($D$3="English","in", "mm") -> in | L38: Equal RD for all bearings | M38: =(M37)^(1/M36) -> 0.98725854 | N38: -
B39: Pitch diameter, d3 | D39: =IF($D$3="English","in", "mm") -> in | E39: d known | F39: FALSE | H39: Base diameter, dbase3 | I39: =I37*COS(RADIANS($C$7)) -> 8.4572336 | J39: =IF($D$3="English","in", "mm") -> in | L39: A and B same radial loads | M39: ='L18 Comb. Lds Bearings Q25 A&B'!I24 -> 19.5 | N39: kN | O39: <--- updated C10 Values
C40: =IF(F39,C39,IF(F37,IF($D$3="English",(C42^-1)*C37, C42*C37),C29*(C24/C35))) -> 9 | D40: =IF($D$3="English","in", "mm") -> in | H40: Base radius, rbase3 | I40: =I39/2 -> 4.2286168 | J40: =IF($D$3="English","in", "mm") -> in | L40: C and D same radial loads | M40: ='L18 Comb. Lds Bearings Q25 C&D'!I24 -> 14 | N40: kN | O40: <--- updated C10 Values
B41: =IF($D$3="English","Diametrial Pitch, P (N/d)", "Module, m (d/N)") -> Diametrial Pitch, P (N/d) | D41: =IF($D$3="English","teeth/in", "mm/tooth") -> teeth/in | E41: =IF($D$3="English","P known", "m known") -> P known | F41: =NOT(F39) -> TRUE
C42: =IF(F41,IF(F42,IF(F31,"Pitch Wrong",C31),C41),IF($D$3="English",C37/C40, C40/C37)) -> 5 | D42: =IF($D$3="English","teeth/in", "mm/tooth") -> teeth/in | E42: P3=P2 | F42: TRUE

Sheet L18 Comb. Lds Bearings Q25 A&B
B2: INPUTS | C2: Units: | D2: English | H2: OUTPUTS | S2: Tables
B4: Bearing Design | H4: Initial Rated Load, C10, Fa = 0 | K4: =($C$19*$C$9*C16)*($C$32/($C$29+($C$30-$C$29)*(LN($C$6^-1))^(1/$C$31)))^(1/$C$11) -> 17.557113 | L4: kN | T4: Table 11-6 | Z4: Table 11-2 | AK4: Table 11-1
B5: Bearing Brand | C5: SKF | H5: C10 From Table 11.2, Fa = 0 | K5: =IF($C$7="Deep Groove", SMALL($AF$8:$AF$27,COUNTIF($AF$8:$AF$27,"<"&K4)+1), IF($C$7="Angular", SMALL($AH$8:$AH$27,COUNTIF($AH$8:$AH$27,"<"&K4)+1), IF($C$7="02-Series", SMALL($AC$62:$AC$82,COUNTIF($AC$62:$AC$82,"<"&K4)+1), IF($C$7="03-Series", SMALL($AG$62:$AG$82,COUNTIF($AG$62:$AG$82,"<"&K4)+1), NA())))) -> 19.5 | L5: kN | T5: Manufacturer | U5: Rating Life (revs) | V5: x0 | W5: θ | X5: b | Z5: Bore | AA5: OD | AB5: Width | AC5: Fillet Radius | AD5: Shoulder | AF5: Load Ratings | AK5: Fa/C0 | AL5: e | AM5: Fa/(VFr) <= e | AO5: Fa/(VFr) > e
B6: Design Reliability, RD | C6: ='L25 Gears Cont. Q25'!M38 -> 0.98725854 | E6: must be greater than 90% | H6: C0 From Table 11.2, Fa = 0 | K6: =IF($C$7="Deep Groove",VLOOKUP(K5,$AF$8:$AG$27,2,FALSE), IF($C$7="Angular", VLOOKUP(K5,$AH$8:$AI$27,2,FALSE), IF($C$7="02-Series", VLOOKUP(K5,$AC$62:$AD$82,2,FALSE), IF($C$7="03-Series", VLOOKUP(K5,$AG$62:$AH$82,2,FALSE), NA())))) -> 10 | L6: kN | T6: TIMKEN | U6: =90*10^6 -> 90000000 | V6: 0 | W6: 4.48 | X6: 1.5 | AD6: Diameter | AF6: Deep Groove | AH6: Angular | AM6: X1 | AN6: Y1 | AO6: X2 | AP6: Y2
B7: Contact Type | C7: Deep Groove | H7: Fa/C0 | K7: =$C$18/K6 -> 0 | T7: SKF | U7: =1*10^6 -> 1000000 | V7: 0.02 | W7: 4.459 | X7: 1.483 | AD7: ds | AE7: dh | AF7: C10 | AG7: C0 | AH7: C10 | AI7: C0 | AK7: 0.014 | AL7: 0.19 | AM7: 1 | AN7: 0 | AO7: 0.56 | AP7: 2.3
B8: Which Ring Rotates | C8: Inner Ring | Z8: 10 | AA8: 30 | AB8: 9 | AC8: 0.6 | AD8: 12.5 | AE8: 27 | AF8: 5.07 | AG8: 2.24 | AH8: 4.94 | AI8: 2.12 | AK8: 0.021 | AL8: 0.21 | AM8: 1 | AN8: 0 | AO8: 0.56 | AP8: 2.15
B9: Rotating Ring Correction Factor, Vr | C9: =IF(C8="Inner Ring", 1, 1.2) -> 1 | H9: Iteration Table for C0 value | Z9: 12 | AA9: 32 | AB9: 10 | AC9: 0.6 | AD9: 14.5 | AE9: 28 | AF9: 6.89 | AG9: 3.1 | AH9: 7.02 | AI9: 3.05 | AK9: 0.028 | AL9: 0.22 | AM9: 1 | AN9: 0 | AO9: 0.56 | AP9: 1.99
B10: Bearing Type | C10: Ball | H10: Itteration # | I10: Fa/C0 | J10: Fa/(VFr) | K10: e | L10: X | M10: Y | N10: FE [kN] | O10: Updated Search C10 [kN] | P10: Updated C10 [kN] | Q10: Updated C0 [kN] | Z10: 15 | AA10: 35 | AB10: 11 | AC10: 0.6 | AD10: 17.5 | AE10: 31 | AF10: 7.8 | AG10: 3.55 | AH10: 8.06 | AI10: 3.65 | AK10: 0.042 | AL10: 0.24 | AM10: 1 | AN10: 0 | AO10: 0.56 | AP10: 1.85
B11: Power Law Exponent, a | C11: =IF(F12,C12,IF(C10="Ball", 3, 10/3)) -> 3 | H11: 0 | I11: =IF($C$18/K6 < 0.014, 0.014, $C$18/K6) -> 0.014 | J11: =$C$18/($C$9*$C$16) -> 0 | K11: =0.506467531924409*(I11)^0.23203728471849 -> 0.18809801 | L11: =IF(J11<=K11,1,0.56) -> 1 | M11: =IF(J11<=K11,0,0.863191147423464*(I11)^(-0.234866270653838)) -> 0 | N11: =L11*$C$9*$C$16 + M11*$C$18 -> 1.4732256 | O11: =($C$19*N11)*($C$32/($C$29+($C$30-$C$29)*(LN($C$6^-1))^(1/$C$31)))^(1/$C$11) -> 17.557113 | P11: =IF($C$7="Deep Groove", SMALL($AF$8:$AF$27,COUNTIF($AF$8:$AF$27,"<"&O11)+1), IF($C$7="Angular", SMALL($AH$8:$AH$27,COUNTIF($AH$8:$AH$27,"<"&O11)+1), IF($C$7="02-Series", SMALL($AC$62:$AC$82,COUNTIF($AC$62:$AC$82,"<"&O11)+1), IF($C$7="03-Series", SMALL($AG$62:$AG$82,COUNTIF($AG$62:$AG$82,"<"&O11)+1), NA())))) -> 19.5 | Q11: =IF($C$7="Deep Groove",VLOOKUP(P11,$AF$8:$AG$27,2,FALSE), IF($C$7="Angular", VLOOKUP(P11,$AH$8:$AI$27,2,FALSE), IF($C$7="02-Series", VLOOKUP(P11,$AC$62:$AD$82,2,FALSE), IF($C$7="03-Series", VLOOKUP(P11,$AG$62:$AH$82,2,FALSE), NA())))) -> 10 | Z11: 17 | AA11: 40 | AB11: 12 | AC11: 0.6 | AD11: 19.5 | AE11: 34 | AF11: 9.56 | AG11: 4.5 | AH11: 9.95 | AI11: 4.75 | AK11: 0.056 | AL11: 0.26 | AM11: 1 | AN11: 0 | AO11: 0.56 | AP11: 1.71
E12: Override a | F12: FALSE | H12: 1 | I12: =IF($C$18/Q11 < 0.014, 0.014, $C$18/Q11) -> 0.014 | J12: =$C$18/($C$9*$C$16) -> 0 | K12: =0.506467531924409*(I12)^0.23203728471849 -> 0.18809801 | L12: =IF(J12<=K12,1,0.56) -> 1 | M12: =IF(J12<=K12,0,0.863191147423464*(I12)^(-0.234866270653838)) -> 0 | N12: =L12*$C$9*$C$16 + M12*$C$18 -> 1.4732256 | O12: =($C$19*N12)*($C$32/($C$29+($C$30-$C$29)*(LN($C$6^-1))^(1/$C$31)))^(1/$C$11) -> 17.557113 | P12: =IF($C$7="Deep Groove", SMALL($AF$8:$AF$27,COUNTIF($AF$8:$AF$27,"<"&O12)+1), IF($C$7="Angular", SMALL($AH$8:$AH$27,COUNTIF($AH$8:$AH$27,"<"&O12)+1), IF($C$7="02-Series", SMALL($AC$62:$AC$82,COUNTIF($AC$62:$AC$82,"<"&O12)+1), IF($C$7="03-Series", SMALL($AG$62:$AG$82,COUNTIF($AG$62:$AG$82,"<"&O12)+1), NA())))) -> 19.5 | Q12: =IF($C$7="Deep Groove",VLOOKUP(P12,$AF$8:$AG$27,2,FALSE), IF($C$7="Angular", VLOOKUP(P12,$AH$8:$AI$27,2,FALSE), IF($C$7="02-Series", VLOOKUP(P12,$AC$62:$AD$82,2,FALSE), IF($C$7="03-Series", VLOOKUP(P12,$AG$62:$AH$82,2,FALSE), NA())))) -> 10 | Z12: 20 | AA12: 47 | AB12: 14 | AC12: 1 | AD12: 25 | AE12: 41 | AF12: 12.7 | AG12: 6.2 | AH12: 13.3 | AI12: 6.55 | AK12: 0.07 | AL12: 0.27 | AM12: 1 | AN12: 0 | AO12: 0.56 | AP12: 1.63
H13: 2 | I13: =IF($C$18/Q12 < 0.014, 0.014, $C$18/Q12) -> 0.014 | J13: =$C$18/($C$9*$C$16) -> 0 | K13: =0.506467531924409*(I13)^0.23203728471849 -> 0.18809801 | L13: =IF(J13<=K13,1,0.56) -> 1 | M13: =IF(J13<=K13,0,0.863191147423464*(I13)^(-0.234866270653838)) -> 0 | N13: =L13*$C$9*$C$16 + M13*$C$18 -> 1.4732256 | O13: =($C$19*N13)*($C$32/($C$29+($C$30-$C$29)*(LN($C$6^-1))^(1/$C$31)))^(1/$C$11) -> 17.557113 | P13: =IF($C$7="Deep Groove", SMALL($AF$8:$AF$27,COUNTIF($AF$8:$AF$27,"<"&O13)+1), IF($C$7="Angular", SMALL($AH$8:$AH$27,COUNTIF($AH$8:$AH$27,"<"&O13)+1), IF($C$7="02-Series", SMALL($AC$62:$AC$82,COUNTIF($AC$62:$AC$82,"<"&O13)+1), IF($C$7="03-Series", SMALL($AG$62:$AG$82,COUNTIF($AG$62:$AG$82,"<"&O13)+1), NA())))) -> 19.5 | Q13: =IF($C$7="Deep Groove",VLOOKUP(P13,$AF$8:$AG$27,2,FALSE), IF($C$7="Angular", VLOOKUP(P13,$AH$8:$AI$27,2,FALSE), IF($C$7="02-Series", VLOOKUP(P13,$AC$62:$AD$82,2,FALSE), IF($C$7="03-Series", VLOOKUP(P13,$AG$62:$AH$82,2,FALSE), NA())))) -> 10 | Z13: 25 | AA13: 52 | AB13: 15 | AC13: 1 | AD13: 30 | AE13: 47 | AF13: 14 | AG13: 6.95 | AH13: 14.8 | AI13: 7.65 | AK13: 0.084 | AL13: 0.28 | AM13: 1 | AN13: 0 | AO13: 0.56 | AP13: 1.55
B14: Bearing Loads | H14: 3 | I14: =IF($C$18/Q13 < 0.014, 0.014, $C$18/Q13) -> 0.014 | J14: =$C$18/($C$9*$C$16) -> 0 | K14: =0.506467531924409*(I14)^0.23203728471849 -> 0.18809801 | L14: =IF(J14<=K14,1,0.56) -> 1 | M14: =IF(J14<=K14,0,0.863191147423464*(I14)^(-0.234866270653838)) -> 0 | N14: =L14*$C$9*$C$16 + M14*$C$18 -> 1.4732256 | O14: =($C$19*N14)*($C$32/($C$29+($C$30-$C$29)*(LN($C$6^-1))^(1/$C$31)))^(1/$C$11) -> 17.557113 | P14: =IF($C$7="Deep Groove", SMALL($AF$8:$AF$27,COUNTIF($AF$8:$AF$27,"<"&O14)+1), IF($C$7="Angular", SMALL($AH$8:$AH$27,COUNTIF($AH$8:$AH$27,"<"&O14)+1), IF($C$7="02-Series", SMALL($AC$62:$AC$82,COUNTIF($AC$62:$AC$82,"<"&O14)+1), IF($C$7="03-Series", SMALL($AG$62:$AG$82,COUNTIF($AG$62:$AG$82,"<"&O14)+1), NA())))) -> 19.5 | Q14: =IF($C$7="Deep Groove",VLOOKUP(P14,$AF$8:$AG$27,2,FALSE), IF($C$7="Angular", VLOOKUP(P14,$AH$8:$AI$27,2,FALSE), IF($C$7="02-Series", VLOOKUP(P14,$AC$62:$AD$82,2,FALSE), IF($C$7="03-Series", VLOOKUP(P14,$AG$62:$AH$82,2,FALSE), NA())))) -> 10 | Z14: 30 | AA14: 62 | AB14: 16 | AC14: 1 | AD14: 35 | AE14: 55 | AF14: 19.5 | AG14: 10 | AH14: 20.3 | AI14: 11 | AK14: 0.11 | AL14: 0.3 | AM14: 1 | AN14: 0 | AO14: 0.56 | AP14: 1.45
B15: Input Radial Load, Fr | C15: ='L25 Gears Cont. Q25'!M25/10^3 -> 0.33121079 | D15: =IF($D$2="English","klbf", "kN") -> klbf | H15: 4 | I15: =IF($C$18/Q14 < 0.014, 0.014, $C$18/Q14) -> 0.014 | J15: =$C$18/($C$9*$C$16) -> 0 | K15: =0.506467531924409*(I15)^0.23203728471849 -> 0.18809801 | L15: =IF(J15<=K15,1,0.56) -> 1 | M15: =IF(J15<=K15,0,0.863191147423464*(I15)^(-0.234866270653838)) -> 0 | N15: =L15*$C$9*$C$16 + M15*$C$18 -> 1.4732256 | O15: =($C$19*N15)*($C$32/($C$29+($C$30-$C$29)*(LN($C$6^-1))^(1/$C$31)))^(1/$C$11) -> 17.557113 | P15: =IF($C$7="Deep Groove", SMALL($AF$8:$AF$27,COUNTIF($AF$8:$AF$27,"<"&O15)+1), IF($C$7="Angular", SMALL($AH$8:$AH$27,COUNTIF($AH$8:$AH$27,"<"&O15)+1), IF($C$7="02-Series", SMALL($AC$62:$AC$82,COUNTIF($AC$62:$AC$82,"<"&O15)+1), IF($C$7="03-Series", SMALL($AG$62:$AG$82,COUNTIF($AG$62:$AG$82,"<"&O15)+1), NA())))) -> 19.5 | Q15: =IF($C$7="Deep Groove",VLOOKUP(P15,$AF$8:$AG$27,2,FALSE), IF($C$7="Angular", VLOOKUP(P15,$AH$8:$AI$27,2,FALSE), IF($C$7="02-Series", VLOOKUP(P15,$AC$62:$AD$82,2,FALSE), IF($C$7="03-Series", VLOOKUP(P15,$AG$62:$AH$82,2,FALSE), NA())))) -> 10 | Z15: 35 | AA15: 72 | AB15: 17 | AC15: 1 | AD15: 41 | AE15: 65 | AF15: 25.5 | AG15: 13.7 | AH15: 27 | AI15: 15 | AK15: 0.17 | AL15: 0.34 | AM15: 1 | AN15: 0 | AO15: 0.56 | AP15: 1.31
C16: =IF($D$2="English",C15*4.448, C15) -> 1.4732256 | D16: kN | H16: 5 | I16: =IF($C$18/Q15 < 0.014, 0.014, $C$18/Q15) -> 0.014 | J16: =$C$18/($C$9*$C$16) -> 0 | K16: =0.506467531924409*(I16)^0.23203728471849 -> 0.18809801 | L16: =IF(J16<=K16,1,0.56) -> 1 | M16: =IF(J16<=K16,0,0.863191147423464*(I16)^(-0.234866270653838)) -> 0 | N16: =L16*$C$9*$C$16 + M16*$C$18 -> 1.4732256 | O16: =($C$19*N16)*($C$32/($C$29+($C$30-$C$29)*(LN($C$6^-1))^(1/$C$31)))^(1/$C$11) -> 17.557113 | P16: =IF($C$7="Deep Groove", SMALL($AF$8:$AF$27,COUNTIF($AF$8:$AF$27,"<"&O16)+1), IF($C$7="Angular", SMALL($AH$8:$AH$27,COUNTIF($AH$8:$AH$27,"<"&O16)+1), IF($C$7="02-Series", SMALL($AC$62:$AC$82,COUNTIF($AC$62:$AC$82,"<"&O16)+1), IF($C$7="03-Series", SMALL($AG$62:$AG$82,COUNTIF($AG$62:$AG$82,"<"&O16)+1), NA())))) -> 19.5 | Q16: =IF($C$7="Deep Groove",VLOOKUP(P16,$AF$8:$AG$27,2,FALSE), IF($C$7="Angular", VLOOKUP(P16,$AH$8:$AI$27,2,FALSE), IF($C$7="02-Series", VLOOKUP(P16,$AC$62:$AD$82,2,FALSE), IF($C$7="03-Series", VLOOKUP(P16,$AG$62:$AH$82,2,FALSE), NA())))) -> 10 | Z16: 40 | AA16: 80 | AB16: 18 | AC16: 1 | AD16: 46 | AE16: 72 | AF16: 30.7 | AG16: 16.6 | AH16: 31.9 | AI16: 18.6 | AK16: 0.28 | AL16: 0.38 | AM16: 1 | AN16: 0 | AO16: 0.56 | AP16: 1.15
B17: Input Axial Load, FA | D17: =IF($D$2="English","klbf", "kN") -> klbf | H17: 6 | I17: =IF($C$18/Q16 < 0.014, 0.014, $C$18/Q16) -> 0.014 | J17: =$C$18/($C$9*$C$16) -> 0 | K17: =0.506467531924409*(I17)^0.23203728471849 -> 0.18809801 | L17: =IF(J17<=K17,1,0.56) -> 1 | M17: =IF(J17<=K17,0,0.863191147423464*(I17)^(-0.234866270653838)) -> 0 | N17: =L17*$C$9*$C$16 + M17*$C$18 -> 1.4732256 | O17: =($C$19*N17)*($C$32/($C$29+($C$30-$C$29)*(LN($C$6^-1))^(1/$C$31)))^(1/$C$11) -> 17.557113 | P17: =IF($C$7="Deep Groove", SMALL($AF$8:$AF$27,COUNTIF($AF$8:$AF$27,"<"&O17)+1), IF($C$7="Angular", SMALL($AH$8:$AH$27,COUNTIF($AH$8:$AH$27,"<"&O17)+1), IF($C$7="02-Series", SMALL($AC$62:$AC$82,COUNTIF($AC$62:$AC$82,"<"&O17)+1), IF($C$7="03-Series", SMALL($AG$62:$AG$82,COUNTIF($AG$62:$AG$82,"<"&O17)+1), NA())))) -> 19.5 | Q17: =IF($C$7="Deep Groove",VLOOKUP(P17,$AF$8:$AG$27,2,FALSE), IF($C$7="Angular", VLOOKUP(P17,$AH$8:$AI$27,2,FALSE), IF($C$7="02-Series", VLOOKUP(P17,$AC$62:$AD$82,2,FALSE), IF($C$7="03-Series", VLOOKUP(P17,$AG$62:$AH$82,2,FALSE), NA())))) -> 10 | Z17: 45 | AA17: 85 | AB17: 19 | AC17: 1 | AD17: 52 | AE17: 77 | AF17: 33.2 | AG17: 18.6 | AH17: 35.8 | AI17: 21.2 | AK17: 0.42 | AL17: 0.42 | AM17: 1 | AN17: 0 | AO17: 0.56 | AP17: 1.04
C18: =IF($D$2="English",C17*4.448, C17) -> 0 | D18: kN | H18: 7 | I18: =IF($C$18/Q17 < 0.014, 0.014, $C$18/Q17) -> 0.014 | J18: =$C$18/($C$9*$C$16) -> 0 | K18: =0.506467531924409*(I18)^0.23203728471849 -> 0.18809801 | L18: =IF(J18<=K18,1,0.56) -> 1 | M18: =IF(J18<=K18,0,0.863191147423464*(I18)^(-0.234866270653838)) -> 0 | N18: =L18*$C$9*$C$16 + M18*$C$18 -> 1.4732256 | O18: =($C$19*N18)*($C$32/($C$29+($C$30-$C$29)*(LN($C$6^-1))^(1/$C$31)))^(1/$C$11) -> 17.557113 | P18: =IF($C$7="Deep Groove", SMALL($AF$8:$AF$27,COUNTIF($AF$8:$AF$27,"<"&O18)+1), IF($C$7="Angular", SMALL($AH$8:$AH$27,COUNTIF($AH$8:$AH$27,"<"&O18)+1), IF($C$7="02-Series", SMALL($AC$62:$AC$82,COUNTIF($AC$62:$AC$82,"<"&O18)+1), IF($C$7="03-Series", SMALL($AG$62:$AG$82,COUNTIF($AG$62:$AG$82,"<"&O18)+1), NA())))) -> 19.5 | Q18: =IF($C$7="Deep Groove",VLOOKUP(P18,$AF$8:$AG$27,2,FALSE), IF($C$7="Angular", VLOOKUP(P18,$AH$8:$AI$27,2,FALSE), IF($C$7="02-Series", VLOOKUP(P18,$AC$62:$AD$82,2,FALSE), IF($C$7="03-Series", VLOOKUP(P18,$AG$62:$AH$82,2,FALSE), NA())))) -> 10 | Z18: 50 | AA18: 90 | AB18: 20 | AC18: 1 | AD18: 56 | AE18: 82 | AF18: 35.1 | AG18: 19.6 | AH18: 37.7 | AI18: 22.8 | AK18: 0.56 | AL18: 0.44 | AM18: 1 | AN18: 0 | AO18: 0.56 | AP18: 1
B19: Load Application Factor, af | C19: 1 | H19: 8 | I19: =IF($C$18/Q18 < 0.014, 0.014, $C$18/Q18) -> 0.014 | J19: =$C$18/($C$9*$C$16) -> 0 | K19: =0.506467531924409*(I19)^0.23203728471849 -> 0.18809801 | L19: =IF(J19<=K19,1,0.56) -> 1 | M19: =IF(J19<=K19,0,0.863191147423464*(I19)^(-0.234866270653838)) -> 0 | N19: =L19*$C$9*$C$16 + M19*$C$18 -> 1.4732256 | O19: =($C$19*N19)*($C$32/($C$29+($C$30-$C$29)*(LN($C$6^-1))^(1/$C$31)))^(1/$C$11) -> 17.557113 | P19: =IF($C$7="Deep Groove", SMALL($AF$8:$AF$27,COUNTIF($AF$8:$AF$27,"<"&O19)+1), IF($C$7="Angular", SMALL($AH$8:$AH$27,COUNTIF($AH$8:$AH$27,"<"&O19)+1), IF($C$7="02-Series", SMALL($AC$62:$AC$82,COUNTIF($AC$62:$AC$82,"<"&O19)+1), IF($C$7="03-Series", SMALL($AG$62:$AG$82,COUNTIF($AG$62:$AG$82,"<"&O19)+1), NA())))) -> 19.5 | Q19: =IF($C$7="Deep Groove",VLOOKUP(P19,$AF$8:$AG$27,2,FALSE), IF($C$7="Angular", VLOOKUP(P19,$AH$8:$AI$27,2,FALSE), IF($C$7="02-Series", VLOOKUP(P19,$AC$62:$AD$82,2,FALSE), IF($C$7="03-Series", VLOOKUP(P19,$AG$62:$AH$82,2,FALSE), NA())))) -> 10 | Z19: 55 | AA19: 100 | AB19: 21 | AC19: 1.5 | AD19: 63 | AE19: 90 | AF19: 43.6 | AG19: 25 | AH19: 46.2 | AI19: 28.5
H20: 9 | I20: =IF($C$18/Q19 < 0.014, 0.014, $C$18/Q19) -> 0.014 | J20: =$C$18/($C$9*$C$16) -> 0 | K20: =0.506467531924409*(I20)^0.23203728471849 -> 0.18809801 | L20: =IF(J20<=K20,1,0.56) -> 1 | M20: =IF(J20<=K20,0,0.863191147423464*(I20)^(-0.234866270653838)) -> 0 | N20: =L20*$C$9*$C$16 + M20*$C$18 -> 1.4732256 | O20: =($C$19*N20)*($C$32/($C$29+($C$30-$C$29)*(LN($C$6^-1))^(1/$C$31)))^(1/$C$11) -> 17.557113 | P20: =IF($C$7="Deep Groove", SMALL($AF$8:$AF$27,COUNTIF($AF$8:$AF$27,"<"&O20)+1), IF($C$7="Angular", SMALL($AH$8:$AH$27,COUNTIF($AH$8:$AH$27,"<"&O20)+1), IF($C$7="02-Series", SMALL($AC$62:$AC$82,COUNTIF($AC$62:$AC$82,"<"&O20)+1), IF($C$7="03-Series", SMALL($AG$62:$AG$82,COUNTIF($AG$62:$AG$82,"<"&O20)+1), NA())))) -> 19.5 | Q20: =IF($C$7="Deep Groove",VLOOKUP(P20,$AF$8:$AG$27,2,FALSE), IF($C$7="Angular", VLOOKUP(P20,$AH$8:$AI$27,2,FALSE), IF($C$7="02-Series", VLOOKUP(P20,$AC$62:$AD$82,2,FALSE), IF($C$7="03-Series", VLOOKUP(P20,$AG$62:$AH$82,2,FALSE), NA())))) -> 10 | Z20: 60 | AA20: 110 | AB20: 22 | AC20: 1.5 | AD20: 70 | AE20: 99 | AF20: 47.5 | AG20: 28 | AH20: 55.9 | AI20: 35.5
B21: Design Cycle Lifetime | H21: 10 | I21: =IF($C$18/Q20 < 0.014, 0.014, $C$18/Q20) -> 0.014 | J21: =$C$18/($C$9*$C$16) -> 0 | K21: =0.506467531924409*(I21)^0.23203728471849 -> 0.18809801 | L21: =IF(J21<=K21,1,0.56) -> 1 | M21: =IF(J21<=K21,0,0.863191147423464*(I21)^(-0.234866270653838)) -> 0 | N21: =L21*$C$9*$C$16 + M21*$C$18 -> 1.4732256 | O21: =($C$19*N21)*($C$32/($C$29+($C$30-$C$29)*(LN($C$6^-1))^(1/$C$31)))^(1/$C$11) -> 17.557113 | P21: =IF($C$7="Deep Groove", SMALL($AF$8:$AF$27,COUNTIF($AF$8:$AF$27,"<"&O21)+1), IF($C$7="Angular", SMALL($AH$8:$AH$27,COUNTIF($AH$8:$AH$27,"<"&O21)+1), IF($C$7="02-Series", SMALL($AC$62:$AC$82,COUNTIF($AC$62:$AC$82,"<"&O21)+1), IF($C$7="03-Series", SMALL($AG$62:$AG$82,COUNTIF($AG$62:$AG$82,"<"&O21)+1), NA())))) -> 19.5 | Q21: =IF($C$7="Deep Groove",VLOOKUP(P21,$AF$8:$AG$27,2,FALSE), IF($C$7="Angular", VLOOKUP(P21,$AH$8:$AI$27,2,FALSE), IF($C$7="02-Series", VLOOKUP(P21,$AC$62:$AD$82,2,FALSE), IF($C$7="03-Series", VLOOKUP(P21,$AG$62:$AH$82,2,FALSE), NA())))) -> 10 | Z21: 65 | AA21: 120 | AB21: 23 | AC21: 1.5 | AD21: 74 | AE21: 109 | AF21: 55.9 | AG21: 34 | AH21: 63.7 | AI21: 41.5
B22: Lifetime, ℒD | C22: 4000 | D22: hrs | Z22: 70 | AA22: 125 | AB22: 24 | AC22: 1.5 | AD22: 79 | AE22: 114 | AF22: 61.8 | AG22: 37.5 | AH22: 68.9 | AI22: 45.5
B23: Rotation Speed, n | C23: ='L25 Gears Cont. Q25'!I23 -> 1800 | D23: rpm | H23: Final Iterated Values | Z23: 75 | AA23: 130 | AB23: 25 | AC23: 1.5 | AD23: 86 | AE23: 119 | AF23: 66.3 | AG23: 40.5 | AH23: 71.5 | AI23: 49
B24: Design Lifetime, LD | C24: =IF(F25,C25,C22*C23*60) -> 432000000 | D24: revs | H24: Iterated C10 | I24: =P21 -> 19.5 | J24: kN | Z24: 80 | AA24: 140 | AB24: 26 | AC24: 2 | AD24: 93 | AE24: 127 | AF24: 70.2 | AG24: 45 | AH24: 80.6 | AI24: 55
D25: revs | E25: Override LD | F25: FALSE | I25: =I24/4.448 -> 4.3839928 | J25: klbf | Z25: 85 | AA25: 150 | AB25: 28 | AC25: 2 | AD25: 99 | AE25: 136 | AF25: 83.2 | AG25: 53 | AH25: 90.4 | AI25: 63
H26: Iterated C0 | I26: =Q21 -> 10 | J26: kN | Z26: 90 | AA26: 160 | AB26: 30 | AC26: 2 | AD26: 104 | AE26: 146 | AF26: 95.6 | AG26: 62 | AH26: 106 | AI26: 73.5
B27: Weibull Paramters Automattically Based on Bearing Brand | E27: RD for 90% = | F27: =EXP(-1*((1 - C29) / (C30 - C29))^C31) -> 0.8990379 | I27: =I26/4.448 -> 2.2482014 | J27: klbf | Z27: 95 | AA27: 170 | AB27: 32 | AC27: 2 | AD27: 110 | AE27: 156 | AF27: 108 | AG27: 69.5 | AH27: 121 | AI27: 85
B28: Rating Life, L10 | C28: =IF(F36,C37,VLOOKUP($C$5,$T$6:$X$7,2,FALSE)) -> 1000000 | D28: revs
B29: x0 | C29: =IF(F36,C38,VLOOKUP($C$5,$T$6:$X$7,3,FALSE)) -> 0.02
B30: θ | C30: =IF(F36,C40,VLOOKUP($C$5,$T$6:$X$7,4,FALSE)) -> 4.459
B31: b | C31: =IF(F36,C42,VLOOKUP($C$5,$T$6:$X$7,5,FALSE)) -> 1.483
B32: Nomormalized Lifetime by Design, xD | C32: =IF(F33,C33,C24/C28) -> 432 | D32: revs
D33: revs | E33: Override xD | F33: FALSE
B34: Normalized Lifetime, xB | C34: =C29+(C30-C29)*(LN(C6^-1))^(1/C31) -> 0.25523029 | E34: For RD | F34: =C6 -> 0.98725854
B36: Weibull Parameters | E36: Override Weibull Parameters | F36: FALSE
B37: Rating Life, L10 | C37: =10^6 -> 1000000 | D37: revs
B38: x0 | C38: 0.02
B39: θ - x0 | C39: 4.439
B40: θ | C40: =IF(F41,C41,C39+C38) -> 4.459
D41: revs | E41: Override θ | F41: FALSE
B42: b | C42: 1.483
Z58: Table 11-3
...

Sheet L18 Comb. Lds Bearings Q25 C&D
B2: INPUTS | C2: Units: | D2: English | H2: OUTPUTS | S2: Tables
B4: Bearing Design | H4: Initial Rated Load, C10, Fa = 0 | K4: =($C$19*$C$9*C16)*($C$32/($C$29+($C$30-$C$29)*(LN($C$6^-1))^(1/$C$31)))^(1/$C$11) -> 12.936191 | L4: kN | T4: Table 11-6 | Z4: Table 11-2 | AK4: Table 11-1
B5: Bearing Brand | C5: SKF | H5: C10 From Table 11.2, Fa = 0 | K5: =IF($C$7="Deep Groove", SMALL($AF$8:$AF$27,COUNTIF($AF$8:$AF$27,"<"&K4)+1), IF($C$7="Angular", SMALL($AH$8:$AH$27,COUNTIF($AH$8:$AH$27,"<"&K4)+1), IF($C$7="02-Series", SMALL($AC$62:$AC$82,COUNTIF($AC$62:$AC$82,"<"&K4)+1), IF($C$7="03-Series", SMALL($AG$62:$AG$82,COUNTIF($AG$62:$AG$82,"<"&K4)+1), NA())))) -> 14 | L5: kN | T5: Manufacturer | U5: Rating Life (revs) | V5: x0 | W5: θ | X5: b | Z5: Bore | AA5: OD | AB5: Width | AC5: Fillet Radius | AD5: Shoulder | AF5: Load Ratings | AK5: Fa/C0 | AL5: e | AM5: Fa/(VFr) <= e | AO5: Fa/(VFr) > e
B6: Design Reliability, RD | C6: ='L25 Gears Cont. Q25'!M38 -> 0.98725854 | E6: must be greater than 90% | H6: C0 From Table 11.2, Fa = 0 | K6: =IF($C$7="Deep Groove",VLOOKUP(K5,$AF$8:$AG$27,2,FALSE), IF($C$7="Angular", VLOOKUP(K5,$AH$8:$AI$27,2,FALSE), IF($C$7="02-Series", VLOOKUP(K5,$AC$62:$AD$82,2,FALSE), IF($C$7="03-Series", VLOOKUP(K5,$AG$62:$AH$82,2,FALSE), NA())))) -> 6.95 | L6: kN | T6: TIMKEN | U6: =90*10^6 -> 90000000 | V6: 0 | W6: 4.48 | X6: 1.5 | AD6: Diameter | AF6: Deep Groove | AH6: Angular | AM6: X1 | AN6: Y1 | AO6: X2 | AP6: Y2
B7: Contact Type | C7: Deep Groove | H7: Fa/C0 | K7: =$C$18/K6 -> 0 | T7: SKF | U7: =1*10^6 -> 1000000 | V7: 0.02 | W7: 4.459 | X7: 1.483 | AD7: ds | AE7: dh | AF7: C10 | AG7: C0 | AH7: C10 | AI7: C0 | AK7: 0.014 | AL7: 0.19 | AM7: 1 | AN7: 0 | AO7: 0.56 | AP7: 2.3
B8: Which Ring Rotates | C8: Inner Ring | Z8: 10 | AA8: 30 | AB8: 9 | AC8: 0.6 | AD8: 12.5 | AE8: 27 | AF8: 5.07 | AG8: 2.24 | AH8: 4.94 | AI8: 2.12 | AK8: 0.021 | AL8: 0.21 | AM8: 1 | AN8: 0 | AO8: 0.56 | AP8: 2.15
B9: Rotating Ring Correction Factor, Vr | C9: =IF(C8="Inner Ring", 1, 1.2) -> 1 | H9: Iteration Table for C0 value | Z9: 12 | AA9: 32 | AB9: 10 | AC9: 0.6 | AD9: 14.5 | AE9: 28 | AF9: 6.89 | AG9: 3.1 | AH9: 7.02 | AI9: 3.05 | AK9: 0.028 | AL9: 0.22 | AM9: 1 | AN9: 0 | AO9: 0.56 | AP9: 1.99
B10: Bearing Type | C10: Ball | H10: Itteration # | I10: Fa/C0 | J10: Fa/(VFr) | K10: e | L10: X | M10: Y | N10: FE [kN] | O10: Updated Search C10 [kN] | P10: Updated C10 [kN] | Q10: Updated C0 [kN] | Z10: 15 | AA10: 35 | AB10: 11 | AC10: 0.6 | AD10: 17.5 | AE10: 31 | AF10: 7.8 | AG10: 3.55 | AH10: 8.06 | AI10: 3.65 | AK10: 0.042 | AL10: 0.24 | AM10: 1 | AN10: 0 | AO10: 0.56 | AP10: 1.85
B11: Power Law Exponent, a | C11: =IF(F12,C12,IF(C10="Ball", 3, 10/3)) -> 3 | H11: 0 | I11: =IF($C$18/K6 < 0.014, 0.014, $C$18/K6) -> 0.014 | J11: =$C$18/($C$9*$C$16) -> 0 | K11: =0.506467531924409*(I11)^0.23203728471849 -> 0.18809801 | L11: =IF(J11<=K11,1,0.56) -> 1 | M11: =IF(J11<=K11,0,0.863191147423464*(I11)^(-0.234866270653838)) -> 0 | N11: =L11*$C$9*$C$16 + M11*$C$18 -> 1.4732256 | O11: =($C$19*N11)*($C$32/($C$29+($C$30-$C$29)*(LN($C$6^-1))^(1/$C$31)))^(1/$C$11) -> 12.936191 | P11: =IF($C$7="Deep Groove", SMALL($AF$8:$AF$27,COUNTIF($AF$8:$AF$27,"<"&O11)+1), IF($C$7="Angular", SMALL($AH$8:$AH$27,COUNTIF($AH$8:$AH$27,"<"&O11)+1), IF($C$7="02-Series", SMALL($AC$62:$AC$82,COUNTIF($AC$62:$AC$82,"<"&O11)+1), IF($C$7="03-Series", SMALL($AG$62:$AG$82,COUNTIF($AG$62:$AG$82,"<"&O11)+1), NA())))) -> 14 | Q11: =IF($C$7="Deep Groove",VLOOKUP(P11,$AF$8:$AG$27,2,FALSE), IF($C$7="Angular", VLOOKUP(P11,$AH$8:$AI$27,2,FALSE), IF($C$7="02-Series", VLOOKUP(P11,$AC$62:$AD$82,2,FALSE), IF($C$7="03-Series", VLOOKUP(P11,$AG$62:$AH$82,2,FALSE), NA())))) -> 6.95 | Z11: 17 | AA11: 40 | AB11: 12 | AC11: 0.6 | AD11: 19.5 | AE11: 34 | AF11: 9.56 | AG11: 4.5 | AH11: 9.95 | AI11: 4.75 | AK11: 0.056 | AL11: 0.26 | AM11: 1 | AN11: 0 | AO11: 0.56 | AP11: 1.71
E12: Override a | F12: FALSE | H12: 1 | I12: =IF($C$18/Q11 < 0.014, 0.014, $C$18/Q11) -> 0.014 | J12: =$C$18/($C$9*$C$16) -> 0 | K12: =0.506467531924409*(I12)^0.23203728471849 -> 0.18809801 | L12: =IF(J12<=K12,1,0.56) -> 1 | M12: =IF(J12<=K12,0,0.863191147423464*(I12)^(-0.234866270653838)) -> 0 | N12: =L12*$C$9*$C$16 + M12*$C$18 -> 1.4732256 | O12: =($C$19*N12)*($C$32/($C$29+($C$30-$C$29)*(LN($C$6^-1))^(1/$C$31)))^(1/$C$11) -> 12.936191 | P12: =IF($C$7="Deep Groove", SMALL($AF$8:$AF$27,COUNTIF($AF$8:$AF$27,"<"&O12)+1), IF($C$7="Angular", SMALL($AH$8:$AH$27,COUNTIF($AH$8:$AH$27,"<"&O12)+1), IF($C$7="02-Series", SMALL($AC$62:$AC$82,COUNTIF($AC$62:$AC$82,"<"&O12)+1), IF($C$7="03-Series", SMALL($AG$62:$AG$82,COUNTIF($AG$62:$AG$82,"<"&O12)+1), NA())))) -> 14 | Q12: =IF($C$7="Deep Groove",VLOOKUP(P12,$AF$8:$AG$27,2,FALSE), IF($C$7="Angular", VLOOKUP(P12,$AH$8:$AI$27,2,FALSE), IF($C$7="02-Series", VLOOKUP(P12,$AC$62:$AD$82,2,FALSE), IF($C$7="03-Series", VLOOKUP(P12,$AG$62:$AH$82,2,FALSE), NA())))) -> 6.95 | Z12: 20 | AA12: 47 | AB12: 14 | AC12: 1 | AD12: 25 | AE12: 41 | AF12: 12.7 | AG12: 6.2 | AH12: 13.3 | AI12: 6.55 | AK12: 0.07 | AL12: 0.27 | AM12: 1 | AN12: 0 | AO12: 0.56 | AP12: 1.63
H13: 2 | I13: =IF($C$18/Q12 < 0.014, 0.014, $C$18/Q12) -> 0.014 | J13: =$C$18/($C$9*$C$16) -> 0 | K13: =0.506467531924409*(I13)^0.23203728471849 -> 0.18809801 | L13: =IF(J13<=K13,1,0.56) -> 1 | M13: =IF(J13<=K13,0,0.863191147423464*(I13)^(-0.234866270653838)) -> 0 | N13: =L13*$C$9*$C$16 + M13*$C$18 -> 1.4732256 | O13: =($C$19*N13)*($C$32/($C$29+($C$30-$C$29)*(LN($C$6^-1))^(1/$C$31)))^(1/$C$11) -> 12.936191 | P13: =IF($C$7="Deep Groove", SMALL($AF$8:$AF$27,COUNTIF($AF$8:$AF$27,"<"&O13)+1), IF($C$7="Angular", SMALL($AH$8:$AH$27,COUNTIF($AH$8:$AH$27,"<"&O13)+1), IF($C$7="02-Series", SMALL($AC$62:$AC$82,COUNTIF($AC$62:$AC$82,"<"&O13)+1), IF($C$7="03-Series", SMALL($AG$62:$AG$82,COUNTIF($AG$62:$AG$82,"<"&O13)+1), NA())))) -> 14 | Q13: =IF($C$7="Deep Groove",VLOOKUP(P13,$AF$8:$AG$27,2,FALSE), IF($C$7="Angular", VLOOKUP(P13,$AH$8:$AI$27,2,FALSE), IF($C$7="02-Series", VLOOKUP(P13,$AC$62:$AD$82,2,FALSE), IF($C$7="03-Series", VLOOKUP(P13,$AG$62:$AH$82,2,FALSE), NA())))) -> 6.95 | Z13: 25 | AA13: 52 | AB13: 15 | AC13: 1 | AD13: 30 | AE13: 47 | AF13: 14 | AG13: 6.95 | AH13: 14.8 | AI13: 7.65 | AK13: 0.084 | AL13: 0.28 | AM13: 1 | AN13: 0 | AO13: 0.56 | AP13: 1.55
B14: Bearing Loads | H14: 3 | I14: =IF($C$18/Q13 < 0.014, 0.014, $C$18/Q13) -> 0.014 | J14: =$C$18/($C$9*$C$16) -> 0 | K14: =0.506467531924409*(I14)^0.23203728471849 -> 0.18809801 | L14: =IF(J14<=K14,1,0.56) -> 1 | M14: =IF(J14<=K14,0,0.863191147423464*(I14)^(-0.234866270653838)) -> 0 | N14: =L14*$C$9*$C$16 + M14*$C$18 -> 1.4732256 | O14: =($C$19*N14)*($C$32/($C$29+($C$30-$C$29)*(LN($C$6^-1))^(1/$C$31)))^(1/$C$11) -> 12.936191 | P14: =IF($C$7="Deep Groove", SMALL($AF$8:$AF$27,COUNTIF($AF$8:$AF$27,"<"&O14)+1), IF($C$7="Angular", SMALL($AH$8:$AH$27,COUNTIF($AH$8:$AH$27,"<"&O14)+1), IF($C$7="02-Series", SMALL($AC$62:$AC$82,COUNTIF($AC$62:$AC$82,"<"&O14)+1), IF($C$7="03-Series", SMALL($AG$62:$AG$82,COUNTIF($AG$62:$AG$82,"<"&O14)+1), NA())))) -> 14 | Q14: =IF($C$7="Deep Groove",VLOOKUP(P14,$AF$8:$AG$27,2,FALSE), IF($C$7="Angular", VLOOKUP(P14,$AH$8:$AI$27,2,FALSE), IF($C$7="02-Series", VLOOKUP(P14,$AC$62:$AD$82,2,FALSE), IF($C$7="03-Series", VLOOKUP(P14,$AG$62:$AH$82,2,FALSE), NA())))) -> 6.95 | Z14: 30 | AA14: 62 | AB14: 16 | AC14: 1 | AD14: 35 | AE14: 55 | AF14: 19.5 | AG14: 10 | AH14: 20.3 | AI14: 11 | AK14: 0.11 | AL14: 0.3 | AM14: 1 | AN14: 0 | AO14: 0.56 | AP14: 1.45
B15: Input Radial Load, Fr | C15: ='L25 Gears Cont. Q25'!M31/10^3 -> 0.33121079 | D15: =IF($D$2="English","klbf", "kN") -> klbf | H15: 4 | I15: =IF($C$18/Q14 < 0.014, 0.014, $C$18/Q14) -> 0.014 | J15: =$C$18/($C$9*$C$16) -> 0 | K15: =0.506467531924409*(I15)^0.23203728471849 -> 0.18809801 | L15: =IF(J15<=K15,1,0.56) -> 1 | M15: =IF(J15<=K15,0,0.863191147423464*(I15)^(-0.234866270653838)) -> 0 | N15: =L15*$C$9*$C$16 + M15*$C$18 -> 1.4732256 | O15: =($C$19*N15)*($C$32/($C$29+($C$30-$C$29)*(LN($C$6^-1))^(1/$C$31)))^(1/$C$11) -> 12.936191 | P15: =IF($C$7="Deep Groove", SMALL($AF$8:$AF$27,COUNTIF($AF$8:$AF$27,"<"&O15)+1), IF($C$7="Angular", SMALL($AH$8:$AH$27,COUNTIF($AH$8:$AH$27,"<"&O15)+1), IF($C$7="02-Series", SMALL($AC$62:$AC$82,COUNTIF($AC$62:$AC$82,"<"&O15)+1), IF($C$7="03-Series", SMALL($AG$62:$AG$82,COUNTIF($AG$62:$AG$82,"<"&O15)+1), NA())))) -> 14 | Q15: =IF($C$7="Deep Groove",VLOOKUP(P15,$AF$8:$AG$27,2,FALSE), IF($C$7="Angular", VLOOKUP(P15,$AH$8:$AI$27,2,FALSE), IF($C$7="02-Series", VLOOKUP(P15,$AC$62:$AD$82,2,FALSE), IF($C$7="03-Series", VLOOKUP(P15,$AG$62:$AH$82,2,FALSE), NA())))) -> 6.95 | Z15: 35 | AA15: 72 | AB15: 17 | AC15: 1 | AD15: 41 | AE15: 65 | AF15: 25.5 | AG15: 13.7 | AH15: 27 | AI15: 15 | AK15: 0.17 | AL15: 0.34 | AM15: 1 | AN15: 0 | AO15: 0.56 | AP15: 1.31
C16: =IF($D$2="English",C15*4.448, C15) -> 1.4732256 | D16: kN | H16: 5 | I16: =IF($C$18/Q15 < 0.014, 0.014, $C$18/Q15) -> 0.014 | J16: =$C$18/($C$9*$C$16) -> 0 | K16: =0.506467531924409*(I16)^0.23203728471849 -> 0.18809801 | L16: =IF(J16<=K16,1,0.56) -> 1 | M16: =IF(J16<=K16,0,0.863191147423464*(I16)^(-0.234866270653838)) -> 0 | N16: =L16*$C$9*$C$16 + M16*$C$18 -> 1.4732256 | O16: =($C$19*N16)*($C$32/($C$29+($C$30-$C$29)*(LN($C$6^-1))^(1/$C$31)))^(1/$C$11) -> 12.936191 | P16: =IF($C$7="Deep Groove", SMALL($AF$8:$AF$27,COUNTIF($AF$8:$AF$27,"<"&O16)+1), IF($C$7="Angular", SMALL($AH$8:$AH$27,COUNTIF($AH$8:$AH$27,"<"&O16)+1), IF($C$7="02-Series", SMALL($AC$62:$AC$82,COUNTIF($AC$62:$AC$82,"<"&O16)+1), IF($C$7="03-Series", SMALL($AG$62:$AG$82,COUNTIF($AG$62:$AG$82,"<"&O16)+1), NA())))) -> 14 | Q16: =IF($C$7="Deep Groove",VLOOKUP(P16,$AF$8:$AG$27,2,FALSE), IF($C$7="Angular", VLOOKUP(P16,$AH$8:$AI$27,2,FALSE), IF($C$7="02-Series", VLOOKUP(P16,$AC$62:$AD$82,2,FALSE), IF($C$7="03-Series", VLOOKUP(P16,$AG$62:$AH$82,2,FALSE), NA())))) -> 6.95 | Z16: 40 | AA16: 80 | AB16: 18 | AC16: 1 | AD16: 46 | AE16: 72 | AF16: 30.7 | AG16: 16.6 | AH16: 31.9 | AI16: 18.6 | AK16: 0.28 | AL16: 0.38 | AM16: 1 | AN16: 0 | AO16: 0.56 | AP16: 1.15
B17: Input Axial Load, FA | D17: =IF($D$2="English","klbf", "kN") -> klbf | H17: 6 | I17: =IF($C$18/Q16 < 0.014, 0.014, $C$18/Q16) -> 0.014 | J17: =$C$18/($C$9*$C$16) -> 0 | K17: =0.506467531924409*(I17)^0.23203728471849 -> 0.18809801 | L17: =IF(J17<=K17,1,0.56) -> 1 | M17: =IF(J17<=K17,0,0.863191147423464*(I17)^(-0.234866270653838)) -> 0 | N17: =L17*$C$9*$C$16 + M17*$C$18 -> 1.4732256 | O17: =($C$19*N17)*($C$32/($C$29+($C$30-$C$29)*(LN($C$6^-1))^(1/$C$31)))^(1/$C$11) -> 12.936191 | P17: =IF($C$7="Deep Groove", SMALL($AF$8:$AF$27,COUNTIF($AF$8:$AF$27,"<"&O17)+1), IF($C$7="Angular", SMALL($AH$8:$AH$27,COUNTIF($AH$8:$AH$27,"<"&O17)+1), IF($C$7="02-Series", SMALL($AC$62:$AC$82,COUNTIF($AC$62:$AC$82,"<"&O17)+1), IF($C$7="03-Series", SMALL($AG$62:$AG$82,COUNTIF($AG$62:$AG$82,"<"&O17)+1), NA())))) -> 14 | Q17: =IF($C$7="Deep Groove",VLOOKUP(P17,$AF$8:$AG$27,2,FALSE), IF($C$7="Angular", VLOOKUP(P17,$AH$8:$AI$27,2,FALSE), IF($C$7="02-Series", VLOOKUP(P17,$AC$62:$AD$82,2,FALSE), IF($C$7="03-Series", VLOOKUP(P17,$AG$62:$AH$82,2,FALSE), NA())))) -> 6.95 | Z17: 45 | AA17: 85 | AB17: 19 | AC17: 1 | AD17: 52 | AE17: 77 | AF17: 33.2 | AG17: 18.6 | AH17: 35.8 | AI17: 21.2 | AK17: 0.42 | AL17: 0.42 | AM17: 1 | AN17: 0 | AO17: 0.56 | AP17: 1.04
C18: =IF($D$2="English",C17*4.448, C17) -> 0 | D18: kN | H18: 7 | I18: =IF($C$18/Q17 < 0.014, 0.014, $C$18/Q17) -> 0.014 | J18: =$C$18/($C$9*$C$16) -> 0 | K18: =0.506467531924409*(I18)^0.23203728471849 -> 0.18809801 | L18: =IF(J18<=K18,1,0.56) -> 1 | M18: =IF(J18<=K18,0,0.863191147423464*(I18)^(-0.234866270653838)) -> 0 | N18: =L18*$C$9*$C$16 + M18*$C$18 -> 1.4732256 | O18: =($C$19*N18)*($C$32/($C$29+($C$30-$C$29)*(LN($C$6^-1))^(1/$C$31)))^(1/$C$11) -> 12.936191 | P18: =IF($C$7="Deep Groove", SMALL($AF$8:$AF$27,COUNTIF($AF$8:$AF$27,"<"&O18)+1), IF($C$7="Angular", SMALL($AH$8:$AH$27,COUNTIF($AH$8:$AH$27,"<"&O18)+1), IF($C$7="02-Series", SMALL($AC$62:$AC$82,COUNTIF($AC$62:$AC$82,"<"&O18)+1), IF($C$7="03-Series", SMALL($AG$62:$AG$82,COUNTIF($AG$62:$AG$82,"<"&O18)+1), NA())))) -> 14 | Q18: =IF($C$7="Deep Groove",VLOOKUP(P18,$AF$8:$AG$27,2,FALSE), IF($C$7="Angular", VLOOKUP(P18,$AH$8:$AI$27,2,FALSE), IF($C$7="02-Series", VLOOKUP(P18,$AC$62:$AD$82,2,FALSE), IF($C$7="03-Series", VLOOKUP(P18,$AG$62:$AH$82,2,FALSE), NA())))) -> 6.95 | Z18: 50 | AA18: 90 | AB18: 20 | AC18: 1 | AD18: 56 | AE18: 82 | AF18: 35.1 | AG18: 19.6 | AH18: 37.7 | AI18: 22.8 | AK18: 0.56 | AL18: 0.44 | AM18: 1 | AN18: 0 | AO18: 0.56 | AP18: 1
B19: Load Application Factor, af | C19: 1 | H19: 8 | I19: =IF($C$18/Q18 < 0.014, 0.014, $C$18/Q18) -> 0.014 | J19: =$C$18/($C$9*$C$16) -> 0 | K19: =0.506467531924409*(I19)^0.23203728471849 -> 0.18809801 | L19: =IF(J19<=K19,1,0.56) -> 1 | M19: =IF(J19<=K19,0,0.863191147423464*(I19)^(-0.234866270653838)) -> 0 | N19: =L19*$C$9*$C$16 + M19*$C$18 -> 1.4732256 | O19: =($C$19*N19)*($C$32/($C$29+($C$30-$C$29)*(LN($C$6^-1))^(1/$C$31)))^(1/$C$11) -> 12.936191 | P19: =IF($C$7="Deep Groove", SMALL($AF$8:$AF$27,COUNTIF($AF$8:$AF$27,"<"&O19)+1), IF($C$7="Angular", SMALL($AH$8:$AH$27,COUNTIF($AH$8:$AH$27,"<"&O19)+1), IF($C$7="02-Series", SMALL($AC$62:$AC$82,COUNTIF($AC$62:$AC$82,"<"&O19)+1), IF($C$7="03-Series", SMALL($AG$62:$AG$82,COUNTIF($AG$62:$AG$82,"<"&O19)+1), NA())))) -> 14 | Q19: =IF($C$7="Deep Groove",VLOOKUP(P19,$AF$8:$AG$27,2,FALSE), IF($C$7="Angular", VLOOKUP(P19,$AH$8:$AI$27,2,FALSE), IF($C$7="02-Series", VLOOKUP(P19,$AC$62:$AD$82,2,FALSE), IF($C$7="03-Series", VLOOKUP(P19,$AG$62:$AH$82,2,FALSE), NA())))) -> 6.95 | Z19: 55 | AA19: 100 | AB19: 21 | AC19: 1.5 | AD19: 63 | AE19: 90 | AF19: 43.6 | AG19: 25 | AH19: 46.2 | AI19: 28.5
H20: 9 | I20: =IF($C$18/Q19 < 0.014, 0.014, $C$18/Q19) -> 0.014 | J20: =$C$18/($C$9*$C$16) -> 0 | K20: =0.506467531924409*(I20)^0.23203728471849 -> 0.18809801 | L20: =IF(J20<=K20,1,0.56) -> 1 | M20: =IF(J20<=K20,0,0.863191147423464*(I20)^(-0.234866270653838)) -> 0 | N20: =L20*$C$9*$C$16 + M20*$C$18 -> 1.4732256 | O20: =($C$19*N20)*($C$32/($C$29+($C$30-$C$29)*(LN($C$6^-1))^(1/$C$31)))^(1/$C$11) -> 12.936191 | P20: =IF($C$7="Deep Groove", SMALL($AF$8:$AF$27,COUNTIF($AF$8:$AF$27,"<"&O20)+1), IF($C$7="Angular", SMALL($AH$8:$AH$27,COUNTIF($AH$8:$AH$27,"<"&O20)+1), IF($C$7="02-Series", SMALL($AC$62:$AC$82,COUNTIF($AC$62:$AC$82,"<"&O20)+1), IF($C$7="03-Series", SMALL($AG$62:$AG$82,COUNTIF($AG$62:$AG$82,"<"&O20)+1), NA())))) -> 14 | Q20: =IF($C$7="Deep Groove",VLOOKUP(P20,$AF$8:$AG$27,2,FALSE), IF($C$7="Angular", VLOOKUP(P20,$AH$8:$AI$27,2,FALSE), IF($C$7="02-Series", VLOOKUP(P20,$AC$62:$AD$82,2,FALSE), IF($C$7="03-Series", VLOOKUP(P20,$AG$62:$AH$82,2,FALSE), NA())))) -> 6.95 | Z20: 60 | AA20: 110 | AB20: 22 | AC20: 1.5 | AD20: 70 | AE20: 99 | AF20: 47.5 | AG20: 28 | AH20: 55.9 | AI20: 35.5
B21: Design Cycle Lifetime | H21: 10 | I21: =IF($C$18/Q20 < 0.014, 0.014, $C$18/Q20) -> 0.014 | J21: =$C$18/($C$9*$C$16) -> 0 | K21: =0.506467531924409*(I21)^0.23203728471849 -> 0.18809801 | L21: =IF(J21<=K21,1,0.56) -> 1 | M21: =IF(J21<=K21,0,0.863191147423464*(I21)^(-0.234866270653838)) -> 0 | N21: =L21*$C$9*$C$16 + M21*$C$18 -> 1.4732256 | O21: =($C$19*N21)*($C$32/($C$29+($C$30-$C$29)*(LN($C$6^-1))^(1/$C$31)))^(1/$C$11) -> 12.936191 | P21: =IF($C$7="Deep Groove", SMALL($AF$8:$AF$27,COUNTIF($AF$8:$AF$27,"<"&O21)+1), IF($C$7="Angular", SMALL($AH$8:$AH$27,COUNTIF($AH$8:$AH$27,"<"&O21)+1), IF($C$7="02-Series", SMALL($AC$62:$AC$82,COUNTIF($AC$62:$AC$82,"<"&O21)+1), IF($C$7="03-Series", SMALL($AG$62:$AG$82,COUNTIF($AG$62:$AG$82,"<"&O21)+1), NA())))) -> 14 | Q21: =IF($C$7="Deep Groove",VLOOKUP(P21,$AF$8:$AG$27,2,FALSE), IF($C$7="Angular", VLOOKUP(P21,$AH$8:$AI$27,2,FALSE), IF($C$7="02-Series", VLOOKUP(P21,$AC$62:$AD$82,2,FALSE), IF($C$7="03-Series", VLOOKUP(P21,$AG$62:$AH$82,2,FALSE), NA())))) -> 6.95 | Z21: 65 | AA21: 120 | AB21: 23 | AC21: 1.5 | AD21: 74 | AE21: 109 | AF21: 55.9 | AG21: 34 | AH21: 63.7 | AI21: 41.5
B22: Lifetime, ℒD | C22: 4000 | D22: hrs | Z22: 70 | AA22: 125 | AB22: 24 | AC22: 1.5 | AD22: 79 | AE22: 114 | AF22: 61.8 | AG22: 37.5 | AH22: 68.9 | AI22: 45.5
B23: Rotation Speed, n | C23: ='L25 Gears Cont. Q25'!I34 -> 720 | D23: rpm | H23: Final Iterated Values | Z23: 75 | AA23: 130 | AB23: 25 | AC23: 1.5 | AD23: 86 | AE23: 119 | AF23: 66.3 | AG23: 40.5 | AH23: 71.5 | AI23: 49
B24: Design Lifetime, LD | C24: =IF(F25,C25,C22*C23*60) -> 172800000 | D24: revs | H24: Iterated C10 | I24: =P21 -> 14 | J24: kN | Z24: 80 | AA24: 140 | AB24: 26 | AC24: 2 | AD24: 93 | AE24: 127 | AF24: 70.2 | AG24: 45 | AH24: 80.6 | AI24: 55
D25: revs | E25: Override LD | F25: FALSE | I25: =I24/4.448 -> 3.147482 | J25: klbf | Z25: 85 | AA25: 150 | AB25: 28 | AC25: 2 | AD25: 99 | AE25: 136 | AF25: 83.2 | AG25: 53 | AH25: 90.4 | AI25: 63
H26: Iterated C0 | I26: =Q21 -> 6.95 | J26: kN | Z26: 90 | AA26: 160 | AB26: 30 | AC26: 2 | AD26: 104 | AE26: 146 | AF26: 95.6 | AG26: 62 | AH26: 106 | AI26: 73.5
B27: Weibull Paramters Automattically Based on Bearing Brand | E27: RD for 90% = | F27: =EXP(-1*((1 - C29) / (C30 - C29))^C31) -> 0.8990379 | I27: =I26/4.448 -> 1.5625 | J27: klbf | Z27: 95 | AA27: 170 | AB27: 32 | AC27: 2 | AD27: 110 | AE27: 156 | AF27: 108 | AG27: 69.5 | AH27: 121 | AI27: 85
B28: Rating Life, L10 | C28: =IF(F36,C37,VLOOKUP($C$5,$T$6:$X$7,2,FALSE)) -> 1000000 | D28: revs
B29: x0 | C29: =IF(F36,C38,VLOOKUP($C$5,$T$6:$X$7,3,FALSE)) -> 0.02
B30: θ | C30: =IF(F36,C40,VLOOKUP($C$5,$T$6:$X$7,4,FALSE)) -> 4.459
B31: b | C31: =IF(F36,C42,VLOOKUP($C$5,$T$6:$X$7,5,FALSE)) -> 1.483
B32: Nomormalized Lifetime by Design, xD | C32: =IF(F33,C33,C24/C28) -> 172.8 | D32: revs
D33: revs | E33: Override xD | F33: FALSE
B34: Normalized Lifetime, xB | C34: =C29+(C30-C29)*(LN(C6^-1))^(1/C31) -> 0.25523029 | E34: For RD | F34: =C6 -> 0.98725854
B36: Weibull Parameters | E36: Override Weibull Parameters | F36: FALSE
B37: Rating Life, L10 | C37: =10^6 -> 1000000 | D37: revs
B38: x0 | C38: 0.02
B39: θ - x0 | C39: 4.439
B40: θ | C40: =IF(F41,C41,C39+C38) -> 4.459
D41: revs | E41: Override θ | F41: FALSE
B42: b | C42: 1.483
Z58: Table 11-3
...
