Workbook

Sheet Lab 3 Updated Jointed Assem (2)
B3: INPUTS | C3: Units: | D3: Metric | I3: OUTPUTS | P3: INPUTS | T3: OUTPUTS | AA3: For bolt of 14 mm | AD3: For bolt of 16 mm | AH3: Tables
I4: Apex angle, α | J4: 30 | K4: degrees | AA4: Fastener Stiffness, kb | AB4: ='Lab 3 Updated Jointed Assembly'!C34 -> 1.7447146e+11 | AC4: mN/m | AD4: Fastener Stiffness, kb | AE4: =C31 -> 2.3050626e+11 | AF4: mN/m | AI4: Table 8-17 | AN4: Table 8-11 | AV4: Table 8-1 | BF4: Table 8-2
B5: Member Properties | E5: Elastic Modulus | I5: Frusta Dimensions | P5: Calculations for Loading due to Pressurized Cylinder | T5: Minimum Strengths of the Bolt from Tables 8-9, 8-11 and 8-17 | AB5: ='Lab 3 Updated Jointed Assembly'!C35 -> 174.47146 | AC5: MN/m | AE5: =C32 -> 230.50626 | AF5: MN/m | AI5: Metric | AN5: Metric | AZ5: Metric | BK5: English
D6: =IF($D$3="English","in", "mm") -> mm | G6: =IF($D$3="English","psi","Pa") -> Pa | I6: Segment | J6: =_xlfn.CONCAT("Thickness ", "[",D6,"]") -> Thickness [mm] | K6: =_xlfn.CONCAT("D ", "[",D13,"]") -> D [mm] | L6: =_xlfn.CONCAT("E ", "[",G6,"]") -> E [Pa] | M6: =_xlfn.CONCAT("k ", "[",D31,"]") -> k [mN/m] | N6: 1/k | P6: Pressurized Cylinder diameter | Q6: 95 | R6: =IF($D$3="English","in", "mm") -> mm | T6: Minimum Proof Strength, Sp | U6: =IF(AND($C$13>=$AO$30,$C$13<=$AP$30),AQ30,IF(AND($C$13>=$AO$31,$C$13<=$AP$31),AQ31,NA())) -> 830000000 | V6: =IF($D$3="English","psi","Pa") -> Pa | AA6: Member Stiffness, km | AB6: ='Lab 3 Updated Jointed Assembly'!J17 -> 8.3374001e+11 | AC6: mN/m | AD6: Member Stiffness, km | AE6: =J17 -> 9.7440431e+11 | AF6: mN/m | AI6: Property Class | AJ6: Min Size | AK6: Max Size | AL6: Endurance Strength (Pa) | AN6: Property Class | AO6: Min Size | AP6: Max Size | AQ6: Proof Strength (Pa) | AR6: Tensile Strength (Pa) | AS6: Yield Strength (Pa) | AT6: Material | AV6: UNC | BA6: UNF | BF6: UNC | BL6: UNF
B7: Aluminum Cam Carrier Length | C7: 51 | D7: =IF($D$3="English","in", "mm") -> mm | E7: Aluminum Elastic Modulus | F7: =68.9*10^9 -> 68900000000 | G7: =IF($D$3="English","psi","Pa") -> Pa | I7: 1 | J7: =C6 -> 0 | K7: =1.5*C13 -> 24 | L7: =F6 -> 0 | M7: =IF(J7=0,0,(PI()*L7*$C$13*TAN(RADIANS($J$4)))/LN(((2*J7*TAN(RADIANS($J$4))+K7-$C$13)*(K7+$C$13))/((2*J7*TAN(RADIANS($J$4))+K7+$C$13)*(K7-$C$13)))) -> 0 | N7: =IF(M7=0,0,M7^-1) -> 0 | Q7: =Q6*10^-3 -> 0.095 | R7: =IF($D$3="English","*10^3 in", "m") -> m | U7: =IF($D$3="English",U6*10^-3,U6*10^-6) -> 830 | V7: =IF($D$3="English","kpsi","MPa") -> MPa | AB7: ='Lab 3 Updated Jointed Assembly'!J18 -> 833.74001 | AC7: MN/m | AE7: =J18 -> 974.40431 | AF7: MN/m | AI7: 8.8 | AJ7: 16 | AK7: 36 | AL7: 129000000 | AN7: 4.6 | AO7: 5 | AP7: 36 | AQ7: 225000000 | AR7: 400000000 | AS7: 240000000 | AT7: Low or medium carbon | AV7: Nominal Major Diameter d [mm] | AW7: Pitch p [mm] | AX7: Tensile-Stress Area At​ [mm2] | AY7: Minor-Diameter Area Ar [mm2] | BA7: Nominal Major Diameter d [mm] | BB7: Pitch p [mm] | BC7: Tensile-Stress Area At​ [mm2] | BD7: Minor-Diameter Area Ar [mm2] | BF7: Size Designation | BG7: Nominal Major Diameter d [in] | BH7: Threads per Inch N [in] | BI7: Tensile-Stress Area At​ [in2] | BJ7: Minor-Diameter Area Ar [in2] | BL7: Size Designation | BM7: Nominal Major Diameter d [in] | BN7: Threads per Inch N [in] | BO7: Tensile-Stress Area At​ [in2] | BP7: Minor-Diameter Area Ar [in2]
B8: Cast Iron Head Length | C8: 95 | D8: =IF($D$3="English","in", "mm") -> mm | E8: Cast Iron Elastic Modulus | F8: =120.5*10^9 -> 120500000000 | G8: =IF($D$3="English","psi","Pa") -> Pa | I8: 2 | J8: =IF(C6+C7<J15,C7,J15-C6) -> 51 | K8: =K7+2*J7*TAN(RADIANS($J$4)) -> 24 | L8: =F7 -> 68900000000 | M8: =IF(J8=0,0,(PI()*L8*$C$13*TAN(RADIANS($J$4)))/LN(((2*J8*TAN(RADIANS($J$4))+K8-$C$13)*(K8+$C$13))/((2*J8*TAN(RADIANS($J$4))+K8+$C$13)*(K8-$C$13)))) -> 1.6410083e+12 | N8: =IF(M8=0,0,M8^-1) -> 6.0938144e-13 | P8: Pressurized Cylinder Area | Q8: =IF($D$3="English",PI()*(Q6^2)*0.25,PI()*(Q7^2)*0.25) -> 0.0070882184 | R8: =IF($D$3="English","in^2","m^2") -> m^2 | T8: Minimum Tensile Strength, Sut | U8: =IF(AND($C$13>=$AO$30,$C$13<=$AP$30),AR30,IF(AND($C$13>=$AO$31,$C$13<=$AP$31),AR31,NA())) -> 1040000000 | V8: =IF($D$3="English","psi","Pa") -> Pa | AA8: Joint Compliance, C | AB8: ='Lab 3 Updated Jointed Assembly'!W16 -> 0.17305046 | AC8: - | AD8: Joint Compliance, C | AE8: =U17 -> 0.1913057 | AF8: - | AI8: 9.8 | AJ8: 1.6 | AK8: 16 | AL8: 140000000 | AN8: 4.8 | AO8: 1.6 | AP8: 16 | AQ8: 310000000 | AR8: 420000000 | AS8: 340000000 | AT8: Low or medium carbon | AV8: 1.6 | AW8: 0.35 | AX8: 1.27 | AY8: 1.07 | BA8: 1.6 | BB8: =NA() -> #N/A | BC8: =NA() -> #N/A | BD8: =NA() -> #N/A | BF8: =0 -> 0 | BG8: 0.06 | BH8: =NA() -> #N/A | BI8: =NA() -> #N/A | BJ8: =NA() -> #N/A | BL8: =0 -> 0 | BM8: 0.06 | BN8: 80 | BO8: 0.0018 | BP8: 0.00151
B9: Cast Iron Block Length | C9: 10 | D9: =IF($D$3="English","in", "mm") -> mm | E9: Cast Iron Elastic Modulus | F9: =120.5*10^9 -> 120500000000 | G9: =IF($D$3="English","psi","Pa") -> Pa | I9: 3 | J9: =IF(C6+C7<J15,J15-C7-C6,C6+C7-J15) -> 31 | K9: =IF(J7+J8<J15,K8+2*J8*TAN(RADIANS($J$4)),K8+2*J8*TAN(RADIANS($J$4))-2*J9*TAN(RADIANS($J$4))) -> 82.889727 | L9: =IF(J7+J8<J15,F8,F7) -> 120500000000 | M9: =IF(J9=0,0,(PI()*L9*$C$13*TAN(RADIANS($J$4)))/LN(((2*J9*TAN(RADIANS($J$4))+K9-$C$13)*(K9+$C$13))/((2*J9*TAN(RADIANS($J$4))+K9+$C$13)*(K9-$C$13)))) -> 2.9217598e+13 | N9: =IF(M9=0,0,M9^-1) -> 3.4225949e-14 | U9: =IF($D$3="English",U8*10^-3,U8*10^-6) -> 1040 | V9: =IF($D$3="English","kpsi","MPa") -> MPa | AA9: Joint opening FoS, ηo | AB9: ='Lab 3 Updated Jointed Assembly'!W37 -> 7.3768268 | AC9: - | AD9: Joint opening FoS, ηo | AE9: =U40 -> 10.298311 | AF9: - | AI9: 10.9 | AJ9: 5 | AK9: 36 | AL9: 162000000 | AN9: 5.8 | AO9: 5 | AP9: 24 | AQ9: 380000000 | AR9: 520000000 | AS9: 420000000 | AT9: Low or medium carbon | AV9: 2 | AW9: 0.4 | AX9: 2.07 | AY9: 1.79 | BA9: 2 | BB9: =NA() -> #N/A | BC9: =NA() -> #N/A | BD9: =NA() -> #N/A | BF9: =1 -> 1 | BG9: 0.073 | BH9: 64 | BI9: 0.00263 | BJ9: 0.00218 | BL9: =1 -> 1 | BM9: 0.073 | BN9: 72 | BO9: 0.00278 | BP9: 0.00237
I10: 4 | J10: =C17-SUM(J7:J9)-J11 -> 72 | K10: =K11+2*J11*TAN(RADIANS($J$4)) -> 35.547005 | L10: =F8 -> 120500000000 | M10: =IF(J10=0,0,(PI()*L10*$C$13*TAN(RADIANS($J$4)))/LN(((2*J10*TAN(RADIANS($J$4))+K10-$C$13)*(K10+$C$13))/((2*J10*TAN(RADIANS($J$4))+K10+$C$13)*(K10-$C$13)))) -> 5.0071639e+12 | N10: =IF(M10=0,0,M10^-1) -> 1.9971385e-13 | P10: Pressure in Cyclinder, Prmin_total | Q10: 0 | R10: =IF($D$3="English","psi","Pa") -> Pa | T10: Minimum Yield Strength, Sy | U10: =IF(AND($C$13>=$AO$30,$C$13<=$AP$30),AS30,IF(AND($C$13>=$AO$31,$C$13<=$AP$31),AS31,NA())) -> 940000000 | V10: =IF($D$3="English","psi","Pa") -> Pa | AA10: Proof strength FoS, ηp | AB10: ='Lab 3 Updated Jointed Assembly'!W38 -> 1.073277 | AC10: - | AD10: Proof strength FoS, ηp | AE10: =U41 -> 1.0789392 | AF10: - | AI10: 12.9 | AJ10: 1.6 | AK10: 36 | AL10: 190000000 | AN10: 8.8 | AO10: 16 | AP10: 36 | AQ10: 600000000 | AR10: 830000000 | AS10: 660000000 | AT10: Medium carbon, Q&T | AV10: 2.5 | AW10: 0.45 | AX10: 3.39 | AY10: 2.98 | BA10: 2.5 | BB10: =NA() -> #N/A | BC10: =NA() -> #N/A | BD10: =NA() -> #N/A | BF10: =2 -> 2 | BG10: 0.086 | BH10: 56 | BI10: 0.0037 | BJ10: 0.0031 | BL10: =2 -> 2 | BM10: 0.086 | BN10: 64 | BO10: 0.00394 | BP10: 0.00339
B11: Bolt Properties | C11: =_xlfn.CONCAT(IF($D$3="English",_xlfn.CONCAT(TEXT(C13, "# ?/?"),"""-",C25,"-", C15, " ",C14),_xlfn.CONCAT("M",C13,"-", C25,"-", C15," ",C14)), " Grade ", C16) -> M16-2-238 UNC Grade 10.9 | I11: 5 | J11: =C9 -> 10 | K11: =1.5*C13 -> 24 | L11: =F9 -> 120500000000 | M11: =IF(J11=0,0,(PI()*L11*$C$13*TAN(RADIANS($J$4)))/LN(((2*J11*TAN(RADIANS($J$4))+K11-$C$13)*(K11+$C$13))/((2*J11*TAN(RADIANS($J$4))+K11+$C$13)*(K11-$C$13)))) -> 5.46607e+12 | N11: =IF(M11=0,0,M11^-1) -> 1.829468e-13 | P11: Pressure in Cyclinder, Prmax_total | Q11: =20*10^6 -> 20000000 | R11: =IF($D$3="English","psi","Pa") -> Pa | U11: =IF($D$3="English",U10*10^-3,U10*10^-6) -> 940 | V11: =IF($D$3="English","kpsi","MPa") -> MPa | AA11: Goodman Fatigue FoS, ηf | AB11: ='Lab 3 Updated Jointed Assembly'!W39 -> 3.6390751 | AC11: - | AD11: Goodman Fatigue FoS, ηf | AE11: =U42 -> 4.4940478 | AF11: - | AN11: 9.8 | AO11: 1.6 | AP11: 16 | AQ11: 650000000 | AR11: 900000000 | AS11: 720000000 | AT11: Medium carbon, Q&T | AV11: 3 | AW11: 0.5 | AX11: 5.03 | AY11: 4.47 | BA11: 3 | BB11: =NA() -> #N/A | BC11: =NA() -> #N/A | BD11: =NA() -> #N/A | BF11: =3 -> 3 | BG11: 0.099 | BH11: 48 | BI11: 0.00487 | BJ11: 0.00406 | BL11: =3 -> 3 | BM11: 0.099 | BN11: 56 | BO11: 0.00523 | BP11: 0.00451
B12: Bolt elastic modulus, E | C12: =207*10^9 -> 207000000000 | D12: =IF($D$3="English","psi","Pa") -> Pa | T12: Corrected Endurance Strength, Se | U12: =IF(AND($C$13>=AJ$20,$C$13<=AK$20),AL20,IF(AND($C$13>=AJ$21,$C$13<=AK$21),AL21,NA())) -> 162000000 | V12: =IF($D$3="English","psi","Pa") -> Pa | AA12: Proof load FoS, ηL | AB12: ='Lab 3 Updated Jointed Assembly'!W40 -> 3.6563906 | AC12: - | AD12: Proof load FoS, ηL | AE12: =U43 -> 4.5154315 | AF12: - | AI12: English | AN12: 10.9 | AO12: 5 | AP12: 36 | AQ12: 830000000 | AR12: 1040000000 | AS12: 940000000 | AT12: Low-carbon martensite, Q&T | AV12: 3.5 | AW12: 0.6 | AX12: 6.78 | AY12: 6 | BA12: 3.5 | BB12: =NA() -> #N/A | BC12: =NA() -> #N/A | BD12: =NA() -> #N/A | BF12: =4 -> 4 | BG12: 0.112 | BH12: 40 | BI12: 0.00604 | BJ12: 0.00496 | BL12: =4 -> 4 | BM12: 0.112 | BN12: 48 | BO12: 0.00661 | BP12: 0.00566
B13: Bolt diameter, d | C13: 16 | D13: =IF($D$3="English","in", "mm") -> mm | I13: Thickness check | J13: =SUM(J7:J11) -> 164 | K13: =IF($D$3="English","in", "mm") -> mm | P13: External Load total, Pmin_total | Q13: =Q10*$Q$8 -> 0 | R13: =IF($D$3="English","lbf", "N") -> N | U13: =IF($D$3="English",U12*10^-3,U12*10^-6) -> 162 | V13: =IF($D$3="English","kpsi","MPa") -> MPa | AA13: gasket pressure | AB13: ='Lab 3 Updated Jointed Assembly'!Q37 -> 20048777 | AC13: =IF($D$3="English","psi","Pa") -> Pa | AD13: gasket pressure | AE13: =Q28 -> 28588589 | AF13: =IF($D$3="English","psi","Pa") -> Pa | AI13: Property Class | AJ13: Min Size (in) | AK13: Max Size (in) | AL13: Endurance Strength (psi) | AN13: 12.9 | AO13: 1.6 | AP13: 36 | AQ13: 970000000 | AR13: 1220000000 | AS13: 1100000000 | AT13: Alloy, Q&T | AV13: 4 | AW13: 0.7 | AX13: 8.78 | AY13: 7.75 | BA13: 4 | BB13: =NA() -> #N/A | BC13: =NA() -> #N/A | BD13: =NA() -> #N/A | BF13: =5 -> 5 | BG13: 0.125 | BH13: 40 | BI13: 0.00796 | BJ13: 0.00672 | BL13: =5 -> 5 | BM13: 0.125 | BN13: 44 | BO13: 0.0088 | BP13: 0.00716
B14: Series | C14: UNC | I14: Grip length, l | J14: =C17 -> 164 | K14: =IF($D$3="English","in", "mm") -> mm | P14: External Load total, Pmax_total | Q14: =Q11*$Q$8 -> 141764.37 | R14: =IF($D$3="English","lbf", "N") -> N | AB14: ='Lab 3 Updated Jointed Assembly'!Q38 -> 20.048777 | AC14: =IF($D$3="English","kpsi","MPa") -> MPa | AE14: =Q29 -> 28.588589 | AF14: =IF($D$3="English","kpsi","MPa") -> MPa | AI14: 5 | AJ14: 0.125 | AK14: 1 | AL14: 18600 | AV14: 5 | AW14: 0.8 | AX14: 14.2 | AY14: 12.7 | BA14: 5 | BB14: =NA() -> #N/A | BC14: =NA() -> #N/A | BD14: =NA() -> #N/A | BF14: =6 -> 6 | BG14: 0.138 | BH14: 32 | BI14: 0.00909 | BJ14: 0.00745 | BL14: =6 -> 6 | BM14: 0.138 | BN14: 40 | BO14: 0.01015 | BP14: 0.00874
B15: Bolt Length, L | C15: 238 | D15: =IF($D$3="English","in", "mm") -> mm | I15: Half grip length, l/2 | J15: =C17/2 -> 82 | K15: =IF($D$3="English","in", "mm") -> mm | AA15: Percent above internal Pressure | AB15: ='Lab 3 Updated Jointed Assembly'!Q40 -> 0.0024388374 | AC15: - | AD15: Percent above internal Pressure | AE15: =Q30 -> 0.42942946 | AF15: - | AI15: 5 | AJ15: 1.125 | AK15: 1.5 | AL15: 16300 | AN15: Table 8-9 | AV15: 6 | AW15: 1 | AX15: 20.1 | AY15: 17.9 | BA15: 6 | BB15: =NA() -> #N/A | BC15: =NA() -> #N/A | BD15: =NA() -> #N/A | BF15: =8 -> 8 | BG15: 0.164 | BH15: 32 | BI15: 0.014 | BJ15: 0.01196 | BL15: =8 -> 8 | BM15: 0.164 | BN15: 36 | BO15: 0.01474 | BP15: 0.01285
B16: Grade No. | C16: 10.9 | P16: Loading on Bolts | T16: Bolt Loading | AI16: 7 | AJ16: 0.25 | AK16: 1.5 | AL16: 20600 | AN16: English | AV16: 8 | AW16: 1.25 | AX16: 36.6 | AY16: 32.8 | BA16: 8 | BB16: 1 | BC16: 39.2 | BD16: 36 | BF16: =10 -> 10 | BG16: 0.19 | BH16: 24 | BI16: 0.0175 | BJ16: 0.0145 | BL16: =10 -> 10 | BM16: 0.19 | BN16: 32 | BO16: 0.02 | BP16: 0.0175
B17: Grip length, l | C17: =SUM(C7:C9)+C13/2 -> 164 | D17: =IF($D$3="English","in", "mm") -> mm | I17: Member Stiffness, km | J17: =SUM(N7:N11)^-1 -> 9.7440431e+11 | K17: =IF($D$3="English","lbf/in","mN/m") -> mN/m | P17: Number of Bolts, N | Q17: 10 | T17: Joint Compliance, C | U17: =C31/(C31+J17) -> 0.1913057 | AI17: 8 | AJ17: 0.25 | AK17: 1.5 | AL17: 23200 | AN17: SAE Grade No. | AO17: Min Size (in) | AP17: Max Size (in) | AQ17: Proof Strength (psi) | AR17: Tensile Strength (psi) | AS17: Yield Strength (psi) | AT17: Material | AV17: 10 | AW17: 1.5 | AX17: 58 | AY17: 52.3 | BA17: 10 | BB17: 1.25 | BC17: 61.2 | BD17: 56.3 | BF17: =12 -> 12 | BG17: 0.216 | BH17: 24 | BI17: 0.0242 | BJ17: 0.0206 | BL17: =12 -> 12 | BM17: 0.216 | BN17: 28 | BO17: 0.0258 | BP17: 0.0226
B18: Threaded bolt length, LT | C18: =IF(F19,C19,IF(F18,C15,IF($D$3="English",IF(C15<=6, 2*C13+0.25, 2*C13+0.5),IF(AND(C15<=125,C13<=48),2*C13+6,IF(C15<=200,2*C13+12,2*C13+25))))) -> 133 | D18: =IF($D$3="English","in", "mm") -> mm | E18: Fully Threaded | F18: FALSE | J18: =IF($D$3="English",J17*10^-6,J17*10^-9) -> 974.40431 | K18: =IF($D$3="English","Mlbf/in","MN/m") -> MN/m | P18: Percent of Yield Load Preload is | Q18: 0.8 | T18: Opening load, Po | U18: =Q19/(1-U17) -> 145993.36 | V18: =IF($D$3="English","lbf", "N") -> N | AN18: 1 | AO18: 0.25 | AP18: 1.5 | AQ18: 33000 | AR18: 60000 | AS18: 36000 | AT18: Low or medium carbon | AV18: 12 | AW18: 1.75 | AX18: 84.3 | AY18: 76.3 | BA18: 12 | BB18: 1.25 | BC18: 92.1 | BD18: 86 | BF18: =1/4 -> 0.25 | BG18: 0.25 | BH18: 20 | BI18: 0.0318 | BJ18: 0.0269 | BL18: =1/4 -> 0.25 | BM18: 0.25 | BN18: 28 | BO18: 0.0364 | BP18: 0.0326
C19: 133 | D19: =IF($D$3="English","in", "mm") -> mm | E19: Override threaded length | F19: TRUE | P19: Preload, Fi | Q19: =IF(R50,O50,U19*Q18) -> 118064 | R19: =IF($D$3="English","lbf", "N") -> N | T19: Yield Load, SyL | U19: =IF($D$3="English",U10*$C$24,U10*$C$24) -> 147580 | V19: =IF($D$3="English","lbf", "N") -> N | AI19: Filtering Table 8-17 for when one grade no. has two lines of data based on diameter | AN19: 2 | AO19: 0.25 | AP19: 0.75 | AQ19: 55000 | AR19: 74000 | AS19: 57000 | AT19: Low or medium carbon | AV19: 14 | AW19: 2 | AX19: 115 | AY19: 104 | BA19: 14 | BB19: 1.5 | BC19: 125 | BD19: 116 | BF19: =5/16 -> 0.3125 | BG19: 0.3125 | BH19: 18 | BI19: 0.0524 | BJ19: 0.0454 | BL19: =5/16 -> 0.3125 | BM19: 0.3125 | BN19: 24 | BO19: 0.058 | BP19: 0.0524
B20: Unthreaded bolt length, ld | C20: =C15-C18 -> 105 | D20: =IF($D$3="English","in", "mm") -> mm | I20: Joint Compliance, C | J20: =U17 -> 0.1913057 | AI20: {=IF($D$3="English",_xlfn._xlws.FILTER(AI14:AL17,AI14:AI17=C16,AI18:AL19=NA()), _xlfn._xlws.FILTER(AI7:AL10,AI7:AI10=C16,AI18:AL19=NA()))} -> 10.9 | AJ20: 5 | AK20: 36 | AL20: 162000000 | AN20: 2 | AO20: 0.875 | AP20: 1.5 | AQ20: 33000 | AR20: 60000 | AS20: 36000 | AT20: =NA() -> #N/A | AV20: 16 | AW20: 2 | AX20: 157 | AY20: 144 | BA20: 16 | BB20: 1.5 | BC20: 167 | BD20: 157 | BF20: =3/8 -> 0.375 | BG20: 0.375 | BH20: 16 | BI20: 0.0775 | BJ20: 0.0678 | BL20: =3/8 -> 0.375 | BM20: 0.375 | BN20: 24 | BO20: 0.0878 | BP20: 0.0809
B21: Threaded bolt length in grip, lt | C21: =C17-C20 -> 59 | D21: =IF($D$3="English","in", "mm") -> mm | P21: Torque based on Preload | T21: External Load per joint, Pmin | U21: =Q47/Q17 -> 0 | V21: =IF($D$3="English","lbf", "N") -> N | W21: Alternating External Load per joint, Pa | X21: =0.5*(U22-U21) -> 7088.2184 | Y21: =IF($D$3="English","lbf", "N") -> N | AN21: 4 | AO21: 0.25 | AP21: 1.5 | AQ21: 65000 | AR21: 115000 | AS21: 100000 | AT21: Medium carbon, cold-drawn | AV21: 20 | AW21: 2.5 | AX21: 245 | AY21: 225 | BA21: 20 | BB21: 1.5 | BC21: 272 | BD21: 259 | BF21: =7/16 -> 0.4375 | BG21: 0.4375 | BH21: 14 | BI21: 0.1063 | BJ21: 0.0933 | BL21: =7/16 -> 0.4375 | BM21: 0.4375 | BN21: 20 | BO21: 0.1187 | BP21: 0.109
B22: Area of unthreaded portion, Ad | C22: =(PI()*(C13^2))/4 -> 201.06193 | D22: =IF($D$3="English","in^2","mm^2") -> mm^2 | P22: Torque, T | Q22: =IF($D$3="English",Q23*Q19*C13,Q23*Q19*(C13*10^-3)) -> 377.8048 | R22: =IF($D$3="English","in-lbf", "Nm") -> Nm | T22: External Load per joint, Pmax | U22: =Q48/Q17 -> 14176.437 | V22: =IF($D$3="English","lbf", "N") -> N | W22: Mean External Load per joint, Pm | X22: =0.5*(U22+U21) -> 7088.2184 | Y22: =IF($D$3="English","lbf", "N") -> N | AN22: 5 | AO22: 0.25 | AP22: 1 | AQ22: 85000 | AR22: 120000 | AS22: 92000 | AT22: Medium carbon, Q&T | AV22: 24 | AW22: 3 | AX22: 353 | AY22: 324 | BA22: 24 | BB22: 2 | BC22: 384 | BD22: 365 | BF22: =1/2 -> 0.5 | BG22: 0.5 | BH22: 13 | BI22: 0.1419 | BJ22: 0.1257 | BL22: =1/2 -> 0.5 | BM22: 0.5 | BN22: 20 | BO22: 0.1599 | BP22: 0.1486
B23: Area of threaded portion, At | C23: =IF($D$3="English",IF($C$14="UNC",VLOOKUP($C$13,$BG$8:$BJ$29,3,FALSE),VLOOKUP($C$13,$BM$8:$BP$29,3,FALSE)), IF($C$14="UNC",VLOOKUP($C$13,$AV$8:$AY$33,3,FALSE),VLOOKUP($C$13,$BA$8:$BD$33,3,FALSE))) -> 157 | D23: =IF($D$3="English","in^2","mm^2") -> mm^2 | P23: Torque coefficient, K | Q23: 0.2 | AN23: 5 | AO23: 1.125 | AP23: 1.5 | AQ23: 74000 | AR23: 105000 | AS23: 81000 | AT23: =NA() -> #N/A | AV23: 30 | AW23: 3.5 | AX23: 561 | AY23: 519 | BA23: 30 | BB23: 2 | BC23: 621 | BD23: 596 | BF23: =9/16 -> 0.5625 | BG23: 0.5625 | BH23: 12 | BI23: 0.182 | BJ23: 0.162 | BL23: =9/16 -> 0.5625 | BM23: 0.5625 | BN23: 18 | BO23: 0.203 | BP23: 0.189
C24: =IF($D$3="English",C23,C23*10^-6) -> 0.000157 | D24: =IF($D$3="English","in^2","m^2") -> m^2 | T24: Load per bolt, Fb_min | U24: =$U$17*U21+$Q$19 -> 118064 | V24: =IF($D$3="English","lbf", "N") -> N | W24: Alternating Load per bolt, Fa | X24: =0.5*(U25-U24) -> 1356.0166 | Y24: =IF($D$3="English","lbf", "N") -> N | AN24: 5.2 | AO24: 0.25 | AP24: 1 | AQ24: 85000 | AR24: 120000 | AS24: 92000 | AT24: Low-carbon martensite, Q&T | AV24: 36 | AW24: 4 | AX24: 817 | AY24: 759 | BA24: 36 | BB24: 2 | BC24: 915 | BD24: 884 | BF24: =5/8 -> 0.625 | BG24: 0.625 | BH24: 11 | BI24: 0.226 | BJ24: 0.202 | BL24: =5/8 -> 0.625 | BM24: 0.625 | BN24: 18 | BO24: 0.256 | BP24: 0.24
B25: =IF($D$3="English","Bolt threads per inch, p","Bolt pitch, p") -> Bolt pitch, p | C25: =IF($D$3="English",IF($C$14="UNC",VLOOKUP($C$13,$BG$8:$BJ$29,2,FALSE),VLOOKUP($C$13,$BM$8:$BP$29,2,FALSE)), IF($C$14="UNC",VLOOKUP($C$13,$AV$8:$AY$33,2,FALSE),VLOOKUP($C$13,$BA$8:$BD$33,2,FALSE))) -> 2 | D25: =IF($D$3="English","threads/in","mm") -> mm | P25: Gasket Clamping Pressure | T25: Load per bolt, Fb_max | U25: =$U$17*U22+$Q$19 -> 120776.03 | V25: =IF($D$3="English","lbf", "N") -> N | W25: Mean Load per bolt, Fm | X25: =0.5*(U25+U24) -> 119420.02 | Y25: =IF($D$3="English","lbf", "N") -> N | AA25: =AE9-AB9 -> 2.9214847 | AN25: 7 | AO25: 0.25 | AP25: 1.5 | AQ25: 105000 | AR25: 133000 | AS25: 115000 | AT25: Medium-carbon alloy, Q&T | AV25: 42 | AW25: 4.5 | AX25: 1120 | AY25: 1050 | BA25: 42 | BB25: 2 | BC25: 1260 | BD25: 1230 | BF25: =3/4 -> 0.75 | BG25: 0.75 | BH25: 10 | BI25: 0.334 | BJ25: 0.302 | BL25: =3/4 -> 0.75 | BM25: 0.75 | BN25: 16 | BO25: 0.373 | BP25: 0.351
P26: gasket area Ag | Q26: 37287.463 | R26: =IF($D$3="English","in^2","mm^2") -> mm^2 | AN26: 8 | AO26: 0.25 | AP26: 1.5 | AQ26: 120000 | AR26: 150000 | AS26: 130000 | AT26: Medium-carbon alloy, Q&T | AV26: 48 | AW26: 5 | AX26: 1470 | AY26: 1380 | BA26: 48 | BB26: 2 | BC26: 1670 | BD26: 1630 | BF26: =7/8 -> 0.875 | BG26: 0.875 | BH26: 9 | BI26: 0.462 | BJ26: 0.419 | BL26: =7/8 -> 0.875 | BM26: 0.875 | BN26: 14 | BO26: 0.509 | BP26: 0.48
B27: Unthreaded Fastener Stiffness, kd | C27: =IF(C20=0,0,(C22*C12)/C20) -> 3.9637923e+11 | D27: =IF($D$3="English","lbf/in","mN/m") -> mN/m | Q27: =Q26*10^-6 -> 0.037287463 | R27: =IF($D$3="English","in^2","m^2") -> m^2 | T27: Load per member, Fmin | U27: =(1-$U$17)*U21-$Q$19 -> -118064 | V27: =IF($D$3="English","lbf", "N") -> N | AN27: 8.2 | AO27: 0.25 | AP27: 1 | AQ27: 120000 | AR27: 150000 | AS27: 130000 | AT27: Low-carbon martensite, Q&T | AV27: 56 | AW27: 5.5 | AX27: 2030 | AY27: 1910 | BA27: 56 | BB27: 2 | BC27: 2300 | BD27: 2250 | BF27: =1 -> 1 | BG27: 1 | BH27: 8 | BI27: 0.606 | BJ27: 0.551 | BL27: =1 -> 1 | BM27: 1 | BN27: 12 | BO27: 0.663 | BP27: 0.625
C28: =IF($D$3="English",C27*10^-6,C27*10^-9) -> 396.37923 | D28: =IF($D$3="English","Mlbf/in","MN/m") -> MN/m | P28: gasket pressure | Q28: =-U28/(Q27/Q17) -> 28588589 | R28: =IF($D$3="English","psi","Pa") -> Pa | T28: Load per member, Fmax | U28: =(1-$U$17)*U22-$Q$19 -> -106599.6 | V28: =IF($D$3="English","lbf", "N") -> N | AV28: 64 | AW28: 6 | AX28: 2680 | AY28: 2520 | BA28: 64 | BB28: 2 | BC28: 3030 | BD28: 2980 | BF28: =1.25 -> 1.25 | BG28: 1.25 | BH28: 7 | BI28: 0.969 | BJ28: 0.89 | BL28: =1.25 -> 1.25 | BM28: 1.25 | BN28: 12 | BO28: 1.073 | BP28: 1.024
B29: Threaded Fastener Stiffness, kt | C29: =IF(C21=0,0,(C23*C12)/C21) -> 5.5083051e+11 | D29: =IF($D$3="English","lbf/in","mN/m") -> mN/m | Q29: =IF($D$3="English",Q28*10^-3,Q28*10^-6) -> 28.588589 | R29: =IF($D$3="English","kpsi","MPa") -> MPa | AN29: Filtering Tables 8-9 and 8-11 for when one grade no. has two lines of data based on diameter | AV29: 72 | AW29: 6 | AX29: 3460 | AY29: 3280 | BA29: 72 | BB29: 2 | BC29: 3860 | BD29: 3800 | BF29: =1.5 -> 1.5 | BG29: 1.5 | BH29: 6 | BI29: 1.405 | BJ29: 1.294 | BL29: =1.5 -> 1.5 | BM29: 1.5 | BN29: 12 | BO29: 1.581 | BP29: 1.521
C30: =IF($D$3="English",C29*10^-6,C29*10^-9) -> 550.83051 | D30: =IF($D$3="English","Mlbf/in","MN/m") -> MN/m | P30: Percent above internal Pressure | Q30: =(Q28-Q11)/Q11 -> 0.42942946 | R30: - | AN30: {=IF($D$3="English",_xlfn._xlws.FILTER(AN18:AT27,AN18:AN27=C16,AN28:AT29=NA()), _xlfn._xlws.FILTER(AN7:AT13,AN7:AN13=C16,AN28:AT29=NA()))} -> 10.9 | AO30: 5 | AP30: 36 | AQ30: 830000000 | AR30: 1040000000 | AS30: 940000000 | AT30: Low-carbon martensite, Q&T | AV30: 80 | AW30: 6 | AX30: 4340 | AY30: 4140 | BA30: 80 | BB30: 1.5 | BC30: 4850 | BD30: 4800
B31: Fastener Stiffness, kb | C31: =SUM(IF(C27=0,0,C27^-1),IF(C29=0,0,C29^-1))^-1 -> 2.3050626e+11 | D31: =IF($D$3="English","lbf/in","mN/m") -> mN/m | T31: Bolt Stress | AV31: 90 | AW31: 6 | AX31: 5590 | AY31: 5360 | BA31: 90 | BB31: 2 | BC31: 6100 | BD31: 6020
C32: =IF($D$3="English",C31*10^-6,C31*10^-9) -> 230.50626 | D32: =IF($D$3="English","Mlbf/in","MN/m") -> MN/m | T32: Initial Bolt Sress, σi | U32: =Q19/$C$24 -> 752000000 | V32: =IF($D$3="English","psi","Pa") -> Pa | AV32: 100 | AW32: 6 | AX32: 6990 | AY32: 6740 | BA32: 100 | BB32: 2 | BC32: 7560 | BD32: 7470
U33: =IF($D$3="English",U32*10^-3,U32*10^-6) -> 752 | V33: =IF($D$3="English","kpsi","MPa") -> MPa | AV33: 110 | AW33: 6 | AX33: =NA() -> #N/A | AY33: =NA() -> #N/A | BA33: 110 | BB33: 2 | BC33: 9180 | BD33: 9080
B34: Threaded into bottom member | C34: FALSE | D34: <---- Note that if this option is selected also | T34: Bolt Sress, σmin | U34: =U24/$C$24 -> 752000000 | V34: =IF($D$3="English","psi","Pa") -> Pa | W34: Alternating Bolt Sress, σa | X34: =0.5*(U36-U34) -> 8637048.3 | Y34: =IF($D$3="English","psi","Pa") -> Pa
B35: Threaded into nut | C35: =NOT(C34) -> TRUE | D35: change Bottom Washer Length to 0 | U35: =IF($D$3="English",U34*10^-3,U34*10^-6) -> 752 | V35: =IF($D$3="English","kpsi","MPa") -> MPa | X35: =IF($D$3="English",X34*10^-3,X34*10^-6) -> 8.6370483 | Y35: =IF($D$3="English","kpsi","MPa") -> MPa
T36: Bolt Sress, σmax | U36: =U25/$C$24 -> 7.692741e+08 | V36: =IF($D$3="English","psi","Pa") -> Pa | W36: Mean Bolt Sress, σm | X36: =0.5*(U36+U34) -> 7.6063705e+08 | Y36: =IF($D$3="English","psi","Pa") -> Pa
U37: =IF($D$3="English",U36*10^-3,U36*10^-6) -> 769.2741 | V37: =IF($D$3="English","kpsi","MPa") -> MPa | X37: =IF($D$3="English",X36*10^-3,X36*10^-6) -> 760.63705 | Y37: =IF($D$3="English","kpsi","MPa") -> MPa
T39: Factors of Safety
T40: Joint opening FoS, ηo | U40: =U18/U22 -> 10.298311
T41: Proof strength FoS, ηp | U41: =(U6*$C$24)/(U25) -> 1.0789392
T42: Goodman Fatigue FoS, ηf | U42: =(U12*(U8-U32))/(U8*X34+U12*(X36-U32)) -> 4.4940478
T43: Proof load FoS, ηL | U43: =(U6*$C$24-Q19)/(U17*U22) -> 4.5154315
...

Sheet Lab 3 Updated Jointed Assembly
B2: Lectures 7&8 Bolt and Member Stiffness Calculations | P2: Lectures 9 Tensile Load Calculations
B3: INPUTS | C3: Units: | D3: Metric | I3: OUTPUTS | P3: INPUTS | V3: OUTPUTS | AC3: Tables
I4: Apex angle, α | J4: 30 | K4: degrees | AD4: Table 8-17 | AI4: Table 8-11 | AQ4: Table 8-1 | BA4: Table 8-2
B5: Member Properties | E5: Elastic Modulus | I5: Frusta Dimensions | V5: Minimum Strengths of the Bolt | AD5: Metric | AI5: Metric | AU5: Metric | BF5: English
B6: Top Washer Length, ttw | D6: =IF($D$3="English","in", "mm") -> mm | E6: E top washer | G6: =IF($D$3="English","psi","Pa") -> Pa | I6: Segment | J6: =_xlfn.CONCAT("Thickness ", "[",D6,"]") -> Thickness [mm] | K6: =_xlfn.CONCAT("D ", "[",D13,"]") -> D [mm] | L6: =_xlfn.CONCAT("E ", "[",G6,"]") -> E [Pa] | M6: =_xlfn.CONCAT("k ", "[",D34,"]") -> k [mN/m] | N6: 1/k | V6: Minimum Proof Strength, Sp | W6: =IF(AND($C$13>=$AJ$30,$C$13<=$AK$30),AL30,IF(AND($C$13>=$AJ$31,$C$13<=$AK$31),AL31,NA())) -> 830000000 | X6: =IF($D$3="English","psi","Pa") -> Pa | AD6: Property Class | AE6: Min Size | AF6: Max Size | AG6: Endurance Strength (Pa) | AI6: Property Class | AJ6: Min Size | AK6: Max Size | AL6: Proof Strength (Pa) | AM6: Tensile Strength (Pa) | AN6: Yield Strength (Pa) | AO6: Material | AQ6: UNC | AV6: UNF | BA6: UNC | BG6: UNF
B7: Top Member Length, ttm | C7: 51 | D7: =IF($D$3="English","in", "mm") -> mm | E7: E top member | F7: =68.9*10^9 -> 68900000000 | G7: =IF($D$3="English","psi","Pa") -> Pa | I7: 1 | J7: =C6 -> 0 | K7: =1.5*C13 -> 21 | L7: =F6 -> 0 | M7: =IF(J7=0,0,(PI()*L7*$C$13*TAN(RADIANS($J$4)))/LN(((2*J7*TAN(RADIANS($J$4))+K7-$C$13)*(K7+$C$13))/((2*J7*TAN(RADIANS($J$4))+K7+$C$13)*(K7-$C$13)))) -> 0 | N7: =IF(M7=0,0,M7^-1) -> 0 | W7: =IF($D$3="English",W6*10^-3,W6*10^-6) -> 830 | X7: =IF($D$3="English","kpsi","MPa") -> MPa | AD7: 8.8 | AE7: 16 | AF7: 36 | AG7: 129000000 | AI7: 4.6 | AJ7: 5 | AK7: 36 | AL7: 225000000 | AM7: 400000000 | AN7: 240000000 | AO7: Low or medium carbon | AQ7: Nominal Major Diameter d [mm] | AR7: Pitch p [mm] | AS7: Tensile-Stress Area At​ [mm2] | AT7: Minor-Diameter Area Ar [mm2] | AV7: Nominal Major Diameter d [mm] | AW7: Pitch p [mm] | AX7: Tensile-Stress Area At​ [mm2] | AY7: Minor-Diameter Area Ar [mm2] | BA7: Size Designation | BB7: Nominal Major Diameter d [in] | BC7: Threads per Inch N [in] | BD7: Tensile-Stress Area At​ [in2] | BE7: Minor-Diameter Area Ar [in2] | BG7: Size Designation | BH7: Nominal Major Diameter d [in] | BI7: Threads per Inch N [in] | BJ7: Tensile-Stress Area At​ [in2] | BK7: Minor-Diameter Area Ar [in2]
B8: Bottom Member Length, tbm | C8: 95 | D8: =IF($D$3="English","in", "mm") -> mm | E8: E bottom member | F8: =120.5*10^9 -> 120500000000 | G8: =IF($D$3="English","psi","Pa") -> Pa | I8: 2 | J8: =IF(C6+C7<J15,C7,J15-C6) -> 51 | K8: =K7+2*J7*TAN(RADIANS($J$4)) -> 21 | L8: =F7 -> 68900000000 | M8: =IF(J8=0,0,(PI()*L8*$C$13*TAN(RADIANS($J$4)))/LN(((2*J8*TAN(RADIANS($J$4))+K8-$C$13)*(K8+$C$13))/((2*J8*TAN(RADIANS($J$4))+K8+$C$13)*(K8-$C$13)))) -> 1.3937637e+12 | N8: =IF(M8=0,0,M8^-1) -> 7.1748173e-13 | V8: Minimum Tensile Strength, Sut | W8: =IF(AND($C$13>=$AJ$30,$C$13<=$AK$30),AM30,IF(AND($C$13>=$AJ$31,$C$13<=$AK$31),AM31,NA())) -> 1040000000 | X8: =IF($D$3="English","psi","Pa") -> Pa | AD8: 9.8 | AE8: 1.6 | AF8: 16 | AG8: 140000000 | AI8: 4.8 | AJ8: 1.6 | AK8: 16 | AL8: 310000000 | AM8: 420000000 | AN8: 340000000 | AO8: Low or medium carbon | AQ8: 1.6 | AR8: 0.35 | AS8: 1.27 | AT8: 1.07 | AV8: 1.6 | AW8: =NA() -> #N/A | AX8: =NA() -> #N/A | AY8: =NA() -> #N/A | BA8: =0 -> 0 | BB8: 0.06 | BC8: =NA() -> #N/A | BD8: =NA() -> #N/A | BE8: =NA() -> #N/A | BG8: =0 -> 0 | BH8: 0.06 | BI8: 80 | BJ8: 0.0018 | BK8: 0.00151
B9: Bottom Washer Length, tbw | C9: 10 | D9: =IF($D$3="English","in", "mm") -> mm | E9: E bottom washer | F9: =120.5*10^9 -> 120500000000 | G9: =IF($D$3="English","psi","Pa") -> Pa | I9: 3 | J9: =IF(C6+C7<J15,J15-C7-C6,C6+C7-J15) -> 30.5 | K9: =IF(J7+J8<J15,K8+2*J8*TAN(RADIANS($J$4)),K8+2*J8*TAN(RADIANS($J$4))-2*J9*TAN(RADIANS($J$4))) -> 79.889727 | L9: =IF(J7+J8<J15,F8,F7) -> 120500000000 | M9: =IF(J9=0,0,(PI()*L9*$C$13*TAN(RADIANS($J$4)))/LN(((2*J9*TAN(RADIANS($J$4))+K9-$C$13)*(K9+$C$13))/((2*J9*TAN(RADIANS($J$4))+K9+$C$13)*(K9-$C$13)))) -> 2.7898595e+13 | N9: =IF(M9=0,0,M9^-1) -> 3.5844099e-14 | W9: =IF($D$3="English",W8*10^-3,W8*10^-6) -> 1040 | X9: =IF($D$3="English","kpsi","MPa") -> MPa | AD9: 10.9 | AE9: 5 | AF9: 36 | AG9: 162000000 | AI9: 5.8 | AJ9: 5 | AK9: 24 | AL9: 380000000 | AM9: 520000000 | AN9: 420000000 | AO9: Low or medium carbon | AQ9: 2 | AR9: 0.4 | AS9: 2.07 | AT9: 1.79 | AV9: 2 | AW9: =NA() -> #N/A | AX9: =NA() -> #N/A | AY9: =NA() -> #N/A | BA9: =1 -> 1 | BB9: 0.073 | BC9: 64 | BD9: 0.00263 | BE9: 0.00218 | BG9: =1 -> 1 | BH9: 0.073 | BI9: 72 | BJ9: 0.00278 | BK9: 0.00237
I10: 4 | J10: =C17-SUM(J7:J9)-J11 -> 71.5 | K10: =K11+2*J11*TAN(RADIANS($J$4)) -> 32.547005 | L10: =F8 -> 120500000000 | M10: =IF(J10=0,0,(PI()*L10*$C$13*TAN(RADIANS($J$4)))/LN(((2*J10*TAN(RADIANS($J$4))+K10-$C$13)*(K10+$C$13))/((2*J10*TAN(RADIANS($J$4))+K10+$C$13)*(K10-$C$13)))) -> 4.5284954e+12 | N10: =IF(M10=0,0,M10^-1) -> 2.208239e-13 | V10: Minimum Yield Strength, Sy | W10: =IF(AND($C$13>=$AJ$30,$C$13<=$AK$30),AN30,IF(AND($C$13>=$AJ$31,$C$13<=$AK$31),AN31,NA())) -> 940000000 | X10: =IF($D$3="English","psi","Pa") -> Pa | AD10: 12.9 | AE10: 1.6 | AF10: 36 | AG10: 190000000 | AI10: 8.8 | AJ10: 16 | AK10: 36 | AL10: 600000000 | AM10: 830000000 | AN10: 660000000 | AO10: Medium carbon, Q&T | AQ10: 2.5 | AR10: 0.45 | AS10: 3.39 | AT10: 2.98 | AV10: 2.5 | AW10: =NA() -> #N/A | AX10: =NA() -> #N/A | AY10: =NA() -> #N/A | BA10: =2 -> 2 | BB10: 0.086 | BC10: 56 | BD10: 0.0037 | BE10: 0.0031 | BG10: =2 -> 2 | BH10: 0.086 | BI10: 64 | BJ10: 0.00394 | BK10: 0.00339
B11: Bolt Properties | C11: =_xlfn.CONCAT(IF($D$3="English",_xlfn.CONCAT(TEXT(C13, "# ?/?"),"""-",C25,"-", C15, " ",C14),_xlfn.CONCAT("M",C13,"-", C25,"-", C15," ",C14)), " Grade ", C16) -> M14-2-238 UNC Grade 10.9 | I11: 5 | J11: =C9 -> 10 | K11: =1.5*C13 -> 21 | L11: =F9 -> 120500000000 | M11: =IF(J11=0,0,(PI()*L11*$C$13*TAN(RADIANS($J$4)))/LN(((2*J11*TAN(RADIANS($J$4))+K11-$C$13)*(K11+$C$13))/((2*J11*TAN(RADIANS($J$4))+K11+$C$13)*(K11-$C$13)))) -> 4.4392172e+12 | N11: =IF(M11=0,0,M11^-1) -> 2.2526494e-13 | W11: =IF($D$3="English",W10*10^-3,W10*10^-6) -> 940 | X11: =IF($D$3="English","kpsi","MPa") -> MPa | AI11: 9.8 | AJ11: 1.6 | AK11: 16 | AL11: 650000000 | AM11: 900000000 | AN11: 720000000 | AO11: Medium carbon, Q&T | AQ11: 3 | AR11: 0.5 | AS11: 5.03 | AT11: 4.47 | AV11: 3 | AW11: =NA() -> #N/A | AX11: =NA() -> #N/A | AY11: =NA() -> #N/A | BA11: =3 -> 3 | BB11: 0.099 | BC11: 48 | BD11: 0.00487 | BE11: 0.00406 | BG11: =3 -> 3 | BH11: 0.099 | BI11: 56 | BJ11: 0.00523 | BK11: 0.00451
B12: Bolt elastic modulus, E | C12: =207*10^9 -> 207000000000 | D12: =IF($D$3="English","psi","Pa") -> Pa | V12: Corrected Endurance Strength, Se | W12: =IF(AND($C$13>=AE$20,$C$13<=AF$20),AG20,IF(AND($C$13>=AE$21,$C$13<=AF$21),AG21,NA())) -> 162000000 | X12: =IF($D$3="English","psi","Pa") -> Pa | AD12: English | AI12: 10.9 | AJ12: 5 | AK12: 36 | AL12: 830000000 | AM12: 1040000000 | AN12: 940000000 | AO12: Low-carbon martensite, Q&T | AQ12: 3.5 | AR12: 0.6 | AS12: 6.78 | AT12: 6 | AV12: 3.5 | AW12: =NA() -> #N/A | AX12: =NA() -> #N/A | AY12: =NA() -> #N/A | BA12: =4 -> 4 | BB12: 0.112 | BC12: 40 | BD12: 0.00604 | BE12: 0.00496 | BG12: =4 -> 4 | BH12: 0.112 | BI12: 48 | BJ12: 0.00661 | BK12: 0.00566
B13: Bolt diameter, d | C13: 14 | D13: =IF($D$3="English","in", "mm") -> mm | I13: Thickness check | J13: =SUM(J7:J11) -> 163 | K13: =IF($D$3="English","in", "mm") -> mm | W13: =IF($D$3="English",W12*10^-3,W12*10^-6) -> 162 | X13: =IF($D$3="English","kpsi","MPa") -> MPa | AD13: Property Class | AE13: Min Size (in) | AF13: Max Size (in) | AG13: Endurance Strength (psi) | AI13: 12.9 | AJ13: 1.6 | AK13: 36 | AL13: 970000000 | AM13: 1220000000 | AN13: 1100000000 | AO13: Alloy, Q&T | AQ13: 4 | AR13: 0.7 | AS13: 8.78 | AT13: 7.75 | AV13: 4 | AW13: =NA() -> #N/A | AX13: =NA() -> #N/A | AY13: =NA() -> #N/A | BA13: =5 -> 5 | BB13: 0.125 | BC13: 40 | BD13: 0.00796 | BE13: 0.00672 | BG13: =5 -> 5 | BH13: 0.125 | BI13: 44 | BJ13: 0.0088 | BK13: 0.00716
B14: Series | C14: UNC | I14: Grip length, l | J14: =C17 -> 163 | K14: =IF($D$3="English","in", "mm") -> mm | AD14: 5 | AE14: 0.125 | AF14: 1 | AG14: 18600 | AQ14: 5 | AR14: 0.8 | AS14: 14.2 | AT14: 12.7 | AV14: 5 | AW14: =NA() -> #N/A | AX14: =NA() -> #N/A | AY14: =NA() -> #N/A | BA14: =6 -> 6 | BB14: 0.138 | BC14: 32 | BD14: 0.00909 | BE14: 0.00745 | BG14: =6 -> 6 | BH14: 0.138 | BI14: 40 | BJ14: 0.01015 | BK14: 0.00874
B15: Bolt Length, L | C15: 238 | D15: =IF($D$3="English","in", "mm") -> mm | I15: Half grip length, l/2 | J15: =C17/2 -> 81.5 | K15: =IF($D$3="English","in", "mm") -> mm | P15: Loading on Bolts | V15: Bolt Loading | AD15: 5 | AE15: 1.125 | AF15: 1.5 | AG15: 16300 | AI15: Table 8-9 | AQ15: 6 | AR15: 1 | AS15: 20.1 | AT15: 17.9 | AV15: 6 | AW15: =NA() -> #N/A | AX15: =NA() -> #N/A | AY15: =NA() -> #N/A | BA15: =8 -> 8 | BB15: 0.164 | BC15: 32 | BD15: 0.014 | BE15: 0.01196 | BG15: =8 -> 8 | BH15: 0.164 | BI15: 36 | BJ15: 0.01474 | BK15: 0.01285
B16: Grade No. | C16: 10.9 | P16: Number of Bolts, N | Q16: 10 | V16: Joint Compliance, C | W16: =C34/(C34+J17) -> 0.17305046 | AD16: 7 | AE16: 0.25 | AF16: 1.5 | AG16: 20600 | AI16: English | AQ16: 8 | AR16: 1.25 | AS16: 36.6 | AT16: 32.8 | AV16: 8 | AW16: 1 | AX16: 39.2 | AY16: 36 | BA16: =10 -> 10 | BB16: 0.19 | BC16: 24 | BD16: 0.0175 | BE16: 0.0145 | BG16: =10 -> 10 | BH16: 0.19 | BI16: 32 | BJ16: 0.02 | BK16: 0.0175
B17: Grip length, l | C17: =SUM(C7:C9)+C13/2 -> 163 | D17: =IF($D$3="English","in", "mm") -> mm | I17: Member Stiffness, km | J17: =SUM(N7:N11)^-1 -> 8.3374001e+11 | K17: =IF($D$3="English","lbf/in","mN/m") -> mN/m | O17: match these when load isn't changing--> | P17: External Load total, Pmin_total | Q17: =Q30 -> 0 | R17: =IF($D$3="English","lbf", "N") -> N | V17: Opening load, Po | W17: =Q19/(1-W16) -> 104577.12 | X17: =IF($D$3="English","lbf", "N") -> N | AD17: 8 | AE17: 0.25 | AF17: 1.5 | AG17: 23200 | AI17: SAE Grade No. | AJ17: Min Size (in) | AK17: Max Size (in) | AL17: Proof Strength (psi) | AM17: Tensile Strength (psi) | AN17: Yield Strength (psi) | AO17: Material | AQ17: 10 | AR17: 1.5 | AS17: 58 | AT17: 52.3 | AV17: 10 | AW17: 1.25 | AX17: 61.2 | AY17: 56.3 | BA17: =12 -> 12 | BB17: 0.216 | BC17: 24 | BD17: 0.0242 | BE17: 0.0206 | BG17: =12 -> 12 | BH17: 0.216 | BI17: 28 | BJ17: 0.0258 | BK17: 0.0226
B18: Threaded bolt length, LT | C18: =IF(F19,C19,IF(F18,C15,IF($D$3="English",IF(C15<=6, 2*C13+0.25, 2*C13+0.5),IF(AND(C15<=125,C13<=48),2*C13+6,IF(C15<=200,2*C13+12,2*C13+25))))) -> 133 | D18: =IF($D$3="English","in", "mm") -> mm | E18: Fully Threaded | F18: FALSE | J18: =IF($D$3="English",J17*10^-6,J17*10^-9) -> 833.74001 | K18: =IF($D$3="English","Mlbf/in","MN/m") -> MN/m | O18: match these when load isn't changing--> | P18: External Load total, Pmax_total | Q18: =Q31 -> 141764.37 | R18: =IF($D$3="English","lbf", "N") -> N | V18: Yield Load, SyL | W18: =IF($D$3="English",W10*$C$24,W10*$C$24) -> 108100 | X18: =IF($D$3="English","lbf", "N") -> N | AI18: 1 | AJ18: 0.25 | AK18: 1.5 | AL18: 33000 | AM18: 60000 | AN18: 36000 | AO18: Low or medium carbon | AQ18: 12 | AR18: 1.75 | AS18: 84.3 | AT18: 76.3 | AV18: 12 | AW18: 1.25 | AX18: 92.1 | AY18: 86 | BA18: =1/4 -> 0.25 | BB18: 0.25 | BC18: 20 | BD18: 0.0318 | BE18: 0.0269 | BG18: =1/4 -> 0.25 | BH18: 0.25 | BI18: 28 | BJ18: 0.0364 | BK18: 0.0326
C19: 133 | D19: =IF($D$3="English","in", "mm") -> mm | E19: Override threaded length | F19: TRUE | P19: Preload, Fi | Q19: =IF(T20,Q20,W18*T19) -> 86480 | R19: =IF($D$3="English","lbf", "N") -> N | S19: Percent of yield load | T19: 0.8 | AD19: Filtering Table 8-17 for when one grade no. has two lines of data based on diameter | AI19: 2 | AJ19: 0.25 | AK19: 0.75 | AL19: 55000 | AM19: 74000 | AN19: 57000 | AO19: Low or medium carbon | AQ19: 14 | AR19: 2 | AS19: 115 | AT19: 104 | AV19: 14 | AW19: 1.5 | AX19: 125 | AY19: 116 | BA19: =5/16 -> 0.3125 | BB19: 0.3125 | BC19: 18 | BD19: 0.0524 | BE19: 0.0454 | BG19: =5/16 -> 0.3125 | BH19: 0.3125 | BI19: 24 | BJ19: 0.058 | BK19: 0.0524
B20: Unthreaded bolt length, ld | C20: =C15-C18 -> 105 | D20: =IF($D$3="English","in", "mm") -> mm | I20: Joint Compliance, C | J20: =W16 -> 0.17305046 | R20: =IF($D$3="English","lbf", "N") -> N | S20: Override Preload | T20: FALSE | V20: External Load per joint, Pmin | W20: =Q17/Q16 -> 0 | X20: =IF($D$3="English","lbf", "N") -> N | Y20: Alternating External Load per joint, Pa | Z20: =0.5*(W21-W20) -> 7088.2184 | AA20: =IF($D$3="English","lbf", "N") -> N | AD20: {=IF($D$3="English",_xlfn._xlws.FILTER(AD14:AG17,AD14:AD17=C16,AD18:AG19=NA()), _xlfn._xlws.FILTER(AD7:AG10,AD7:AD10=C16,AD18:AG19=NA()))} -> 10.9 | AE20: 5 | AF20: 36 | AG20: 162000000 | AI20: 2 | AJ20: 0.875 | AK20: 1.5 | AL20: 33000 | AM20: 60000 | AN20: 36000 | AO20: =NA() -> #N/A | AQ20: 16 | AR20: 2 | AS20: 157 | AT20: 144 | AV20: 16 | AW20: 1.5 | AX20: 167 | AY20: 157 | BA20: =3/8 -> 0.375 | BB20: 0.375 | BC20: 16 | BD20: 0.0775 | BE20: 0.0678 | BG20: =3/8 -> 0.375 | BH20: 0.375 | BI20: 24 | BJ20: 0.0878 | BK20: 0.0809
B21: Threaded bolt length in grip, lt | C21: =C17-C20 -> 58 | D21: =IF($D$3="English","in", "mm") -> mm | V21: External Load per joint, Pmax | W21: =Q18/Q16 -> 14176.437 | X21: =IF($D$3="English","lbf", "N") -> N | Y21: Mean External Load per joint, Pm | Z21: =0.5*(W21+W20) -> 7088.2184 | AA21: =IF($D$3="English","lbf", "N") -> N | AI21: 4 | AJ21: 0.25 | AK21: 1.5 | AL21: 65000 | AM21: 115000 | AN21: 100000 | AO21: Medium carbon, cold-drawn | AQ21: 20 | AR21: 2.5 | AS21: 245 | AT21: 225 | AV21: 20 | AW21: 1.5 | AX21: 272 | AY21: 259 | BA21: =7/16 -> 0.4375 | BB21: 0.4375 | BC21: 14 | BD21: 0.1063 | BE21: 0.0933 | BG21: =7/16 -> 0.4375 | BH21: 0.4375 | BI21: 20 | BJ21: 0.1187 | BK21: 0.109
B22: Area of unthreaded portion, Ad | C22: =(PI()*(C13^2))/4 -> 153.93804 | D22: =IF($D$3="English","in^2","mm^2") -> mm^2 | P22: Calculations for Loading due to Pressurized Cylinder | AI22: 5 | AJ22: 0.25 | AK22: 1 | AL22: 85000 | AM22: 120000 | AN22: 92000 | AO22: Medium carbon, Q&T | AQ22: 24 | AR22: 3 | AS22: 353 | AT22: 324 | AV22: 24 | AW22: 2 | AX22: 384 | AY22: 365 | BA22: =1/2 -> 0.5 | BB22: 0.5 | BC22: 13 | BD22: 0.1419 | BE22: 0.1257 | BG22: =1/2 -> 0.5 | BH22: 0.5 | BI22: 20 | BJ22: 0.1599 | BK22: 0.1486
B23: Area of threaded portion, At | C23: =IF($D$3="English",IF($C$14="UNC",VLOOKUP($C$13,$BB$8:$BE$29,3,FALSE),VLOOKUP($C$13,$BH$8:$BK$29,3,FALSE)), IF($C$14="UNC",VLOOKUP($C$13,$AQ$8:$AT$33,3,FALSE),VLOOKUP($C$13,$AV$8:$AY$33,3,FALSE))) -> 115 | D23: =IF($D$3="English","in^2","mm^2") -> mm^2 | P23: Pressurized Cylinder diameter | Q23: 95 | R23: =IF($D$3="English","in", "mm") -> mm | V23: Load per bolt, Fb_min | W23: =$W$16*W20+$Q$19 -> 86480 | X23: =IF($D$3="English","lbf", "N") -> N | Y23: Alternating Load per bolt, Fa | Z23: =0.5*(W24-W23) -> 1226.6195 | AA23: =IF($D$3="English","lbf", "N") -> N | AI23: 5 | AJ23: 1.125 | AK23: 1.5 | AL23: 74000 | AM23: 105000 | AN23: 81000 | AO23: =NA() -> #N/A | AQ23: 30 | AR23: 3.5 | AS23: 561 | AT23: 519 | AV23: 30 | AW23: 2 | AX23: 621 | AY23: 596 | BA23: =9/16 -> 0.5625 | BB23: 0.5625 | BC23: 12 | BD23: 0.182 | BE23: 0.162 | BG23: =9/16 -> 0.5625 | BH23: 0.5625 | BI23: 18 | BJ23: 0.203 | BK23: 0.189
C24: =IF($D$3="English",C23,C23*10^-6) -> 0.000115 | D24: =IF($D$3="English","in^2","m^2") -> m^2 | Q24: =Q23*10^-3 -> 0.095 | R24: =IF($D$3="English","*10^3 in", "m") -> m | V24: Load per bolt, Fb_max | W24: =$W$16*W21+$Q$19 -> 88933.239 | X24: =IF($D$3="English","lbf", "N") -> N | Y24: Mean Load per bolt, Fm | Z24: =0.5*(W24+W23) -> 87706.619 | AA24: =IF($D$3="English","lbf", "N") -> N | AI24: 5.2 | AJ24: 0.25 | AK24: 1 | AL24: 85000 | AM24: 120000 | AN24: 92000 | AO24: Low-carbon martensite, Q&T | AQ24: 36 | AR24: 4 | AS24: 817 | AT24: 759 | AV24: 36 | AW24: 2 | AX24: 915 | AY24: 884 | BA24: =5/8 -> 0.625 | BB24: 0.625 | BC24: 11 | BD24: 0.226 | BE24: 0.202 | BG24: =5/8 -> 0.625 | BH24: 0.625 | BI24: 18 | BJ24: 0.256 | BK24: 0.24
B25: =IF($D$3="English","Bolt threads per inch, p","Bolt pitch, p") -> Bolt pitch, p | C25: =IF($D$3="English",IF($C$14="UNC",VLOOKUP($C$13,$BB$8:$BE$29,2,FALSE),VLOOKUP($C$13,$BH$8:$BK$29,2,FALSE)), IF($C$14="UNC",VLOOKUP($C$13,$AQ$8:$AT$33,2,FALSE),VLOOKUP($C$13,$AV$8:$AY$33,2,FALSE))) -> 2 | D25: =IF($D$3="English","threads/in","mm") -> mm | P25: Pressurized Cylinder Area | Q25: =IF($D$3="English",PI()*(Q23^2)*0.25,PI()*(Q24^2)*0.25) -> 0.0070882184 | R25: =IF($D$3="English","in^2","m^2") -> m^2 | AI25: 7 | AJ25: 0.25 | AK25: 1.5 | AL25: 105000 | AM25: 133000 | AN25: 115000 | AO25: Medium-carbon alloy, Q&T | AQ25: 42 | AR25: 4.5 | AS25: 1120 | AT25: 1050 | AV25: 42 | AW25: 2 | AX25: 1260 | AY25: 1230 | BA25: =3/4 -> 0.75 | BB25: 0.75 | BC25: 10 | BD25: 0.334 | BE25: 0.302 | BG25: =3/4 -> 0.75 | BH25: 0.75 | BI25: 16 | BJ25: 0.373 | BK25: 0.351
I26: Max Load on the bolt may be actually refering to the max external load on the bolt | V26: Load per member, Fmin | W26: =(1-$W$16)*W20-$Q$19 -> -86480 | X26: =IF($D$3="English","lbf", "N") -> N | AI26: 8 | AJ26: 0.25 | AK26: 1.5 | AL26: 120000 | AM26: 150000 | AN26: 130000 | AO26: Medium-carbon alloy, Q&T | AQ26: 48 | AR26: 5 | AS26: 1470 | AT26: 1380 | AV26: 48 | AW26: 2 | AX26: 1670 | AY26: 1630 | BA26: =7/8 -> 0.875 | BB26: 0.875 | BC26: 9 | BD26: 0.462 | BE26: 0.419 | BG26: =7/8 -> 0.875 | BH26: 0.875 | BI26: 14 | BJ26: 0.509 | BK26: 0.48
B27: Threaded into bottom member | C27: FALSE | D27: <---- Note that if this option is selected also | I27: which would be the external load per joint | P27: Pressure in Cyclinder, Prmin_total | Q27: 0 | R27: =IF($D$3="English","psi","Pa") -> Pa | V27: Load per member, Fmax | W27: =(1-$W$16)*W21-$Q$19 -> -74756.802 | X27: =IF($D$3="English","lbf", "N") -> N | AI27: 8.2 | AJ27: 0.25 | AK27: 1 | AL27: 120000 | AM27: 150000 | AN27: 130000 | AO27: Low-carbon martensite, Q&T | AQ27: 56 | AR27: 5.5 | AS27: 2030 | AT27: 1910 | AV27: 56 | AW27: 2 | AX27: 2300 | AY27: 2250 | BA27: =1 -> 1 | BB27: 1 | BC27: 8 | BD27: 0.606 | BE27: 0.551 | BG27: =1 -> 1 | BH27: 1 | BI27: 12 | BJ27: 0.663 | BK27: 0.625
B28: Threaded into nut | C28: =NOT(C27) -> TRUE | D28: change Bottom Washer Length to 0 | I28: =V21 -> External Load per joint, Pmax | K28: =W21 -> 14176.437 | P28: Pressure in Cyclinder, Prmax_total | Q28: =20*10^6 -> 20000000 | R28: =IF($D$3="English","psi","Pa") -> Pa | AQ28: 64 | AR28: 6 | AS28: 2680 | AT28: 2520 | AV28: 64 | AW28: 2 | AX28: 3030 | AY28: 2980 | BA28: =1.25 -> 1.25 | BB28: 1.25 | BC28: 7 | BD28: 0.969 | BE28: 0.89 | BG28: =1.25 -> 1.25 | BH28: 1.25 | BI28: 12 | BJ28: 1.073 | BK28: 1.024
V29: Bolt Stress | AI29: Filtering Tables 8-9 and 8-11 for when one grade no. has two lines of data based on diameter | AQ29: 72 | AR29: 6 | AS29: 3460 | AT29: 3280 | AV29: 72 | AW29: 2 | AX29: 3860 | AY29: 3800 | BA29: =1.5 -> 1.5 | BB29: 1.5 | BC29: 6 | BD29: 1.405 | BE29: 1.294 | BG29: =1.5 -> 1.5 | BH29: 1.5 | BI29: 12 | BJ29: 1.581 | BK29: 1.521
B30: Unthreaded Fastener Stiffness, kd | C30: =IF(C20=0,0,(C22*C12)/C20) -> 3.0347785e+11 | D30: =IF($D$3="English","lbf/in","mN/m") -> mN/m | P30: External Load total, Pmin_total | Q30: =Q27*$Q$25 -> 0 | R30: =IF($D$3="English","lbf", "N") -> N | V30: Initial Bolt Sress, σi | W30: =Q19/$C$24 -> 7.52e+08 | X30: =IF($D$3="English","psi","Pa") -> Pa | AI30: {=IF($D$3="English",_xlfn._xlws.FILTER(AI18:AO27,AI18:AI27=C16,AI28:AO29=NA()), _xlfn._xlws.FILTER(AI7:AO13,AI7:AI13=C16,AI28:AO29=NA()))} -> 10.9 | AJ30: 5 | AK30: 36 | AL30: 830000000 | AM30: 1040000000 | AN30: 940000000 | AO30: Low-carbon martensite, Q&T | AQ30: 80 | AR30: 6 | AS30: 4340 | AT30: 4140 | AV30: 80 | AW30: 1.5 | AX30: 4850 | AY30: 4800
C31: =IF($D$3="English",C30*10^-6,C30*10^-9) -> 303.47785 | D31: =IF($D$3="English","Mlbf/in","MN/m") -> MN/m | P31: External Load total, Pmax_total | Q31: =Q28*$Q$25 -> 141764.37 | R31: =IF($D$3="English","lbf", "N") -> N | W31: =IF($D$3="English",W30*10^-3,W30*10^-6) -> 752 | X31: =IF($D$3="English","kpsi","MPa") -> MPa | AQ31: 90 | AR31: 6 | AS31: 5590 | AT31: 5360 | AV31: 90 | AW31: 2 | AX31: 6100 | AY31: 6020
B32: Threaded Fastener Stiffness, kt | C32: =IF(C21=0,0,(C23*C12)/C21) -> 4.1043103e+11 | D32: =IF($D$3="English","lbf/in","mN/m") -> mN/m | P32: copy pasted these values in to external loads above as values | V32: Bolt Sress, σmin | W32: =W23/$C$24 -> 7.52e+08 | X32: =IF($D$3="English","psi","Pa") -> Pa | Y32: Alternating Bolt Sress, σa | Z32: =0.5*(W34-W32) -> 10666256 | AA32: =IF($D$3="English","psi","Pa") -> Pa | AQ32: 100 | AR32: 6 | AS32: 6990 | AT32: 6740 | AV32: 100 | AW32: 2 | AX32: 7560 | AY32: 7470
C33: =IF($D$3="English",C32*10^-6,C32*10^-9) -> 410.43103 | D33: =IF($D$3="English","Mlbf/in","MN/m") -> MN/m | W33: =IF($D$3="English",W32*10^-3,W32*10^-6) -> 752 | X33: =IF($D$3="English","kpsi","MPa") -> MPa | Z33: =IF($D$3="English",Z32*10^-3,Z32*10^-6) -> 10.666256 | AA33: =IF($D$3="English","kpsi","MPa") -> MPa | AQ33: 110 | AR33: 6 | AS33: =NA() -> #N/A | AT33: =NA() -> #N/A | AV33: 110 | AW33: 2 | AX33: 9180 | AY33: 9080
B34: Fastener Stiffness, kb | C34: =SUM(IF(C30=0,0,C30^-1),IF(C32=0,0,C32^-1))^-1 -> 1.7447146e+11 | D34: =IF($D$3="English","lbf/in","mN/m") -> mN/m | V34: Bolt Sress, σmax | W34: =W24/$C$24 -> 7.7333251e+08 | X34: =IF($D$3="English","psi","Pa") -> Pa | Y34: Mean Bolt Sress, σm | Z34: =0.5*(W34+W32) -> 7.6266626e+08 | AA34: =IF($D$3="English","psi","Pa") -> Pa
C35: =IF($D$3="English",C34*10^-6,C34*10^-9) -> 174.47146 | D35: =IF($D$3="English","Mlbf/in","MN/m") -> MN/m | P35: gasket area Ag | Q35: 37287.463 | R35: =IF($D$3="English","in^2","mm^2") -> mm^2 | W35: =IF($D$3="English",W34*10^-3,W34*10^-6) -> 773.33251 | X35: =IF($D$3="English","kpsi","MPa") -> MPa | Z35: =IF($D$3="English",Z34*10^-3,Z34*10^-6) -> 762.66626 | AA35: =IF($D$3="English","kpsi","MPa") -> MPa
Q36: =Q35*10^-6 -> 0.037287463 | R36: =IF($D$3="English","in^2","m^2") -> m^2 | V36: Factors of Safety
P37: gasket pressure | Q37: =-W27/(Q36/Q16) -> 20048777 | R37: =IF($D$3="English","psi","Pa") -> Pa | V37: Joint opening FoS, ηo | W37: =W17/W21 -> 7.3768268
Q38: =IF($D$3="English",Q37*10^-3,Q37*10^-6) -> 20.048777 | R38: =IF($D$3="English","kpsi","MPa") -> MPa | U38: was written as FoS against yield on practice quiz --> | V38: Proof strength FoS, ηp | W38: =(W6*$C$24)/(W24) -> 1.073277
V39: Goodman Fatigue FoS, ηf | W39: =(W12*(W8-W30))/(W8*Z32+W12*(Z34-W30)) -> 3.6390751 | X39: EQ (8-38)
Q40: =(Q37-Q28)/Q28 -> 0.0024388374 | V40: Proof load FoS, ηL | W40: =(W6*$C$24-Q19)/(W16*W21) -> 3.6563906
V42: Torque based on Preload
...

Sheet Old Lab3 Jointed Assembly
B2: INPUTS | C2: Units: | D2: Metric | I2: OUTPUTS | U2: Table 8-1 | AE2: Table 8-2
Y3: Metric | AJ3: English
B4: Member Properties | I4: Frusta Dimensions | P4: Bolt Loading | U4: UNC | Z4: UNF | AE4: UNC | AK4: UNF
B5: Apex angle, α | C5: 30 | D5: degrees | E5: Elastic Modulus | I5: Segment | J5: =_xlfn.CONCAT("Thickness ", "[",D6,"]") -> Thickness [mm] | K5: =_xlfn.CONCAT("D ", "[",D13,"]") -> D [mm] | L5: =_xlfn.CONCAT("E ", "[",G6,"]") -> E [Pa] | M5: =_xlfn.CONCAT("k ", "[",D33,"]") -> k [mN/m] | N5: 1/k | P5: Joint Compliance, C | Q5: =C33/(C33+J16) -> 0.18220361 | U5: Nominal Major Diameter d [mm] | V5: Pitch p [mm] | W5: Tensile-Stress Area At​ [mm2] | X5: Minor-Diameter Area Ar [mm2] | Z5: Nominal Major Diameter d [mm] | AA5: Pitch p [mm] | AB5: Tensile-Stress Area At​ [mm2] | AC5: Minor-Diameter Area Ar [mm2] | AE5: Size Designation | AF5: Nominal Major Diameter d [in] | AG5: Threads per Inch N [in] | AH5: Tensile-Stress Area At​ [in2] | AI5: Minor-Diameter Area Ar [in2] | AK5: Size Designation | AL5: Nominal Major Diameter d [in] | AM5: Threads per Inch N [in] | AN5: Tensile-Stress Area At​ [in2] | AO5: Minor-Diameter Area Ar [in2]
B6: Top Washer Length, ttw | D6: =IF($D$2="English","in", "mm") -> mm | E6: E top washer | G6: =IF($D$2="English","psi","Pa") -> Pa | I6: 1 | J6: =C6 -> 0 | K6: =1.5*C13 -> 21 | L6: =F6 -> 0 | M6: =IF(J6=0,0,(PI()*L6*$C$13*TAN(RADIANS($C$5)))/LN(((2*J6*TAN(RADIANS($C$5))+K6-$C$13)*(K6+$C$13))/((2*J6*TAN(RADIANS($C$5))+K6+$C$13)*(K6-$C$13)))) -> 0 | N6: =IF(M6=0,0,M6^-1) -> 0 | P6: External Load per bolt/member, P | Q6: =C38/C37 -> 35441.092 | R6: =IF($D$2="English","lbf", "N") -> N | U6: 1.6 | V6: 0.35 | W6: 1.27 | X6: 1.07 | Z6: 1.6 | AA6: =NA() -> #N/A | AB6: =NA() -> #N/A | AC6: =NA() -> #N/A | AE6: =0 -> 0 | AF6: 0.06 | AG6: =NA() -> #N/A | AH6: =NA() -> #N/A | AI6: =NA() -> #N/A | AK6: =0 -> 0 | AL6: 0.06 | AM6: 80 | AN6: 0.0018 | AO6: 0.00151
B7: aluminum rocker carrier | C7: 51 | D7: =IF($D$2="English","in", "mm") -> mm | E7: E top member | F7: =71*10^9 -> 71000000000 | G7: =IF($D$2="English","psi","Pa") -> Pa | I7: 2 | J7: =IF(C6+C7<J14,C7,J14-C6) -> 51 | K7: =K6+2*J6*TAN(RADIANS($C$5)) -> 21 | L7: =F7 -> 71000000000 | M7: =IF(J7=0,0,(PI()*L7*$C$13*TAN(RADIANS($C$5)))/LN(((2*J7*TAN(RADIANS($C$5))+K7-$C$13)*(K7+$C$13))/((2*J7*TAN(RADIANS($C$5))+K7+$C$13)*(K7-$C$13)))) -> 1.4362442e+12 | N7: =IF(M7=0,0,M7^-1) -> 6.9626044e-13 | P7: Load per bolt, Fb | Q7: =Q5*Q6+C39 -> 92937.495 | R7: =IF($D$2="English","lbf", "N") -> N | U7: 2 | V7: 0.4 | W7: 2.07 | X7: 1.79 | Z7: 2 | AA7: =NA() -> #N/A | AB7: =NA() -> #N/A | AC7: =NA() -> #N/A | AE7: =1 -> 1 | AF7: 0.073 | AG7: 64 | AH7: 0.00263 | AI7: 0.00218 | AK7: =1 -> 1 | AL7: 0.073 | AM7: 72 | AN7: 0.00278 | AO7: 0.00237
B8: cast-iron head | C8: 95 | D8: =IF($D$2="English","in", "mm") -> mm | E8: E bottom member | F8: =100*10^9 -> 100000000000 | G8: =IF($D$2="English","psi","Pa") -> Pa | I8: 3 | J8: =IF(C6+C7<J14,J14-C7-C6,C6+C7-J14) -> 30.5 | K8: =IF(J6+J7<J14,K7+2*J7*TAN(RADIANS($C$5)),K7+2*J7*TAN(RADIANS($C$5))-2*J8*TAN(RADIANS($C$5))) -> 79.889727 | L8: =IF(J6+J7<J14,F8,F7) -> 100000000000 | M8: =IF(J8=0,0,(PI()*L8*$C$13*TAN(RADIANS($C$5)))/LN(((2*J8*TAN(RADIANS($C$5))+K8-$C$13)*(K8+$C$13))/((2*J8*TAN(RADIANS($C$5))+K8+$C$13)*(K8-$C$13)))) -> 2.3152361e+13 | N8: =IF(M8=0,0,M8^-1) -> 4.3192139e-14 | P8: Load per member, Fm | Q8: =(1-Q5)*Q6-C39 -> -57496.403 | R8: =IF($D$2="English","lbf", "N") -> N | U8: 2.5 | V8: 0.45 | W8: 3.39 | X8: 2.98 | Z8: 2.5 | AA8: =NA() -> #N/A | AB8: =NA() -> #N/A | AC8: =NA() -> #N/A | AE8: =2 -> 2 | AF8: 0.086 | AG8: 56 | AH8: 0.0037 | AI8: 0.0031 | AK8: =2 -> 2 | AL8: 0.086 | AM8: 64 | AN8: 0.00394 | AO8: 0.00339
B9: Cast Iron Block (threads start 10 mm down) | C9: 10 | D9: =IF($D$2="English","in", "mm") -> mm | E9: E bottom washer | F9: =100*10^9 -> 100000000000 | G9: =IF($D$2="English","psi","Pa") -> Pa | I9: 4 | J9: =C17-SUM(J6:J8)-J10 -> 71.5 | K9: =K10+2*J10*TAN(RADIANS($C$5)) -> 32.547005 | L9: =F8 -> 100000000000 | M9: =IF(J9=0,0,(PI()*L9*$C$13*TAN(RADIANS($C$5)))/LN(((2*J9*TAN(RADIANS($C$5))+K9-$C$13)*(K9+$C$13))/((2*J9*TAN(RADIANS($C$5))+K9+$C$13)*(K9-$C$13)))) -> 3.7580875e+12 | N9: =IF(M9=0,0,M9^-1) -> 2.660928e-13 | P9: Opening load, Po | Q9: =C39/(1-Q5) -> 105747.59 | R9: =IF($D$2="English","lbf", "N") -> N | U9: 3 | V9: 0.5 | W9: 5.03 | X9: 4.47 | Z9: 3 | AA9: =NA() -> #N/A | AB9: =NA() -> #N/A | AC9: =NA() -> #N/A | AE9: =3 -> 3 | AF9: 0.099 | AG9: 48 | AH9: 0.00487 | AI9: 0.00406 | AK9: =3 -> 3 | AL9: 0.099 | AM9: 56 | AN9: 0.00523 | AO9: 0.00451
I10: 5 | J10: =C9 -> 10 | K10: =1.5*C13 -> 21 | L10: =F9 -> 100000000000 | M10: =IF(J10=0,0,(PI()*L10*$C$13*TAN(RADIANS($C$5)))/LN(((2*J10*TAN(RADIANS($C$5))+K10-$C$13)*(K10+$C$13))/((2*J10*TAN(RADIANS($C$5))+K10+$C$13)*(K10-$C$13)))) -> 3.6839977e+12 | N10: =IF(M10=0,0,M10^-1) -> 2.7144425e-13 | U10: 3.5 | V10: 0.6 | W10: 6.78 | X10: 6 | Z10: 3.5 | AA10: =NA() -> #N/A | AB10: =NA() -> #N/A | AC10: =NA() -> #N/A | AE10: =4 -> 4 | AF10: 0.112 | AG10: 40 | AH10: 0.00604 | AI10: 0.00496 | AK10: =4 -> 4 | AL10: 0.112 | AM10: 48 | AN10: 0.00661 | AO10: 0.00566
B11: Bolt Properties | C11: =_xlfn.CONCAT(IF($D$2="English",_xlfn.CONCAT(TEXT(C13, "# ?/?"),"""-",C24,"-", C15, " ",C14),_xlfn.CONCAT("M",C13,"-", C24,"-", C15," ",C14)), " Grade ", C16) -> M14-2-238 UNC Grade 10.9 | P11: Factors of Safety | U11: 4 | V11: 0.7 | W11: 8.78 | X11: 7.75 | Z11: 4 | AA11: =NA() -> #N/A | AB11: =NA() -> #N/A | AC11: =NA() -> #N/A | AE11: =5 -> 5 | AF11: 0.125 | AG11: 40 | AH11: 0.00796 | AI11: 0.00672 | AK11: =5 -> 5 | AL11: 0.125 | AM11: 44 | AN11: 0.0088 | AO11: 0.00716
B12: Bolt elastic modulus, E | C12: =207*10^9 -> 207000000000 | D12: =IF($D$2="English","psi","Pa") -> Pa | I12: Thickness check | J12: =SUM(J6:J10) -> 163 | K12: =IF($D$2="English","in", "mm") -> mm | P12: Proof strength FoS, ηp | Q12: =(Q21*C23)/(Q7) -> 1027034.4 | U12: 5 | V12: 0.8 | W12: 14.2 | X12: 12.7 | Z12: 5 | AA12: =NA() -> #N/A | AB12: =NA() -> #N/A | AC12: =NA() -> #N/A | AE12: =6 -> 6 | AF12: 0.138 | AG12: 32 | AH12: 0.00909 | AI12: 0.00745 | AK12: =6 -> 6 | AL12: 0.138 | AM12: 40 | AN12: 0.01015 | AO12: 0.00874
B13: Bolt diameter, d | C13: 14 | D13: =IF($D$2="English","in", "mm") -> mm | I13: Grip length, l | J13: =C17 -> 163 | K13: =IF($D$2="English","in", "mm") -> mm | P13: Proof load FoS, ηL | Q13: =(Q21*C23-C39)/(Q5*Q6) -> 14781261 | U13: 6 | V13: 1 | W13: 20.1 | X13: 17.9 | Z13: 6 | AA13: =NA() -> #N/A | AB13: =NA() -> #N/A | AC13: =NA() -> #N/A | AE13: =8 -> 8 | AF13: 0.164 | AG13: 32 | AH13: 0.014 | AI13: 0.01196 | AK13: =8 -> 8 | AL13: 0.164 | AM13: 36 | AN13: 0.01474 | AO13: 0.01285
B14: Series | C14: UNC | I14: Half grip length, l/2 | J14: =C17/2 -> 81.5 | K14: =IF($D$2="English","in", "mm") -> mm | P14: Joint opening FoS, ηo | Q14: =Q9/Q6 -> 2.9837566 | U14: 8 | V14: 1.25 | W14: 36.6 | X14: 32.8 | Z14: 8 | AA14: 1 | AB14: 39.2 | AC14: 36 | AE14: =10 -> 10 | AF14: 0.19 | AG14: 24 | AH14: 0.0175 | AI14: 0.0145 | AK14: =10 -> 10 | AL14: 0.19 | AM14: 32 | AN14: 0.02 | AO14: 0.0175
B15: Bolt Length, L | C15: 238 | D15: =IF($D$2="English","in", "mm") -> mm | U15: 10 | V15: 1.5 | W15: 58 | X15: 52.3 | Z15: 10 | AA15: 1.25 | AB15: 61.2 | AC15: 56.3 | AE15: =12 -> 12 | AF15: 0.216 | AG15: 24 | AH15: 0.0242 | AI15: 0.0206 | AK15: =12 -> 12 | AL15: 0.216 | AM15: 28 | AN15: 0.0258 | AO15: 0.0226
B16: Grade No. | C16: 10.9 | I16: Member Stiffness, km | J16: =SUM(N6:N10)^-1 -> 7.8309172e+11 | K16: =IF($D$2="English","lbf/in","mN/m") -> mN/m | P16: Yield Load, SyL | Q16: =IF($D$2="English",Q27*C23,Q27*C23*10^-6) -> 108100 | R16: =IF($D$2="English","lbf", "N") -> N | U16: 12 | V16: 1.75 | W16: 84.3 | X16: 76.3 | Z16: 12 | AA16: 1.25 | AB16: 92.1 | AC16: 86 | AE16: =1/4 -> 0.25 | AF16: 0.25 | AG16: 20 | AH16: 0.0318 | AI16: 0.0269 | AK16: =1/4 -> 0.25 | AL16: 0.25 | AM16: 28 | AN16: 0.0364 | AO16: 0.0326
B17: Grip length, l | C17: =SUM(C6:C8)+C9+C13/2 -> 163 | D17: =IF($D$2="English","in", "mm") -> mm | J17: =IF($D$2="English",J16*10^-6,J16*10^-9) -> 783.09172 | K17: =IF($D$2="English","Mlbf/in","MN/m") -> MN/m | U17: 14 | V17: 2 | W17: 115 | X17: 104 | Z17: 14 | AA17: 1.5 | AB17: 125 | AC17: 116 | AE17: =5/16 -> 0.3125 | AF17: 0.3125 | AG17: 18 | AH17: 0.0524 | AI17: 0.0454 | AK17: =5/16 -> 0.3125 | AL17: 0.3125 | AM17: 24 | AN17: 0.058 | AO17: 0.0524
B18: Threaded bolt length, LT | C18: =IF(F19,C19,IF(F18,C15,IF($D$2="English",IF(C15<=6, 2*C13+0.25, 2*C13+0.5),IF(AND(C15<=125,C13<=48),2*C13+6,IF(C15<=200,2*C13+12,2*C13+25))))) -> 133 | D18: =IF($D$2="English","in", "mm") -> mm | E18: Fully Threaded | F18: FALSE | P18: Torque, T | Q18: =Q19*C39*(C13*10^-3) -> 242.144 | R18: =IF($D$2="English","in-lbf", "Nm") -> Nm | U18: 16 | V18: 2 | W18: 157 | X18: 144 | Z18: 16 | AA18: 1.5 | AB18: 167 | AC18: 157 | AE18: =3/8 -> 0.375 | AF18: 0.375 | AG18: 16 | AH18: 0.0775 | AI18: 0.0678 | AK18: =3/8 -> 0.375 | AL18: 0.375 | AM18: 24 | AN18: 0.0878 | AO18: 0.0809
C19: 133 | D19: =IF($D$2="English","in", "mm") -> mm | E19: Override threaded length | F19: TRUE | P19: Torque coefficient, K | Q19: 0.2 | U19: 20 | V19: 2.5 | W19: 245 | X19: 225 | Z19: 20 | AA19: 1.5 | AB19: 272 | AC19: 259 | AE19: =7/16 -> 0.4375 | AF19: 0.4375 | AG19: 14 | AH19: 0.1063 | AI19: 0.0933 | AK19: =7/16 -> 0.4375 | AL19: 0.4375 | AM19: 20 | AN19: 0.1187 | AO19: 0.109
B20: Unthreaded bolt length, ld | C20: =C15-C18 -> 105 | D20: =IF($D$2="English","in", "mm") -> mm | U20: 24 | V20: 3 | W20: 353 | X20: 324 | Z20: 24 | AA20: 2 | AB20: 384 | AC20: 365 | AE20: =1/2 -> 0.5 | AF20: 0.5 | AG20: 13 | AH20: 0.1419 | AI20: 0.1257 | AK20: =1/2 -> 0.5 | AL20: 0.5 | AM20: 20 | AN20: 0.1599 | AO20: 0.1486
B21: Threaded bolt length in grip, lt | C21: =C17-C20 -> 58 | D21: =IF($D$2="English","in", "mm") -> mm | O21: from Table 8-9 through 8-11 --> | P21: Minimum Proof Strength, Sp | Q21: =830*10^6 -> 830000000 | R21: =IF($D$2="English","psi","Pa") -> Pa | U21: 30 | V21: 3.5 | W21: 561 | X21: 519 | Z21: 30 | AA21: 2 | AB21: 621 | AC21: 596 | AE21: =9/16 -> 0.5625 | AF21: 0.5625 | AG21: 12 | AH21: 0.182 | AI21: 0.162 | AK21: =9/16 -> 0.5625 | AL21: 0.5625 | AM21: 18 | AN21: 0.203 | AO21: 0.189
B22: Area of unthreaded portion, Ad | C22: =(PI()*(C13^2))/4 -> 153.93804 | D22: =IF($D$2="English","in^2","mm^2") -> mm^2 | Q22: =IF($D$2="English",Q21*10^-3,Q21*10^-6) -> 830 | R22: =IF($D$2="English","kpsi","MPa") -> MPa | U22: 36 | V22: 4 | W22: 817 | X22: 759 | Z22: 36 | AA22: 2 | AB22: 915 | AC22: 884 | AE22: =5/8 -> 0.625 | AF22: 0.625 | AG22: 11 | AH22: 0.226 | AI22: 0.202 | AK22: =5/8 -> 0.625 | AL22: 0.625 | AM22: 18 | AN22: 0.256 | AO22: 0.24
B23: Area of threaded portion, At | C23: =IF($D$2="English",IF($C$14="UNC",VLOOKUP($C$13,$AF$6:$AI$27,3,FALSE),VLOOKUP($C$13,$AL$6:$AO$27,3,FALSE)), IF($C$14="UNC",VLOOKUP($C$13,$U$6:$X$31,3,FALSE),VLOOKUP($C$13,$Z$6:$AC$31,3,FALSE))) -> 115 | D23: =IF($D$2="English","in^2","mm^2") -> mm^2 | U23: 42 | V23: 4.5 | W23: 1120 | X23: 1050 | Z23: 42 | AA23: 2 | AB23: 1260 | AC23: 1230 | AE23: =3/4 -> 0.75 | AF23: 0.75 | AG23: 10 | AH23: 0.334 | AI23: 0.302 | AK23: =3/4 -> 0.75 | AL23: 0.75 | AM23: 16 | AN23: 0.373 | AO23: 0.351
B24: =IF($D$2="English","Bolt threads per inch, p","Bolt pitch, p") -> Bolt pitch, p | C24: =IF($D$2="English",IF($C$14="UNC",VLOOKUP($C$13,$AF$6:$AI$27,2,FALSE),VLOOKUP($C$13,$AL$6:$AO$27,2,FALSE)), IF($C$14="UNC",VLOOKUP($C$13,$U$6:$X$31,2,FALSE),VLOOKUP($C$13,$Z$6:$AC$31,2,FALSE))) -> 2 | D24: =IF($D$2="English","threads/in","mm") -> mm | P24: Minimum Tensile Strength, Sut | Q24: =1040*10^6 -> 1040000000 | R24: =IF($D$2="English","psi","Pa") -> Pa | U24: 48 | V24: 5 | W24: 1470 | X24: 1380 | Z24: 48 | AA24: 2 | AB24: 1670 | AC24: 1630 | AE24: =7/8 -> 0.875 | AF24: 0.875 | AG24: 9 | AH24: 0.462 | AI24: 0.419 | AK24: =7/8 -> 0.875 | AL24: 0.875 | AM24: 14 | AN24: 0.509 | AO24: 0.48
Q25: =IF($D$2="English",Q24*10^-3,Q24*10^-6) -> 1040 | R25: =IF($D$2="English","kpsi","MPa") -> MPa | U25: 56 | V25: 5.5 | W25: 2030 | X25: 1910 | Z25: 56 | AA25: 2 | AB25: 2300 | AC25: 2250 | AE25: =1 -> 1 | AF25: 1 | AG25: 8 | AH25: 0.606 | AI25: 0.551 | AK25: =1 -> 1 | AL25: 1 | AM25: 12 | AN25: 0.663 | AO25: 0.625
B26: Threaded into bottom member | C26: TRUE | D26: <---- Note that if this option is selected also change Bottom Washer Length to 0 | U26: 64 | V26: 6 | W26: 2680 | X26: 2520 | Z26: 64 | AA26: 2 | AB26: 3030 | AC26: 2980 | AE26: =1.25 -> 1.25 | AF26: 1.25 | AG26: 7 | AH26: 0.969 | AI26: 0.89 | AK26: =1.25 -> 1.25 | AL26: 1.25 | AM26: 12 | AN26: 1.073 | AO26: 1.024
B27: Threaded into nut | C27: =NOT(C26) -> FALSE | P27: Minimum Yield Strength, Sy | Q27: =940*10^6 -> 940000000 | R27: =IF($D$2="English","psi","Pa") -> Pa | U27: 72 | V27: 6 | W27: 3460 | X27: 3280 | Z27: 72 | AA27: 2 | AB27: 3860 | AC27: 3800 | AE27: =1.5 -> 1.5 | AF27: 1.5 | AG27: 6 | AH27: 1.405 | AI27: 1.294 | AK27: =1.5 -> 1.5 | AL27: 1.5 | AM27: 12 | AN27: 1.581 | AO27: 1.521
